{
  "version": 8,
  "blockIdVersion": 11,
  "anchorX": 0,
  "anchorY": 0,
  "anchorZ": 0,
  "blocks": [
    {
      "x": -16,
      "y": 0,
      "z": -16,
      "name": "Rock_Stone_Brick"
    },
    {
      "x": -16,
      "y": 1,
      "z": -16,
      "name": "Rock_Stone_Brick"
    },
    {
      "x": -16,
      "y": 2,
      "z": -16,
      "name": "Rock_Stone_Brick"
    },
    {
      "x": -16,
      "y": 3,
      "z": -16,
      "name": "Rock_Stone_Brick"
    },
    {
      "x": -16,
      "y": 4,
      "z": -16,
      "name": "Rock_Stone_Brick"
    },
    {
      "x": -16,
      "y": 5,
      "z": -16,
      "name": "Rock_Stone_Brick"
    },
    {
      "x": -16,
      "y": 6,
      "z": -16,
      "name": "Rock_Stone_Brick"
    },
    {
      "x": -16,
      "y": 7,
      "z": -16,
      "name": "Rock_Stone_Brick"
    },
    {
      "x": -16,
      "y": 8,
      "z": -16,
      "name": "Rock_Stone_Brick"
    },
    {
      "x": -16,
      "y": 9,
      "z": -16,
      "name": "Rock_Stone_Brick"
    },
    {
      "x": -16,
      "y": 10,
      "z": -16,
      "name": "Rock_Stone_Brick"
    },
    {
      "x": -16,
      "y": 11,
      "z": -16,
      "name": "Rock_Stone_Brick"
    },
    {
      "x": -16,
      "y": 0,
      "z": -15,
      "name": "Rock_Stone_Brick"
    },
    {
      "x": -16,
      "y": 1,
      "z": -15,
      "name": "Rock_Stone_Brick"
    },
    {
      "x": -16,
      "y": 2,
      "z": -15,
      "name": "Rock_Stone_Brick"
    },
    {
      "x": -16,
      "y": 3,
      "z": -15,
      "name": "Rock_Stone_Brick"
    },
    {
      "x": -16,
      "y": 4,
      "z": -15,
      "name": "Rock_Stone_Brick"
    },
    {
      "x": -16,
      "y": 5,
      "z": -15,
      "name": "Rock_Stone_Brick"
    },
    {
      "x": -16,
      "y": 6,
      "z": -15,
      "name": "Rock_Stone_Brick"
    },
    {
      "x": -16,
      "y": 7,
      "z": -15,
      "name": "Rock_Stone_Brick"
    },
    {
      "x": -16,
      "y": 8,
      "z": -15,
      "name": "Rock_Stone_Brick"
    },
    {
      "x": -16,
      "y": 9,
      "z": -15,
      "name": "Rock_Stone_Brick"
    },
    {
      "x": -16,
      "y": 10,
      "z": -15,
      "name": "Rock_Stone_Brick"
    },
    {
      "x": -16,
      "y": 11,
      "z": -15,
      "name": "Rock_Stone_Brick"
    },
    {
      "x": -16,
      "y": 0,
      "z": -14,
      "name": "Rock_Stone_Brick"
    },
    {
      "x": -16,
      "y": 1,
      "z": -14,
      "name": "Rock_Stone_Brick"
    },
    {
      "x": -16,
      "y": 2,
      "z": -14,
      "name": "Rock_Stone_Brick"
    },
    {
      "x": -16,
      "y": 3,
      "z": -14,
      "name": "Rock_Stone_Brick"
    },
    {
      "x": -16,
      "y": 4,
      "z": -14,
      "name": "Rock_Stone_Brick"
    },
    {
      "x": -16,
      "y": 5,
      "z": -14,
      "name": "Rock_Stone_Brick"
    },
    {
      "x": -16,
      "y": 6,
      "z": -14,
      "name": "Rock_Stone_Brick"
    },
    {
      "x": -16,
      "y": 7,
      "z": -14,
      "name": "Rock_Stone_Brick"
    },
    {
      "x": -16,
      "y": 8,
      "z": -14,
      "name": "Rock_Stone_Brick"
    },
    {
      "x": -16,
      "y": 9,
      "z": -14,
      "name": "Rock_Stone_Brick"
    },
    {
      "x": -16,
      "y": 10,
      "z": -14,
      "name": "Rock_Stone_Brick"
    },
    {
      "x": -16,
      "y": 11,
      "z": -14,
      "name": "Rock_Stone_Brick"
    },
    {
      "x": -16,
      "y": 0,
      "z": -13,
      "name": "Rock_Stone_Brick"
    },
    {
      "x": -16,
      "y": 1,
      "z": -13,
      "name": "Rock_Stone_Brick"
    },
    {
      "x": -16,
      "y": 2,
      "z": -13,
      "name": "Rock_Stone_Brick"
    },
    {
      "x": -16,
      "y": 3,
      "z": -13,
      "name": "Rock_Stone_Brick"
    },
    {
      "x": -16,
      "y": 4,
      "z": -13,
      "name": "Rock_Stone_Brick"
    },
    {
      "x": -16,
      "y": 5,
      "z": -13,
      "name": "Rock_Stone_Brick"
    },
    {
      "x": -16,
      "y": 6,
      "z": -13,
      "name": "Rock_Stone_Brick"
    },
    {
      "x": -16,
      "y": 7,
      "z": -13,
      "name": "Rock_Stone_Brick"
    },
    {
      "x": -16,
      "y": 8,
      "z": -13,
      "name": "Rock_Stone_Brick"
    },
    {
      "x": -16,
      "y": 9,
      "z": -13,
      "name": "Rock_Stone_Brick"
    },
    {
      "x": -16,
      "y": 10,
      "z": -13,
      "name": "Rock_Stone_Brick"
    },
    {
      "x": -16,
      "y": 11,
      "z": -13,
      "name": "Rock_Stone_Brick"
    },
    {
      "x": -16,
      "y": 0,
      "z": -12,
      "name": "Rock_Stone_Brick"
    },
    {
      "x": -16,
      "y": 1,
      "z": -12,
      "name": "Rock_Stone_Brick"
    },
    {
      "x": -16,
      "y": 2,
      "z": -12,
      "name": "Rock_Stone_Brick"
    },
    {
      "x": -16,
      "y": 3,
      "z": -12,
      "name": "Rock_Stone_Brick"
    },
    {
      "x": -16,
      "y": 4,
      "z": -12,
      "name": "Rock_Stone_Brick"
    },
    {
      "x": -16,
      "y": 5,
      "z": -12,
      "name": "Rock_Stone_Brick"
    },
    {
      "x": -16,
      "y": 6,
      "z": -12,
      "name": "Rock_Stone_Brick"
    },
    {
      "x": -16,
      "y": 7,
      "z": -12,
      "name": "Rock_Stone_Brick"
    },
    {
      "x": -16,
      "y": 8,
      "z": -12,
      "name": "Rock_Stone_Brick"
    },
    {
      "x": -16,
      "y": 9,
      "z": -12,
      "name": "Rock_Stone_Brick"
    },
    {
      "x": -16,
      "y": 10,
      "z": -12,
      "name": "Rock_Stone_Brick"
    },
    {
      "x": -16,
      "y": 11,
      "z": -12,
      "name": "Rock_Stone_Brick"
    },
    {
      "x": -16,
      "y": 0,
      "z": -11,
      "name": "Rock_Stone_Brick"
    },
    {
      "x": -16,
      "y": 1,
      "z": -11,
      "name": "Rock_Stone_Brick"
    },
    {
      "x": -16,
      "y": 2,
      "z": -11,
      "name": "Rock_Stone_Brick"
    },
    {
      "x": -16,
      "y": 3,
      "z": -11,
      "name": "Rock_Stone_Brick"
    },
    {
      "x": -16,
      "y": 4,
      "z": -11,
      "name": "Rock_Stone_Brick"
    },
    {
      "x": -16,
      "y": 5,
      "z": -11,
      "name": "Rock_Stone_Brick"
    },
    {
      "x": -16,
      "y": 6,
      "z": -11,
      "name": "Rock_Stone_Brick"
    },
    {
      "x": -16,
      "y": 7,
      "z": -11,
      "name": "Rock_Stone_Brick"
    },
    {
      "x": -16,
      "y": 8,
      "z": -11,
      "name": "Rock_Stone_Brick"
    },
    {
      "x": -16,
      "y": 9,
      "z": -11,
      "name": "Rock_Stone_Brick"
    },
    {
      "x": -16,
      "y": 10,
      "z": -11,
      "name": "Rock_Stone_Brick"
    },
    {
      "x": -16,
      "y": 11,
      "z": -11,
      "name": "Rock_Stone_Brick"
    },
    {
      "x": -16,
      "y": 0,
      "z": -10,
      "name": "Rock_Stone_Brick"
    },
    {
      "x": -16,
      "y": 1,
      "z": -10,
      "name": "Rock_Stone_Brick"
    },
    {
      "x": -16,
      "y": 2,
      "z": -10,
      "name": "Rock_Stone_Brick"
    },
    {
      "x": -16,
      "y": 3,
      "z": -10,
      "name": "Rock_Stone_Brick"
    },
    {
      "x": -16,
      "y": 4,
      "z": -10,
      "name": "Rock_Stone_Brick"
    },
    {
      "x": -16,
      "y": 5,
      "z": -10,
      "name": "Rock_Stone_Brick"
    },
    {
      "x": -16,
      "y": 6,
      "z": -10,
      "name": "Rock_Stone_Brick"
    },
    {
      "x": -16,
      "y": 7,
      "z": -10,
      "name": "Rock_Stone_Brick"
    },
    {
      "x": -16,
      "y": 8,
      "z": -10,
      "name": "Rock_Stone_Brick"
    },
    {
      "x": -16,
      "y": 9,
      "z": -10,
      "name": "Rock_Stone_Brick"
    },
    {
      "x": -16,
      "y": 10,
      "z": -10,
      "name": "Rock_Stone_Brick"
    },
    {
      "x": -16,
      "y": 11,
      "z": -10,
      "name": "Rock_Stone_Brick"
    },
    {
      "x": -16,
      "y": 0,
      "z": -9,
      "name": "Rock_Stone_Brick"
    },
    {
      "x": -16,
      "y": 1,
      "z": -9,
      "name": "Rock_Stone_Brick"
    },
    {
      "x": -16,
      "y": 2,
      "z": -9,
      "name": "Rock_Stone_Brick"
    },
    {
      "x": -16,
      "y": 3,
      "z": -9,
      "name": "Rock_Stone_Brick"
    },
    {
      "x": -16,
      "y": 4,
      "z": -9,
      "name": "Rock_Stone_Brick"
    },
    {
      "x": -16,
      "y": 5,
      "z": -9,
      "name": "Rock_Stone_Brick"
    },
    {
      "x": -16,
      "y": 6,
      "z": -9,
      "name": "Rock_Stone_Brick"
    },
    {
      "x": -16,
      "y": 7,
      "z": -9,
      "name": "Rock_Stone_Brick"
    },
    {
      "x": -16,
      "y": 8,
      "z": -9,
      "name": "Rock_Stone_Brick"
    },
    {
      "x": -16,
      "y": 9,
      "z": -9,
      "name": "Rock_Stone_Brick"
    },
    {
      "x": -16,
      "y": 10,
      "z": -9,
      "name": "Rock_Stone_Brick"
    },
    {
      "x": -16,
      "y": 11,
      "z": -9,
      "name": "Rock_Stone_Brick"
    },
    {
      "x": -16,
      "y": 0,
      "z": -8,
      "name": "Rock_Stone_Brick"
    },
    {
      "x": -16,
      "y": 1,
      "z": -8,
      "name": "Rock_Stone_Brick"
    },
    {
      "x": -16,
      "y": 2,
      "z": -8,
      "name": "Rock_Stone_Brick"
    },
    {
      "x": -16,
      "y": 3,
      "z": -8,
      "name": "Rock_Stone_Brick"
    },
    {
      "x": -16,
      "y": 4,
      "z": -8,
      "name": "Rock_Stone_Brick"
    },
    {
      "x": -16,
      "y": 5,
      "z": -8,
      "name": "Rock_Stone_Brick"
    },
    {
      "x": -16,
      "y": 6,
      "z": -8,
      "name": "Rock_Stone_Brick"
    },
    {
      "x": -16,
      "y": 7,
      "z": -8,
      "name": "Rock_Stone_Brick"
    },
    {
      "x": -16,
      "y": 8,
      "z": -8,
      "name": "Rock_Stone_Brick"
    },
    {
      "x": -16,
      "y": 9,
      "z": -8,
      "name": "Rock_Stone_Brick"
    },
    {
      "x": -16,
      "y": 10,
      "z": -8,
      "name": "Rock_Stone_Brick"
    },
    {
      "x": -16,
      "y": 11,
      "z": -8,
      "name": "Rock_Stone_Brick"
    },
    {
      "x": -16,
      "y": 0,
      "z": -7,
      "name": "Rock_Stone_Brick"
    },
    {
      "x": -16,
      "y": 1,
      "z": -7,
      "name": "Rock_Stone_Brick"
    },
    {
      "x": -16,
      "y": 2,
      "z": -7,
      "name": "Rock_Stone_Brick"
    },
    {
      "x": -16,
      "y": 3,
      "z": -7,
      "name": "Rock_Stone_Brick"
    },
    {
      "x": -16,
      "y": 4,
      "z": -7,
      "name": "Rock_Stone_Brick"
    },
    {
      "x": -16,
      "y": 5,
      "z": -7,
      "name": "Rock_Stone_Brick"
    },
    {
      "x": -16,
      "y": 6,
      "z": -7,
      "name": "Rock_Stone_Brick"
    },
    {
      "x": -16,
      "y": 7,
      "z": -7,
      "name": "Rock_Stone_Brick"
    },
    {
      "x": -16,
      "y": 8,
      "z": -7,
      "name": "Rock_Stone_Brick"
    },
    {
      "x": -16,
      "y": 9,
      "z": -7,
      "name": "Rock_Stone_Brick"
    },
    {
      "x": -16,
      "y": 10,
      "z": -7,
      "name": "Rock_Stone_Brick"
    },
    {
      "x": -16,
      "y": 11,
      "z": -7,
      "name": "Rock_Stone_Brick"
    },
    {
      "x": -16,
      "y": 0,
      "z": -6,
      "name": "Rock_Stone_Brick"
    },
    {
      "x": -16,
      "y": 1,
      "z": -6,
      "name": "Rock_Stone_Brick"
    },
    {
      "x": -16,
      "y": 2,
      "z": -6,
      "name": "Rock_Stone_Brick"
    },
    {
      "x": -16,
      "y": 3,
      "z": -6,
      "name": "Rock_Stone_Brick"
    },
    {
      "x": -16,
      "y": 4,
      "z": -6,
      "name": "Rock_Stone_Brick"
    },
    {
      "x": -16,
      "y": 5,
      "z": -6,
      "name": "Rock_Stone_Brick"
    },
    {
      "x": -16,
      "y": 6,
      "z": -6,
      "name": "Rock_Stone_Brick"
    },
    {
      "x": -16,
      "y": 7,
      "z": -6,
      "name": "Rock_Stone_Brick"
    },
    {
      "x": -16,
      "y": 8,
      "z": -6,
      "name": "Rock_Stone_Brick"
    },
    {
      "x": -16,
      "y": 9,
      "z": -6,
      "name": "Rock_Stone_Brick"
    },
    {
      "x": -16,
      "y": 10,
      "z": -6,
      "name": "Rock_Stone_Brick"
    },
    {
      "x": -16,
      "y": 11,
      "z": -6,
      "name": "Rock_Stone_Brick"
    },
    {
      "x": -16,
      "y": 0,
      "z": -5,
      "name": "Rock_Stone_Brick"
    },
    {
      "x": -16,
      "y": 1,
      "z": -5,
      "name": "Rock_Stone_Brick"
    },
    {
      "x": -16,
      "y": 2,
      "z": -5,
      "name": "Rock_Stone_Brick"
    },
    {
      "x": -16,
      "y": 3,
      "z": -5,
      "name": "Rock_Stone_Brick"
    },
    {
      "x": -16,
      "y": 4,
      "z": -5,
      "name": "Rock_Stone_Brick"
    },
    {
      "x": -16,
      "y": 5,
      "z": -5,
      "name": "Rock_Stone_Brick"
    },
    {
      "x": -16,
      "y": 6,
      "z": -5,
      "name": "Rock_Stone_Brick"
    },
    {
      "x": -16,
      "y": 7,
      "z": -5,
      "name": "Rock_Stone_Brick"
    },
    {
      "x": -16,
      "y": 8,
      "z": -5,
      "name": "Rock_Stone_Brick"
    },
    {
      "x": -16,
      "y": 9,
      "z": -5,
      "name": "Rock_Stone_Brick"
    },
    {
      "x": -16,
      "y": 10,
      "z": -5,
      "name": "Rock_Stone_Brick"
    },
    {
      "x": -16,
      "y": 11,
      "z": -5,
      "name": "Rock_Stone_Brick"
    },
    {
      "x": -16,
      "y": 0,
      "z": -4,
      "name": "Rock_Stone_Brick"
    },
    {
      "x": -16,
      "y": 1,
      "z": -4,
      "name": "Rock_Stone_Brick"
    },
    {
      "x": -16,
      "y": 2,
      "z": -4,
      "name": "Rock_Stone_Brick"
    },
    {
      "x": -16,
      "y": 3,
      "z": -4,
      "name": "Rock_Stone_Brick"
    },
    {
      "x": -16,
      "y": 4,
      "z": -4,
      "name": "Rock_Stone_Brick"
    },
    {
      "x": -16,
      "y": 5,
      "z": -4,
      "name": "Rock_Stone_Brick"
    },
    {
      "x": -16,
      "y": 6,
      "z": -4,
      "name": "Rock_Stone_Brick"
    },
    {
      "x": -16,
      "y": 7,
      "z": -4,
      "name": "Rock_Stone_Brick"
    },
    {
      "x": -16,
      "y": 8,
      "z": -4,
      "name": "Rock_Stone_Brick"
    },
    {
      "x": -16,
      "y": 9,
      "z": -4,
      "name": "Rock_Stone_Brick"
    },
    {
      "x": -16,
      "y": 10,
      "z": -4,
      "name": "Rock_Stone_Brick"
    },
    {
      "x": -16,
      "y": 11,
      "z": -4,
      "name": "Rock_Stone_Brick"
    },
    {
      "x": -16,
      "y": 0,
      "z": -3,
      "name": "Rock_Stone_Brick"
    },
    {
      "x": -16,
      "y": 1,
      "z": -3,
      "name": "Rock_Stone_Brick"
    },
    {
      "x": -16,
      "y": 2,
      "z": -3,
      "name": "Rock_Stone_Brick"
    },
    {
      "x": -16,
      "y": 3,
      "z": -3,
      "name": "Rock_Stone_Brick"
    },
    {
      "x": -16,
      "y": 4,
      "z": -3,
      "name": "Rock_Stone_Brick"
    },
    {
      "x": -16,
      "y": 5,
      "z": -3,
      "name": "Rock_Stone_Brick"
    },
    {
      "x": -16,
      "y": 6,
      "z": -3,
      "name": "Rock_Stone_Brick"
    },
    {
      "x": -16,
      "y": 7,
      "z": -3,
      "name": "Rock_Stone_Brick"
    },
    {
      "x": -16,
      "y": 8,
      "z": -3,
      "name": "Rock_Stone_Brick"
    },
    {
      "x": -16,
      "y": 9,
      "z": -3,
      "name": "Rock_Stone_Brick"
    },
    {
      "x": -16,
      "y": 10,
      "z": -3,
      "name": "Rock_Stone_Brick"
    },
    {
      "x": -16,
      "y": 11,
      "z": -3,
      "name": "Rock_Stone_Brick"
    },
    {
      "x": -16,
      "y": 0,
      "z": -2,
      "name": "Rock_Stone_Brick"
    },
    {
      "x": -16,
      "y": 1,
      "z": -2,
      "name": "Rock_Stone_Brick"
    },
    {
      "x": -16,
      "y": 2,
      "z": -2,
      "name": "Rock_Stone_Brick"
    },
    {
      "x": -16,
      "y": 3,
      "z": -2,
      "name": "Rock_Stone_Brick"
    },
    {
      "x": -16,
      "y": 4,
      "z": -2,
      "name": "Rock_Stone_Brick"
    },
    {
      "x": -16,
      "y": 5,
      "z": -2,
      "name": "Rock_Stone_Brick"
    },
    {
      "x": -16,
      "y": 6,
      "z": -2,
      "name": "Rock_Stone_Brick"
    },
    {
      "x": -16,
      "y": 7,
      "z": -2,
      "name": "Rock_Stone_Brick"
    },
    {
      "x": -16,
      "y": 8,
      "z": -2,
      "name": "Rock_Stone_Brick"
    },
    {
      "x": -16,
      "y": 9,
      "z": -2,
      "name": "Rock_Stone_Brick"
    },
    {
      "x": -16,
      "y": 10,
      "z": -2,
      "name": "Rock_Stone_Brick"
    },
    {
      "x": -16,
      "y": 11,
      "z": -2,
      "name": "Rock_Stone_Brick"
    },
    {
      "x": -16,
      "y": 0,
      "z": -1,
      "name": "Rock_Stone_Brick"
    },
    {
      "x": -16,
      "y": 1,
      "z": -1,
      "name": "Rock_Stone_Brick"
    },
    {
      "x": -16,
      "y": 2,
      "z": -1,
      "name": "Rock_Stone_Brick"
    },
    {
      "x": -16,
      "y": 3,
      "z": -1,
      "name": "Rock_Stone_Brick"
    },
    {
      "x": -16,
      "y": 4,
      "z": -1,
      "name": "Rock_Stone_Brick"
    },
    {
      "x": -16,
      "y": 5,
      "z": -1,
      "name": "Rock_Stone_Brick"
    },
    {
      "x": -16,
      "y": 6,
      "z": -1,
      "name": "Rock_Stone_Brick"
    },
    {
      "x": -16,
      "y": 7,
      "z": -1,
      "name": "Rock_Stone_Brick"
    },
    {
      "x": -16,
      "y": 8,
      "z": -1,
      "name": "Rock_Stone_Brick"
    },
    {
      "x": -16,
      "y": 9,
      "z": -1,
      "name": "Rock_Stone_Brick"
    },
    {
      "x": -16,
      "y": 10,
      "z": -1,
      "name": "Rock_Stone_Brick"
    },
    {
      "x": -16,
      "y": 11,
      "z": -1,
      "name": "Rock_Stone_Brick"
    },
    {
      "x": -16,
      "y": 0,
      "z": 0,
      "name": "Rock_Stone_Brick"
    },
    {
      "x": -16,
      "y": 1,
      "z": 0,
      "name": "Rock_Stone_Brick"
    },
    {
      "x": -16,
      "y": 2,
      "z": 0,
      "name": "Rock_Stone_Brick"
    },
    {
      "x": -16,
      "y": 3,
      "z": 0,
      "name": "Rock_Stone_Brick"
    },
    {
      "x": -16,
      "y": 4,
      "z": 0,
      "name": "Rock_Stone_Brick"
    },
    {
      "x": -16,
      "y": 5,
      "z": 0,
      "name": "Rock_Stone_Brick"
    },
    {
      "x": -16,
      "y": 6,
      "z": 0,
      "name": "Rock_Stone_Brick"
    },
    {
      "x": -16,
      "y": 7,
      "z": 0,
      "name": "Rock_Stone_Brick"
    },
    {
      "x": -16,
      "y": 8,
      "z": 0,
      "name": "Rock_Stone_Brick"
    },
    {
      "x": -16,
      "y": 9,
      "z": 0,
      "name": "Rock_Stone_Brick"
    },
    {
      "x": -16,
      "y": 10,
      "z": 0,
      "name": "Rock_Stone_Brick"
    },
    {
      "x": -16,
      "y": 11,
      "z": 0,
      "name": "Rock_Stone_Brick"
    },
    {
      "x": -16,
      "y": 0,
      "z": 1,
      "name": "Rock_Stone_Brick"
    },
    {
      "x": -16,
      "y": 1,
      "z": 1,
      "name": "Rock_Stone_Brick"
    },
    {
      "x": -16,
      "y": 2,
      "z": 1,
      "name": "Rock_Stone_Brick"
    },
    {
      "x": -16,
      "y": 3,
      "z": 1,
      "name": "Rock_Stone_Brick"
    },
    {
      "x": -16,
      "y": 4,
      "z": 1,
      "name": "Rock_Stone_Brick"
    },
    {
      "x": -16,
      "y": 5,
      "z": 1,
      "name": "Rock_Stone_Brick"
    },
    {
      "x": -16,
      "y": 6,
      "z": 1,
      "name": "Rock_Stone_Brick"
    },
    {
      "x": -16,
      "y": 7,
      "z": 1,
      "name": "Rock_Stone_Brick"
    },
    {
      "x": -16,
      "y": 8,
      "z": 1,
      "name": "Rock_Stone_Brick"
    },
    {
      "x": -16,
      "y": 9,
      "z": 1,
      "name": "Rock_Stone_Brick"
    },
    {
      "x": -16,
      "y": 10,
      "z": 1,
      "name": "Rock_Stone_Brick"
    },
    {
      "x": -16,
      "y": 11,
      "z": 1,
      "name": "Rock_Stone_Brick"
    },
    {
      "x": -16,
      "y": 0,
      "z": 2,
      "name": "Rock_Stone_Brick"
    },
    {
      "x": -16,
      "y": 1,
      "z": 2,
      "name": "Rock_Stone_Brick"
    },
    {
      "x": -16,
      "y": 2,
      "z": 2,
      "name": "Rock_Stone_Brick"
    },
    {
      "x": -16,
      "y": 3,
      "z": 2,
      "name": "Rock_Stone_Brick"
    },
    {
      "x": -16,
      "y": 4,
      "z": 2,
      "name": "Rock_Stone_Brick"
    },
    {
      "x": -16,
      "y": 5,
      "z": 2,
      "name": "Rock_Stone_Brick"
    },
    {
      "x": -16,
      "y": 6,
      "z": 2,
      "name": "Rock_Stone_Brick"
    },
    {
      "x": -16,
      "y": 7,
      "z": 2,
      "name": "Rock_Stone_Brick"
    },
    {
      "x": -16,
      "y": 8,
      "z": 2,
      "name": "Rock_Stone_Brick"
    },
    {
      "x": -16,
      "y": 9,
      "z": 2,
      "name": "Rock_Stone_Brick"
    },
    {
      "x": -16,
      "y": 10,
      "z": 2,
      "name": "Rock_Stone_Brick"
    },
    {
      "x": -16,
      "y": 11,
      "z": 2,
      "name": "Rock_Stone_Brick"
    },
    {
      "x": -16,
      "y": 0,
      "z": 3,
      "name": "Rock_Stone_Brick"
    },
    {
      "x": -16,
      "y": 1,
      "z": 3,
      "name": "Rock_Stone_Brick"
    },
    {
      "x": -16,
      "y": 2,
      "z": 3,
      "name": "Rock_Stone_Brick"
    },
    {
      "x": -16,
      "y": 3,
      "z": 3,
      "name": "Rock_Stone_Brick"
    },
    {
      "x": -16,
      "y": 4,
      "z": 3,
      "name": "Rock_Stone_Brick"
    },
    {
      "x": -16,
      "y": 5,
      "z": 3,
      "name": "Rock_Stone_Brick"
    },
    {
      "x": -16,
      "y": 6,
      "z": 3,
      "name": "Rock_Stone_Brick"
    },
    {
      "x": -16,
      "y": 7,
      "z": 3,
      "name": "Rock_Stone_Brick"
    },
    {
      "x": -16,
      "y": 8,
      "z": 3,
      "name": "Rock_Stone_Brick"
    },
    {
      "x": -16,
      "y": 9,
      "z": 3,
      "name": "Rock_Stone_Brick"
    },
    {
      "x": -16,
      "y": 10,
      "z": 3,
      "name": "Rock_Stone_Brick"
    },
    {
      "x": -16,
      "y": 11,
      "z": 3,
      "name": "Rock_Stone_Brick"
    },
    {
      "x": -16,
      "y": 0,
      "z": 4,
      "name": "Rock_Stone_Brick"
    },
    {
      "x": -16,
      "y": 1,
      "z": 4,
      "name": "Rock_Stone_Brick"
    },
    {
      "x": -16,
      "y": 2,
      "z": 4,
      "name": "Rock_Stone_Brick"
    },
    {
      "x": -16,
      "y": 3,
      "z": 4,
      "name": "Rock_Stone_Brick"
    },
    {
      "x": -16,
      "y": 4,
      "z": 4,
      "name": "Rock_Stone_Brick"
    },
    {
      "x": -16,
      "y": 5,
      "z": 4,
      "name": "Rock_Stone_Brick"
    },
    {
      "x": -16,
      "y": 6,
      "z": 4,
      "name": "Rock_Stone_Brick"
    },
    {
      "x": -16,
      "y": 7,
      "z": 4,
      "name": "Rock_Stone_Brick"
    },
    {
      "x": -16,
      "y": 8,
      "z": 4,
      "name": "Rock_Stone_Brick"
    },
    {
      "x": -16,
      "y": 9,
      "z": 4,
      "name": "Rock_Stone_Brick"
    },
    {
      "x": -16,
      "y": 10,
      "z": 4,
      "name": "Rock_Stone_Brick"
    },
    {
      "x": -16,
      "y": 11,
      "z": 4,
      "name": "Rock_Stone_Brick"
    },
    {
      "x": -16,
      "y": 0,
      "z": 5,
      "name": "Rock_Stone_Brick"
    },
    {
      "x": -16,
      "y": 1,
      "z": 5,
      "name": "Rock_Stone_Brick"
    },
    {
      "x": -16,
      "y": 2,
      "z": 5,
      "name": "Rock_Stone_Brick"
    },
    {
      "x": -16,
      "y": 3,
      "z": 5,
      "name": "Rock_Stone_Brick"
    },
    {
      "x": -16,
      "y": 4,
      "z": 5,
      "name": "Rock_Stone_Brick"
    },
    {
      "x": -16,
      "y": 5,
      "z": 5,
      "name": "Rock_Stone_Brick"
    },
    {
      "x": -16,
      "y": 6,
      "z": 5,
      "name": "Rock_Stone_Brick"
    },
    {
      "x": -16,
      "y": 7,
      "z": 5,
      "name": "Rock_Stone_Brick"
    },
    {
      "x": -16,
      "y": 8,
      "z": 5,
      "name": "Rock_Stone_Brick"
    },
    {
      "x": -16,
      "y": 9,
      "z": 5,
      "name": "Rock_Stone_Brick"
    },
    {
      "x": -16,
      "y": 10,
      "z": 5,
      "name": "Rock_Stone_Brick"
    },
    {
      "x": -16,
      "y": 11,
      "z": 5,
      "name": "Rock_Stone_Brick"
    },
    {
      "x": -16,
      "y": 0,
      "z": 6,
      "name": "Rock_Stone_Brick"
    },
    {
      "x": -16,
      "y": 1,
      "z": 6,
      "name": "Rock_Stone_Brick"
    },
    {
      "x": -16,
      "y": 2,
      "z": 6,
      "name": "Rock_Stone_Brick"
    },
    {
      "x": -16,
      "y": 3,
      "z": 6,
      "name": "Rock_Stone_Brick"
    },
    {
      "x": -16,
      "y": 4,
      "z": 6,
      "name": "Rock_Stone_Brick"
    },
    {
      "x": -16,
      "y": 5,
      "z": 6,
      "name": "Rock_Stone_Brick"
    },
    {
      "x": -16,
      "y": 6,
      "z": 6,
      "name": "Rock_Stone_Brick"
    },
    {
      "x": -16,
      "y": 7,
      "z": 6,
      "name": "Rock_Stone_Brick"
    },
    {
      "x": -16,
      "y": 8,
      "z": 6,
      "name": "Rock_Stone_Brick"
    },
    {
      "x": -16,
      "y": 9,
      "z": 6,
      "name": "Rock_Stone_Brick"
    },
    {
      "x": -16,
      "y": 10,
      "z": 6,
      "name": "Rock_Stone_Brick"
    },
    {
      "x": -16,
      "y": 11,
      "z": 6,
      "name": "Rock_Stone_Brick"
    },
    {
      "x": -16,
      "y": 0,
      "z": 7,
      "name": "Rock_Stone_Brick"
    },
    {
      "x": -16,
      "y": 1,
      "z": 7,
      "name": "Rock_Stone_Brick"
    },
    {
      "x": -16,
      "y": 2,
      "z": 7,
      "name": "Rock_Stone_Brick"
    },
    {
      "x": -16,
      "y": 3,
      "z": 7,
      "name": "Rock_Stone_Brick"
    },
    {
      "x": -16,
      "y": 4,
      "z": 7,
      "name": "Rock_Stone_Brick"
    },
    {
      "x": -16,
      "y": 5,
      "z": 7,
      "name": "Rock_Stone_Brick"
    },
    {
      "x": -16,
      "y": 6,
      "z": 7,
      "name": "Rock_Stone_Brick"
    },
    {
      "x": -16,
      "y": 7,
      "z": 7,
      "name": "Rock_Stone_Brick"
    },
    {
      "x": -16,
      "y": 8,
      "z": 7,
      "name": "Rock_Stone_Brick"
    },
    {
      "x": -16,
      "y": 9,
      "z": 7,
      "name": "Rock_Stone_Brick"
    },
    {
      "x": -16,
      "y": 10,
      "z": 7,
      "name": "Rock_Stone_Brick"
    },
    {
      "x": -16,
      "y": 11,
      "z": 7,
      "name": "Rock_Stone_Brick"
    },
    {
      "x": -16,
      "y": 0,
      "z": 8,
      "name": "Rock_Stone_Brick"
    },
    {
      "x": -16,
      "y": 1,
      "z": 8,
      "name": "Rock_Stone_Brick"
    },
    {
      "x": -16,
      "y": 2,
      "z": 8,
      "name": "Rock_Stone_Brick"
    },
    {
      "x": -16,
      "y": 3,
      "z": 8,
      "name": "Rock_Stone_Brick"
    },
    {
      "x": -16,
      "y": 4,
      "z": 8,
      "name": "Rock_Stone_Brick"
    },
    {
      "x": -16,
      "y": 5,
      "z": 8,
      "name": "Rock_Stone_Brick"
    },
    {
      "x": -16,
      "y": 6,
      "z": 8,
      "name": "Rock_Stone_Brick"
    },
    {
      "x": -16,
      "y": 7,
      "z": 8,
      "name": "Rock_Stone_Brick"
    },
    {
      "x": -16,
      "y": 8,
      "z": 8,
      "name": "Rock_Stone_Brick"
    },
    {
      "x": -16,
      "y": 9,
      "z": 8,
      "name": "Rock_Stone_Brick"
    },
    {
      "x": -16,
      "y": 10,
      "z": 8,
      "name": "Rock_Stone_Brick"
    },
    {
      "x": -16,
      "y": 11,
      "z": 8,
      "name": "Rock_Stone_Brick"
    },
    {
      "x": -16,
      "y": 0,
      "z": 9,
      "name": "Rock_Stone_Brick"
    },
    {
      "x": -16,
      "y": 1,
      "z": 9,
      "name": "Rock_Stone_Brick"
    },
    {
      "x": -16,
      "y": 2,
      "z": 9,
      "name": "Rock_Stone_Brick"
    },
    {
      "x": -16,
      "y": 3,
      "z": 9,
      "name": "Rock_Stone_Brick"
    },
    {
      "x": -16,
      "y": 4,
      "z": 9,
      "name": "Rock_Stone_Brick"
    },
    {
      "x": -16,
      "y": 5,
      "z": 9,
      "name": "Rock_Stone_Brick"
    },
    {
      "x": -16,
      "y": 6,
      "z": 9,
      "name": "Rock_Stone_Brick"
    },
    {
      "x": -16,
      "y": 7,
      "z": 9,
      "name": "Rock_Stone_Brick"
    },
    {
      "x": -16,
      "y": 8,
      "z": 9,
      "name": "Rock_Stone_Brick"
    },
    {
      "x": -16,
      "y": 9,
      "z": 9,
      "name": "Rock_Stone_Brick"
    },
    {
      "x": -16,
      "y": 10,
      "z": 9,
      "name": "Rock_Stone_Brick"
    },
    {
      "x": -16,
      "y": 11,
      "z": 9,
      "name": "Rock_Stone_Brick"
    },
    {
      "x": -16,
      "y": 0,
      "z": 10,
      "name": "Rock_Stone_Brick"
    },
    {
      "x": -16,
      "y": 1,
      "z": 10,
      "name": "Rock_Stone_Brick"
    },
    {
      "x": -16,
      "y": 2,
      "z": 10,
      "name": "Rock_Stone_Brick"
    },
    {
      "x": -16,
      "y": 3,
      "z": 10,
      "name": "Rock_Stone_Brick"
    },
    {
      "x": -16,
      "y": 4,
      "z": 10,
      "name": "Rock_Stone_Brick"
    },
    {
      "x": -16,
      "y": 5,
      "z": 10,
      "name": "Rock_Stone_Brick"
    },
    {
      "x": -16,
      "y": 6,
      "z": 10,
      "name": "Rock_Stone_Brick"
    },
    {
      "x": -16,
      "y": 7,
      "z": 10,
      "name": "Rock_Stone_Brick"
    },
    {
      "x": -16,
      "y": 8,
      "z": 10,
      "name": "Rock_Stone_Brick"
    },
    {
      "x": -16,
      "y": 9,
      "z": 10,
      "name": "Rock_Stone_Brick"
    },
    {
      "x": -16,
      "y": 10,
      "z": 10,
      "name": "Rock_Stone_Brick"
    },
    {
      "x": -16,
      "y": 11,
      "z": 10,
      "name": "Rock_Stone_Brick"
    },
    {
      "x": -16,
      "y": 0,
      "z": 11,
      "name": "Rock_Stone_Brick"
    },
    {
      "x": -16,
      "y": 1,
      "z": 11,
      "name": "Rock_Stone_Brick"
    },
    {
      "x": -16,
      "y": 2,
      "z": 11,
      "name": "Rock_Stone_Brick"
    },
    {
      "x": -16,
      "y": 3,
      "z": 11,
      "name": "Rock_Stone_Brick"
    },
    {
      "x": -16,
      "y": 4,
      "z": 11,
      "name": "Rock_Stone_Brick"
    },
    {
      "x": -16,
      "y": 5,
      "z": 11,
      "name": "Rock_Stone_Brick"
    },
    {
      "x": -16,
      "y": 6,
      "z": 11,
      "name": "Rock_Stone_Brick"
    },
    {
      "x": -16,
      "y": 7,
      "z": 11,
      "name": "Rock_Stone_Brick"
    },
    {
      "x": -16,
      "y": 8,
      "z": 11,
      "name": "Rock_Stone_Brick"
    },
    {
      "x": -16,
      "y": 9,
      "z": 11,
      "name": "Rock_Stone_Brick"
    },
    {
      "x": -16,
      "y": 10,
      "z": 11,
      "name": "Rock_Stone_Brick"
    },
    {
      "x": -16,
      "y": 11,
      "z": 11,
      "name": "Rock_Stone_Brick"
    },
    {
      "x": -16,
      "y": 0,
      "z": 12,
      "name": "Rock_Stone_Brick"
    },
    {
      "x": -16,
      "y": 1,
      "z": 12,
      "name": "Rock_Stone_Brick"
    },
    {
      "x": -16,
      "y": 2,
      "z": 12,
      "name": "Rock_Stone_Brick"
    },
    {
      "x": -16,
      "y": 3,
      "z": 12,
      "name": "Rock_Stone_Brick"
    },
    {
      "x": -16,
      "y": 4,
      "z": 12,
      "name": "Rock_Stone_Brick"
    },
    {
      "x": -16,
      "y": 5,
      "z": 12,
      "name": "Rock_Stone_Brick"
    },
    {
      "x": -16,
      "y": 6,
      "z": 12,
      "name": "Rock_Stone_Brick"
    },
    {
      "x": -16,
      "y": 7,
      "z": 12,
      "name": "Rock_Stone_Brick"
    },
    {
      "x": -16,
      "y": 8,
      "z": 12,
      "name": "Rock_Stone_Brick"
    },
    {
      "x": -16,
      "y": 9,
      "z": 12,
      "name": "Rock_Stone_Brick"
    },
    {
      "x": -16,
      "y": 10,
      "z": 12,
      "name": "Rock_Stone_Brick"
    },
    {
      "x": -16,
      "y": 11,
      "z": 12,
      "name": "Rock_Stone_Brick"
    },
    {
      "x": -16,
      "y": 0,
      "z": 13,
      "name": "Rock_Stone_Brick"
    },
    {
      "x": -16,
      "y": 1,
      "z": 13,
      "name": "Rock_Stone_Brick"
    },
    {
      "x": -16,
      "y": 2,
      "z": 13,
      "name": "Rock_Stone_Brick"
    },
    {
      "x": -16,
      "y": 3,
      "z": 13,
      "name": "Rock_Stone_Brick"
    },
    {
      "x": -16,
      "y": 4,
      "z": 13,
      "name": "Rock_Stone_Brick"
    },
    {
      "x": -16,
      "y": 5,
      "z": 13,
      "name": "Rock_Stone_Brick"
    },
    {
      "x": -16,
      "y": 6,
      "z": 13,
      "name": "Rock_Stone_Brick"
    },
    {
      "x": -16,
      "y": 7,
      "z": 13,
      "name": "Rock_Stone_Brick"
    },
    {
      "x": -16,
      "y": 8,
      "z": 13,
      "name": "Rock_Stone_Brick"
    },
    {
      "x": -16,
      "y": 9,
      "z": 13,
      "name": "Rock_Stone_Brick"
    },
    {
      "x": -16,
      "y": 10,
      "z": 13,
      "name": "Rock_Stone_Brick"
    },
    {
      "x": -16,
      "y": 11,
      "z": 13,
      "name": "Rock_Stone_Brick"
    },
    {
      "x": -16,
      "y": 0,
      "z": 14,
      "name": "Rock_Stone_Brick"
    },
    {
      "x": -16,
      "y": 1,
      "z": 14,
      "name": "Rock_Stone_Brick"
    },
    {
      "x": -16,
      "y": 2,
      "z": 14,
      "name": "Rock_Stone_Brick"
    },
    {
      "x": -16,
      "y": 3,
      "z": 14,
      "name": "Rock_Stone_Brick"
    },
    {
      "x": -16,
      "y": 4,
      "z": 14,
      "name": "Rock_Stone_Brick"
    },
    {
      "x": -16,
      "y": 5,
      "z": 14,
      "name": "Rock_Stone_Brick"
    },
    {
      "x": -16,
      "y": 6,
      "z": 14,
      "name": "Rock_Stone_Brick"
    },
    {
      "x": -16,
      "y": 7,
      "z": 14,
      "name": "Rock_Stone_Brick"
    },
    {
      "x": -16,
      "y": 8,
      "z": 14,
      "name": "Rock_Stone_Brick"
    },
    {
      "x": -16,
      "y": 9,
      "z": 14,
      "name": "Rock_Stone_Brick"
    },
    {
      "x": -16,
      "y": 10,
      "z": 14,
      "name": "Rock_Stone_Brick"
    },
    {
      "x": -16,
      "y": 11,
      "z": 14,
      "name": "Rock_Stone_Brick"
    },
    {
      "x": -16,
      "y": 0,
      "z": 15,
      "name": "Rock_Stone_Brick"
    },
    {
      "x": -16,
      "y": 1,
      "z": 15,
      "name": "Rock_Stone_Brick"
    },
    {
      "x": -16,
      "y": 2,
      "z": 15,
      "name": "Rock_Stone_Brick"
    },
    {
      "x": -16,
      "y": 3,
      "z": 15,
      "name": "Rock_Stone_Brick"
    },
    {
      "x": -16,
      "y": 4,
      "z": 15,
      "name": "Rock_Stone_Brick"
    },
    {
      "x": -16,
      "y": 5,
      "z": 15,
      "name": "Rock_Stone_Brick"
    },
    {
      "x": -16,
      "y": 6,
      "z": 15,
      "name": "Rock_Stone_Brick"
    },
    {
      "x": -16,
      "y": 7,
      "z": 15,
      "name": "Rock_Stone_Brick"
    },
    {
      "x": -16,
      "y": 8,
      "z": 15,
      "name": "Rock_Stone_Brick"
    },
    {
      "x": -16,
      "y": 9,
      "z": 15,
      "name": "Rock_Stone_Brick"
    },
    {
      "x": -16,
      "y": 10,
      "z": 15,
      "name": "Rock_Stone_Brick"
    },
    {
      "x": -16,
      "y": 11,
      "z": 15,
      "name": "Rock_Stone_Brick"
    },
    {
      "x": -16,
      "y": 0,
      "z": 16,
      "name": "Rock_Stone_Brick"
    },
    {
      "x": -16,
      "y": 1,
      "z": 16,
      "name": "Rock_Stone_Brick"
    },
    {
      "x": -16,
      "y": 2,
      "z": 16,
      "name": "Rock_Stone_Brick"
    },
    {
      "x": -16,
      "y": 3,
      "z": 16,
      "name": "Rock_Stone_Brick"
    },
    {
      "x": -16,
      "y": 4,
      "z": 16,
      "name": "Rock_Stone_Brick"
    },
    {
      "x": -16,
      "y": 5,
      "z": 16,
      "name": "Rock_Stone_Brick"
    },
    {
      "x": -16,
      "y": 6,
      "z": 16,
      "name": "Rock_Stone_Brick"
    },
    {
      "x": -16,
      "y": 7,
      "z": 16,
      "name": "Rock_Stone_Brick"
    },
    {
      "x": -16,
      "y": 8,
      "z": 16,
      "name": "Rock_Stone_Brick"
    },
    {
      "x": -16,
      "y": 9,
      "z": 16,
      "name": "Rock_Stone_Brick"
    },
    {
      "x": -16,
      "y": 10,
      "z": 16,
      "name": "Rock_Stone_Brick"
    },
    {
      "x": -16,
      "y": 11,
      "z": 16,
      "name": "Rock_Stone_Brick"
    },
    {
      "x": -15,
      "y": 0,
      "z": -16,
      "name": "Rock_Stone_Brick"
    },
    {
      "x": -15,
      "y": 1,
      "z": -16,
      "name": "Rock_Stone_Brick"
    },
    {
      "x": -15,
      "y": 2,
      "z": -16,
      "name": "Rock_Stone_Brick"
    },
    {
      "x": -15,
      "y": 3,
      "z": -16,
      "name": "Rock_Stone_Brick"
    },
    {
      "x": -15,
      "y": 4,
      "z": -16,
      "name": "Rock_Stone_Brick"
    },
    {
      "x": -15,
      "y": 5,
      "z": -16,
      "name": "Rock_Stone_Brick"
    },
    {
      "x": -15,
      "y": 6,
      "z": -16,
      "name": "Rock_Stone_Brick"
    },
    {
      "x": -15,
      "y": 7,
      "z": -16,
      "name": "Rock_Stone_Brick"
    },
    {
      "x": -15,
      "y": 8,
      "z": -16,
      "name": "Rock_Stone_Brick"
    },
    {
      "x": -15,
      "y": 9,
      "z": -16,
      "name": "Rock_Stone_Brick"
    },
    {
      "x": -15,
      "y": 10,
      "z": -16,
      "name": "Rock_Stone_Brick"
    },
    {
      "x": -15,
      "y": 11,
      "z": -16,
      "name": "Rock_Stone_Brick"
    },
    {
      "x": -15,
      "y": 0,
      "z": -15,
      "name": "Rock_Stone_Brick"
    },
    {
      "x": -15,
      "y": 11,
      "z": -15,
      "name": "Rock_Stone_Brick"
    },
    {
      "x": -15,
      "y": 0,
      "z": -14,
      "name": "Rock_Stone_Brick"
    },
    {
      "x": -15,
      "y": 11,
      "z": -14,
      "name": "Rock_Stone_Brick"
    },
    {
      "x": -15,
      "y": 0,
      "z": -13,
      "name": "Rock_Stone_Brick"
    },
    {
      "x": -15,
      "y": 11,
      "z": -13,
      "name": "Rock_Stone_Brick"
    },
    {
      "x": -15,
      "y": 0,
      "z": -12,
      "name": "Rock_Stone_Brick"
    },
    {
      "x": -15,
      "y": 11,
      "z": -12,
      "name": "Rock_Stone_Brick"
    },
    {
      "x": -15,
      "y": 0,
      "z": -11,
      "name": "Rock_Stone_Brick"
    },
    {
      "x": -15,
      "y": 11,
      "z": -11,
      "name": "Rock_Stone_Brick"
    },
    {
      "x": -15,
      "y": 0,
      "z": -10,
      "name": "Rock_Stone_Brick"
    },
    {
      "x": -15,
      "y": 11,
      "z": -10,
      "name": "Rock_Stone_Brick"
    },
    {
      "x": -15,
      "y": 0,
      "z": -9,
      "name": "Rock_Stone_Brick"
    },
    {
      "x": -15,
      "y": 11,
      "z": -9,
      "name": "Rock_Stone_Brick"
    },
    {
      "x": -15,
      "y": 0,
      "z": -8,
      "name": "Rock_Stone_Brick"
    },
    {
      "x": -15,
      "y": 11,
      "z": -8,
      "name": "Rock_Stone_Brick"
    },
    {
      "x": -15,
      "y": 0,
      "z": -7,
      "name": "Rock_Stone_Brick"
    },
    {
      "x": -15,
      "y": 11,
      "z": -7,
      "name": "Rock_Stone_Brick"
    },
    {
      "x": -15,
      "y": 0,
      "z": -6,
      "name": "Rock_Stone_Brick"
    },
    {
      "x": -15,
      "y": 11,
      "z": -6,
      "name": "Rock_Stone_Brick"
    },
    {
      "x": -15,
      "y": 0,
      "z": -5,
      "name": "Rock_Stone_Brick"
    },
    {
      "x": -15,
      "y": 11,
      "z": -5,
      "name": "Rock_Stone_Brick"
    },
    {
      "x": -15,
      "y": 0,
      "z": -4,
      "name": "Rock_Stone_Brick"
    },
    {
      "x": -15,
      "y": 11,
      "z": -4,
      "name": "Rock_Stone_Brick"
    },
    {
      "x": -15,
      "y": 0,
      "z": -3,
      "name": "Rock_Stone_Brick"
    },
    {
      "x": -15,
      "y": 11,
      "z": -3,
      "name": "Rock_Stone_Brick"
    },
    {
      "x": -15,
      "y": 0,
      "z": -2,
      "name": "Rock_Stone_Brick"
    },
    {
      "x": -15,
      "y": 11,
      "z": -2,
      "name": "Rock_Stone_Brick"
    },
    {
      "x": -15,
      "y": 0,
      "z": -1,
      "name": "Rock_Stone_Brick"
    },
    {
      "x": -15,
      "y": 11,
      "z": -1,
      "name": "Rock_Stone_Brick"
    },
    {
      "x": -15,
      "y": 0,
      "z": 0,
      "name": "Rock_Stone_Brick"
    },
    {
      "x": -15,
      "y": 11,
      "z": 0,
      "name": "Rock_Stone_Brick"
    },
    {
      "x": -15,
      "y": 0,
      "z": 1,
      "name": "Rock_Stone_Brick"
    },
    {
      "x": -15,
      "y": 11,
      "z": 1,
      "name": "Rock_Stone_Brick"
    },
    {
      "x": -15,
      "y": 0,
      "z": 2,
      "name": "Rock_Stone_Brick"
    },
    {
      "x": -15,
      "y": 11,
      "z": 2,
      "name": "Rock_Stone_Brick"
    },
    {
      "x": -15,
      "y": 0,
      "z": 3,
      "name": "Rock_Stone_Brick"
    },
    {
      "x": -15,
      "y": 11,
      "z": 3,
      "name": "Rock_Stone_Brick"
    },
    {
      "x": -15,
      "y": 0,
      "z": 4,
      "name": "Rock_Stone_Brick"
    },
    {
      "x": -15,
      "y": 11,
      "z": 4,
      "name": "Rock_Stone_Brick"
    },
    {
      "x": -15,
      "y": 0,
      "z": 5,
      "name": "Rock_Stone_Brick"
    },
    {
      "x": -15,
      "y": 11,
      "z": 5,
      "name": "Rock_Stone_Brick"
    },
    {
      "x": -15,
      "y": 0,
      "z": 6,
      "name": "Rock_Stone_Brick"
    },
    {
      "x": -15,
      "y": 11,
      "z": 6,
      "name": "Rock_Stone_Brick"
    },
    {
      "x": -15,
      "y": 0,
      "z": 7,
      "name": "Rock_Stone_Brick"
    },
    {
      "x": -15,
      "y": 11,
      "z": 7,
      "name": "Rock_Stone_Brick"
    },
    {
      "x": -15,
      "y": 0,
      "z": 8,
      "name": "Rock_Stone_Brick"
    },
    {
      "x": -15,
      "y": 11,
      "z": 8,
      "name": "Rock_Stone_Brick"
    },
    {
      "x": -15,
      "y": 0,
      "z": 9,
      "name": "Rock_Stone_Brick"
    },
    {
      "x": -15,
      "y": 11,
      "z": 9,
      "name": "Rock_Stone_Brick"
    },
    {
      "x": -15,
      "y": 0,
      "z": 10,
      "name": "Rock_Stone_Brick"
    },
    {
      "x": -15,
      "y": 11,
      "z": 10,
      "name": "Rock_Stone_Brick"
    },
    {
      "x": -15,
      "y": 0,
      "z": 11,
      "name": "Rock_Stone_Brick"
    },
    {
      "x": -15,
      "y": 11,
      "z": 11,
      "name": "Rock_Stone_Brick"
    },
    {
      "x": -15,
      "y": 0,
      "z": 12,
      "name": "Rock_Stone_Brick"
    },
    {
      "x": -15,
      "y": 11,
      "z": 12,
      "name": "Rock_Stone_Brick"
    },
    {
      "x": -15,
      "y": 0,
      "z": 13,
      "name": "Rock_Stone_Brick"
    },
    {
      "x": -15,
      "y": 11,
      "z": 13,
      "name": "Rock_Stone_Brick"
    },
    {
      "x": -15,
      "y": 0,
      "z": 14,
      "name": "Rock_Stone_Brick"
    },
    {
      "x": -15,
      "y": 11,
      "z": 14,
      "name": "Rock_Stone_Brick"
    },
    {
      "x": -15,
      "y": 0,
      "z": 15,
      "name": "Rock_Stone_Brick"
    },
    {
      "x": -15,
      "y": 11,
      "z": 15,
      "name": "Rock_Stone_Brick"
    },
    {
      "x": -15,
      "y": 0,
      "z": 16,
      "name": "Rock_Stone_Brick"
    },
    {
      "x": -15,
      "y": 1,
      "z": 16,
      "name": "Rock_Stone_Brick"
    },
    {
      "x": -15,
      "y": 2,
      "z": 16,
      "name": "Rock_Stone_Brick"
    },
    {
      "x": -15,
      "y": 3,
      "z": 16,
      "name": "Rock_Stone_Brick"
    },
    {
      "x": -15,
      "y": 4,
      "z": 16,
      "name": "Rock_Stone_Brick"
    },
    {
      "x": -15,
      "y": 5,
      "z": 16,
      "name": "Rock_Stone_Brick"
    },
    {
      "x": -15,
      "y": 6,
      "z": 16,
      "name": "Rock_Stone_Brick"
    },
    {
      "x": -15,
      "y": 7,
      "z": 16,
      "name": "Rock_Stone_Brick"
    },
    {
      "x": -15,
      "y": 8,
      "z": 16,
      "name": "Rock_Stone_Brick"
    },
    {
      "x": -15,
      "y": 9,
      "z": 16,
      "name": "Rock_Stone_Brick"
    },
    {
      "x": -15,
      "y": 10,
      "z": 16,
      "name": "Rock_Stone_Brick"
    },
    {
      "x": -15,
      "y": 11,
      "z": 16,
      "name": "Rock_Stone_Brick"
    },
    {
      "x": -14,
      "y": 0,
      "z": -16,
      "name": "Rock_Stone_Brick"
    },
    {
      "x": -14,
      "y": 1,
      "z": -16,
      "name": "Rock_Stone_Brick"
    },
    {
      "x": -14,
      "y": 2,
      "z": -16,
      "name": "Rock_Stone_Brick"
    },
    {
      "x": -14,
      "y": 3,
      "z": -16,
      "name": "Rock_Stone_Brick"
    },
    {
      "x": -14,
      "y": 4,
      "z": -16,
      "name": "Rock_Stone_Brick"
    },
    {
      "x": -14,
      "y": 5,
      "z": -16,
      "name": "Rock_Stone_Brick"
    },
    {
      "x": -14,
      "y": 6,
      "z": -16,
      "name": "Rock_Stone_Brick"
    },
    {
      "x": -14,
      "y": 7,
      "z": -16,
      "name": "Rock_Stone_Brick"
    },
    {
      "x": -14,
      "y": 8,
      "z": -16,
      "name": "Rock_Stone_Brick"
    },
    {
      "x": -14,
      "y": 9,
      "z": -16,
      "name": "Rock_Stone_Brick"
    },
    {
      "x": -14,
      "y": 10,
      "z": -16,
      "name": "Rock_Stone_Brick"
    },
    {
      "x": -14,
      "y": 11,
      "z": -16,
      "name": "Rock_Stone_Brick"
    },
    {
      "x": -14,
      "y": 0,
      "z": -15,
      "name": "Rock_Stone_Brick"
    },
    {
      "x": -14,
      "y": 11,
      "z": -15,
      "name": "Rock_Stone_Brick"
    },
    {
      "x": -14,
      "y": 0,
      "z": -14,
      "name": "Rock_Stone_Brick"
    },
    {
      "x": -14,
      "y": 11,
      "z": -14,
      "name": "Rock_Stone_Brick"
    },
    {
      "x": -14,
      "y": 0,
      "z": -13,
      "name": "Rock_Stone_Brick"
    },
    {
      "x": -14,
      "y": 11,
      "z": -13,
      "name": "Rock_Stone_Brick"
    },
    {
      "x": -14,
      "y": 0,
      "z": -12,
      "name": "Rock_Stone_Brick"
    },
    {
      "x": -14,
      "y": 11,
      "z": -12,
      "name": "Rock_Stone_Brick"
    },
    {
      "x": -14,
      "y": 0,
      "z": -11,
      "name": "Rock_Stone_Brick"
    },
    {
      "x": -14,
      "y": 11,
      "z": -11,
      "name": "Rock_Stone_Brick"
    },
    {
      "x": -14,
      "y": 0,
      "z": -10,
      "name": "Rock_Stone_Brick"
    },
    {
      "x": -14,
      "y": 11,
      "z": -10,
      "name": "Rock_Stone_Brick"
    },
    {
      "x": -14,
      "y": 0,
      "z": -9,
      "name": "Rock_Stone_Brick"
    },
    {
      "x": -14,
      "y": 11,
      "z": -9,
      "name": "Rock_Stone_Brick"
    },
    {
      "x": -14,
      "y": 0,
      "z": -8,
      "name": "Rock_Stone_Brick"
    },
    {
      "x": -14,
      "y": 11,
      "z": -8,
      "name": "Rock_Stone_Brick"
    },
    {
      "x": -14,
      "y": 0,
      "z": -7,
      "name": "Rock_Stone_Brick"
    },
    {
      "x": -14,
      "y": 11,
      "z": -7,
      "name": "Rock_Stone_Brick"
    },
    {
      "x": -14,
      "y": 0,
      "z": -6,
      "name": "Rock_Stone_Brick"
    },
    {
      "x": -14,
      "y": 11,
      "z": -6,
      "name": "Rock_Stone_Brick"
    },
    {
      "x": -14,
      "y": 0,
      "z": -5,
      "name": "Rock_Stone_Brick"
    },
    {
      "x": -14,
      "y": 11,
      "z": -5,
      "name": "Rock_Stone_Brick"
    },
    {
      "x": -14,
      "y": 0,
      "z": -4,
      "name": "Rock_Stone_Brick"
    },
    {
      "x": -14,
      "y": 11,
      "z": -4,
      "name": "Rock_Stone_Brick"
    },
    {
      "x": -14,
      "y": 0,
      "z": -3,
      "name": "Rock_Stone_Brick"
    },
    {
      "x": -14,
      "y": 11,
      "z": -3,
      "name": "Rock_Stone_Brick"
    },
    {
      "x": -14,
      "y": 0,
      "z": -2,
      "name": "Rock_Stone_Brick"
    },
    {
      "x": -14,
      "y": 11,
      "z": -2,
      "name": "Rock_Stone_Brick"
    },
    {
      "x": -14,
      "y": 0,
      "z": -1,
      "name": "Rock_Stone_Brick"
    },
    {
      "x": -14,
      "y": 11,
      "z": -1,
      "name": "Rock_Stone_Brick"
    },
    {
      "x": -14,
      "y": 0,
      "z": 0,
      "name": "Rock_Stone_Brick"
    },
    {
      "x": -14,
      "y": 11,
      "z": 0,
      "name": "Rock_Stone_Brick"
    },
    {
      "x": -14,
      "y": 0,
      "z": 1,
      "name": "Rock_Stone_Brick"
    },
    {
      "x": -14,
      "y": 11,
      "z": 1,
      "name": "Rock_Stone_Brick"
    },
    {
      "x": -14,
      "y": 0,
      "z": 2,
      "name": "Rock_Stone_Brick"
    },
    {
      "x": -14,
      "y": 11,
      "z": 2,
      "name": "Rock_Stone_Brick"
    },
    {
      "x": -14,
      "y": 0,
      "z": 3,
      "name": "Rock_Stone_Brick"
    },
    {
      "x": -14,
      "y": 11,
      "z": 3,
      "name": "Rock_Stone_Brick"
    },
    {
      "x": -14,
      "y": 0,
      "z": 4,
      "name": "Rock_Stone_Brick"
    },
    {
      "x": -14,
      "y": 11,
      "z": 4,
      "name": "Rock_Stone_Brick"
    },
    {
      "x": -14,
      "y": 0,
      "z": 5,
      "name": "Rock_Stone_Brick"
    },
    {
      "x": -14,
      "y": 11,
      "z": 5,
      "name": "Rock_Stone_Brick"
    },
    {
      "x": -14,
      "y": 0,
      "z": 6,
      "name": "Rock_Stone_Brick"
    },
    {
      "x": -14,
      "y": 11,
      "z": 6,
      "name": "Rock_Stone_Brick"
    },
    {
      "x": -14,
      "y": 0,
      "z": 7,
      "name": "Rock_Stone_Brick"
    },
    {
      "x": -14,
      "y": 11,
      "z": 7,
      "name": "Rock_Stone_Brick"
    },
    {
      "x": -14,
      "y": 0,
      "z": 8,
      "name": "Rock_Stone_Brick"
    },
    {
      "x": -14,
      "y": 11,
      "z": 8,
      "name": "Rock_Stone_Brick"
    },
    {
      "x": -14,
      "y": 0,
      "z": 9,
      "name": "Rock_Stone_Brick"
    },
    {
      "x": -14,
      "y": 11,
      "z": 9,
      "name": "Rock_Stone_Brick"
    },
    {
      "x": -14,
      "y": 0,
      "z": 10,
      "name": "Rock_Stone_Brick"
    },
    {
      "x": -14,
      "y": 11,
      "z": 10,
      "name": "Rock_Stone_Brick"
    },
    {
      "x": -14,
      "y": 0,
      "z": 11,
      "name": "Rock_Stone_Brick"
    },
    {
      "x": -14,
      "y": 11,
      "z": 11,
      "name": "Rock_Stone_Brick"
    },
    {
      "x": -14,
      "y": 0,
      "z": 12,
      "name": "Rock_Stone_Brick"
    },
    {
      "x": -14,
      "y": 11,
      "z": 12,
      "name": "Rock_Stone_Brick"
    },
    {
      "x": -14,
      "y": 0,
      "z": 13,
      "name": "Rock_Stone_Brick"
    },
    {
      "x": -14,
      "y": 11,
      "z": 13,
      "name": "Rock_Stone_Brick"
    },
    {
      "x": -14,
      "y": 0,
      "z": 14,
      "name": "Rock_Stone_Brick"
    },
    {
      "x": -14,
      "y": 11,
      "z": 14,
      "name": "Rock_Stone_Brick"
    },
    {
      "x": -14,
      "y": 0,
      "z": 15,
      "name": "Rock_Stone_Brick"
    },
    {
      "x": -14,
      "y": 11,
      "z": 15,
      "name": "Rock_Stone_Brick"
    },
    {
      "x": -14,
      "y": 0,
      "z": 16,
      "name": "Rock_Stone_Brick"
    },
    {
      "x": -14,
      "y": 1,
      "z": 16,
      "name": "Rock_Stone_Brick"
    },
    {
      "x": -14,
      "y": 2,
      "z": 16,
      "name": "Rock_Stone_Brick"
    },
    {
      "x": -14,
      "y": 3,
      "z": 16,
      "name": "Rock_Stone_Brick"
    },
    {
      "x": -14,
      "y": 4,
      "z": 16,
      "name": "Rock_Stone_Brick"
    },
    {
      "x": -14,
      "y": 5,
      "z": 16,
      "name": "Rock_Stone_Brick"
    },
    {
      "x": -14,
      "y": 6,
      "z": 16,
      "name": "Rock_Stone_Brick"
    },
    {
      "x": -14,
      "y": 7,
      "z": 16,
      "name": "Rock_Stone_Brick"
    },
    {
      "x": -14,
      "y": 8,
      "z": 16,
      "name": "Rock_Stone_Brick"
    },
    {
      "x": -14,
      "y": 9,
      "z": 16,
      "name": "Rock_Stone_Brick"
    },
    {
      "x": -14,
      "y": 10,
      "z": 16,
      "name": "Rock_Stone_Brick"
    },
    {
      "x": -14,
      "y": 11,
      "z": 16,
      "name": "Rock_Stone_Brick"
    },
    {
      "x": -13,
      "y": 0,
      "z": -16,
      "name": "Rock_Stone_Brick"
    },
    {
      "x": -13,
      "y": 1,
      "z": -16,
      "name": "Rock_Stone_Brick"
    },
    {
      "x": -13,
      "y": 2,
      "z": -16,
      "name": "Rock_Stone_Brick"
    },
    {
      "x": -13,
      "y": 3,
      "z": -16,
      "name": "Rock_Stone_Brick"
    },
    {
      "x": -13,
      "y": 4,
      "z": -16,
      "name": "Rock_Stone_Brick"
    },
    {
      "x": -13,
      "y": 5,
      "z": -16,
      "name": "Rock_Stone_Brick"
    },
    {
      "x": -13,
      "y": 6,
      "z": -16,
      "name": "Rock_Stone_Brick"
    },
    {
      "x": -13,
      "y": 7,
      "z": -16,
      "name": "Rock_Stone_Brick"
    },
    {
      "x": -13,
      "y": 8,
      "z": -16,
      "name": "Rock_Stone_Brick"
    },
    {
      "x": -13,
      "y": 9,
      "z": -16,
      "name": "Rock_Stone_Brick"
    },
    {
      "x": -13,
      "y": 10,
      "z": -16,
      "name": "Rock_Stone_Brick"
    },
    {
      "x": -13,
      "y": 11,
      "z": -16,
      "name": "Rock_Stone_Brick"
    },
    {
      "x": -13,
      "y": 0,
      "z": -15,
      "name": "Rock_Stone_Brick"
    },
    {
      "x": -13,
      "y": 11,
      "z": -15,
      "name": "Rock_Stone_Brick"
    },
    {
      "x": -13,
      "y": 0,
      "z": -14,
      "name": "Rock_Stone_Brick"
    },
    {
      "x": -13,
      "y": 11,
      "z": -14,
      "name": "Rock_Stone_Brick"
    },
    {
      "x": -13,
      "y": 0,
      "z": -13,
      "name": "Rock_Stone_Brick"
    },
    {
      "x": -13,
      "y": 11,
      "z": -13,
      "name": "Rock_Stone_Brick"
    },
    {
      "x": -13,
      "y": 0,
      "z": -12,
      "name": "Rock_Stone_Brick"
    },
    {
      "x": -13,
      "y": 11,
      "z": -12,
      "name": "Rock_Stone_Brick"
    },
    {
      "x": -13,
      "y": 0,
      "z": -11,
      "name": "Rock_Stone_Brick"
    },
    {
      "x": -13,
      "y": 11,
      "z": -11,
      "name": "Rock_Stone_Brick"
    },
    {
      "x": -13,
      "y": 0,
      "z": -10,
      "name": "Rock_Stone_Brick"
    },
    {
      "x": -13,
      "y": 11,
      "z": -10,
      "name": "Rock_Stone_Brick"
    },
    {
      "x": -13,
      "y": 0,
      "z": -9,
      "name": "Rock_Stone_Brick"
    },
    {
      "x": -13,
      "y": 11,
      "z": -9,
      "name": "Rock_Stone_Brick"
    },
    {
      "x": -13,
      "y": 0,
      "z": -8,
      "name": "Rock_Stone_Brick"
    },
    {
      "x": -13,
      "y": 11,
      "z": -8,
      "name": "Rock_Stone_Brick"
    },
    {
      "x": -13,
      "y": 0,
      "z": -7,
      "name": "Rock_Stone_Brick"
    },
    {
      "x": -13,
      "y": 11,
      "z": -7,
      "name": "Rock_Stone_Brick"
    },
    {
      "x": -13,
      "y": 0,
      "z": -6,
      "name": "Rock_Stone_Brick"
    },
    {
      "x": -13,
      "y": 11,
      "z": -6,
      "name": "Rock_Stone_Brick"
    },
    {
      "x": -13,
      "y": 0,
      "z": -5,
      "name": "Rock_Stone_Brick"
    },
    {
      "x": -13,
      "y": 11,
      "z": -5,
      "name": "Rock_Stone_Brick"
    },
    {
      "x": -13,
      "y": 0,
      "z": -4,
      "name": "Rock_Stone_Brick"
    },
    {
      "x": -13,
      "y": 11,
      "z": -4,
      "name": "Rock_Stone_Brick"
    },
    {
      "x": -13,
      "y": 0,
      "z": -3,
      "name": "Rock_Stone_Brick"
    },
    {
      "x": -13,
      "y": 11,
      "z": -3,
      "name": "Rock_Stone_Brick"
    },
    {
      "x": -13,
      "y": 0,
      "z": -2,
      "name": "Rock_Stone_Brick"
    },
    {
      "x": -13,
      "y": 11,
      "z": -2,
      "name": "Rock_Stone_Brick"
    },
    {
      "x": -13,
      "y": 0,
      "z": -1,
      "name": "Rock_Stone_Brick"
    },
    {
      "x": -13,
      "y": 11,
      "z": -1,
      "name": "Rock_Stone_Brick"
    },
    {
      "x": -13,
      "y": 0,
      "z": 0,
      "name": "Rock_Stone_Brick"
    },
    {
      "x": -13,
      "y": 11,
      "z": 0,
      "name": "Rock_Stone_Brick"
    },
    {
      "x": -13,
      "y": 0,
      "z": 1,
      "name": "Rock_Stone_Brick"
    },
    {
      "x": -13,
      "y": 11,
      "z": 1,
      "name": "Rock_Stone_Brick"
    },
    {
      "x": -13,
      "y": 0,
      "z": 2,
      "name": "Rock_Stone_Brick"
    },
    {
      "x": -13,
      "y": 11,
      "z": 2,
      "name": "Rock_Stone_Brick"
    },
    {
      "x": -13,
      "y": 0,
      "z": 3,
      "name": "Rock_Stone_Brick"
    },
    {
      "x": -13,
      "y": 11,
      "z": 3,
      "name": "Rock_Stone_Brick"
    },
    {
      "x": -13,
      "y": 0,
      "z": 4,
      "name": "Rock_Stone_Brick"
    },
    {
      "x": -13,
      "y": 11,
      "z": 4,
      "name": "Rock_Stone_Brick"
    },
    {
      "x": -13,
      "y": 0,
      "z": 5,
      "name": "Rock_Stone_Brick"
    },
    {
      "x": -13,
      "y": 11,
      "z": 5,
      "name": "Rock_Stone_Brick"
    },
    {
      "x": -13,
      "y": 0,
      "z": 6,
      "name": "Rock_Stone_Brick"
    },
    {
      "x": -13,
      "y": 11,
      "z": 6,
      "name": "Rock_Stone_Brick"
    },
    {
      "x": -13,
      "y": 0,
      "z": 7,
      "name": "Rock_Stone_Brick"
    },
    {
      "x": -13,
      "y": 11,
      "z": 7,
      "name": "Rock_Stone_Brick"
    },
    {
      "x": -13,
      "y": 0,
      "z": 8,
      "name": "Rock_Stone_Brick"
    },
    {
      "x": -13,
      "y": 11,
      "z": 8,
      "name": "Rock_Stone_Brick"
    },
    {
      "x": -13,
      "y": 0,
      "z": 9,
      "name": "Rock_Stone_Brick"
    },
    {
      "x": -13,
      "y": 11,
      "z": 9,
      "name": "Rock_Stone_Brick"
    },
    {
      "x": -13,
      "y": 0,
      "z": 10,
      "name": "Rock_Stone_Brick"
    },
    {
      "x": -13,
      "y": 11,
      "z": 10,
      "name": "Rock_Stone_Brick"
    },
    {
      "x": -13,
      "y": 0,
      "z": 11,
      "name": "Rock_Stone_Brick"
    },
    {
      "x": -13,
      "y": 11,
      "z": 11,
      "name": "Rock_Stone_Brick"
    },
    {
      "x": -13,
      "y": 0,
      "z": 12,
      "name": "Rock_Stone_Brick"
    },
    {
      "x": -13,
      "y": 11,
      "z": 12,
      "name": "Rock_Stone_Brick"
    },
    {
      "x": -13,
      "y": 0,
      "z": 13,
      "name": "Rock_Stone_Brick"
    },
    {
      "x": -13,
      "y": 11,
      "z": 13,
      "name": "Rock_Stone_Brick"
    },
    {
      "x": -13,
      "y": 0,
      "z": 14,
      "name": "Rock_Stone_Brick"
    },
    {
      "x": -13,
      "y": 11,
      "z": 14,
      "name": "Rock_Stone_Brick"
    },
    {
      "x": -13,
      "y": 0,
      "z": 15,
      "name": "Rock_Stone_Brick"
    },
    {
      "x": -13,
      "y": 11,
      "z": 15,
      "name": "Rock_Stone_Brick"
    },
    {
      "x": -13,
      "y": 0,
      "z": 16,
      "name": "Rock_Stone_Brick"
    },
    {
      "x": -13,
      "y": 1,
      "z": 16,
      "name": "Rock_Stone_Brick"
    },
    {
      "x": -13,
      "y": 2,
      "z": 16,
      "name": "Rock_Stone_Brick"
    },
    {
      "x": -13,
      "y": 3,
      "z": 16,
      "name": "Rock_Stone_Brick"
    },
    {
      "x": -13,
      "y": 4,
      "z": 16,
      "name": "Rock_Stone_Brick"
    },
    {
      "x": -13,
      "y": 5,
      "z": 16,
      "name": "Rock_Stone_Brick"
    },
    {
      "x": -13,
      "y": 6,
      "z": 16,
      "name": "Rock_Stone_Brick"
    },
    {
      "x": -13,
      "y": 7,
      "z": 16,
      "name": "Rock_Stone_Brick"
    },
    {
      "x": -13,
      "y": 8,
      "z": 16,
      "name": "Rock_Stone_Brick"
    },
    {
      "x": -13,
      "y": 9,
      "z": 16,
      "name": "Rock_Stone_Brick"
    },
    {
      "x": -13,
      "y": 10,
      "z": 16,
      "name": "Rock_Stone_Brick"
    },
    {
      "x": -13,
      "y": 11,
      "z": 16,
      "name": "Rock_Stone_Brick"
    },
    {
      "x": -12,
      "y": 0,
      "z": -16,
      "name": "Rock_Stone_Brick"
    },
    {
      "x": -12,
      "y": 1,
      "z": -16,
      "name": "Rock_Stone_Brick"
    },
    {
      "x": -12,
      "y": 2,
      "z": -16,
      "name": "Rock_Stone_Brick"
    },
    {
      "x": -12,
      "y": 3,
      "z": -16,
      "name": "Rock_Stone_Brick"
    },
    {
      "x": -12,
      "y": 4,
      "z": -16,
      "name": "Rock_Stone_Brick"
    },
    {
      "x": -12,
      "y": 5,
      "z": -16,
      "name": "Rock_Stone_Brick"
    },
    {
      "x": -12,
      "y": 6,
      "z": -16,
      "name": "Rock_Stone_Brick"
    },
    {
      "x": -12,
      "y": 7,
      "z": -16,
      "name": "Rock_Stone_Brick"
    },
    {
      "x": -12,
      "y": 8,
      "z": -16,
      "name": "Rock_Stone_Brick"
    },
    {
      "x": -12,
      "y": 9,
      "z": -16,
      "name": "Rock_Stone_Brick"
    },
    {
      "x": -12,
      "y": 10,
      "z": -16,
      "name": "Rock_Stone_Brick"
    },
    {
      "x": -12,
      "y": 11,
      "z": -16,
      "name": "Rock_Stone_Brick"
    },
    {
      "x": -12,
      "y": 0,
      "z": -15,
      "name": "Rock_Stone_Brick"
    },
    {
      "x": -12,
      "y": 11,
      "z": -15,
      "name": "Rock_Stone_Brick"
    },
    {
      "x": -12,
      "y": 0,
      "z": -14,
      "name": "Rock_Stone_Brick"
    },
    {
      "x": -12,
      "y": 11,
      "z": -14,
      "name": "Rock_Stone_Brick"
    },
    {
      "x": -12,
      "y": 0,
      "z": -13,
      "name": "Rock_Stone_Brick"
    },
    {
      "x": -12,
      "y": 11,
      "z": -13,
      "name": "Rock_Stone_Brick"
    },
    {
      "x": -12,
      "y": 0,
      "z": -12,
      "name": "Rock_Stone_Brick"
    },
    {
      "x": -12,
      "y": 11,
      "z": -12,
      "name": "Rock_Stone_Brick"
    },
    {
      "x": -12,
      "y": 0,
      "z": -11,
      "name": "Rock_Stone_Brick"
    },
    {
      "x": -12,
      "y": 11,
      "z": -11,
      "name": "Rock_Stone_Brick"
    },
    {
      "x": -12,
      "y": 0,
      "z": -10,
      "name": "Rock_Stone_Brick"
    },
    {
      "x": -12,
      "y": 11,
      "z": -10,
      "name": "Rock_Stone_Brick"
    },
    {
      "x": -12,
      "y": 0,
      "z": -9,
      "name": "Rock_Stone_Brick"
    },
    {
      "x": -12,
      "y": 11,
      "z": -9,
      "name": "Rock_Stone_Brick"
    },
    {
      "x": -12,
      "y": 0,
      "z": -8,
      "name": "Rock_Stone_Brick"
    },
    {
      "x": -12,
      "y": 11,
      "z": -8,
      "name": "Rock_Stone_Brick"
    },
    {
      "x": -12,
      "y": 0,
      "z": -7,
      "name": "Rock_Stone_Brick"
    },
    {
      "x": -12,
      "y": 11,
      "z": -7,
      "name": "Rock_Stone_Brick"
    },
    {
      "x": -12,
      "y": 0,
      "z": -6,
      "name": "Rock_Stone_Brick"
    },
    {
      "x": -12,
      "y": 11,
      "z": -6,
      "name": "Rock_Stone_Brick"
    },
    {
      "x": -12,
      "y": 0,
      "z": -5,
      "name": "Rock_Stone_Brick"
    },
    {
      "x": -12,
      "y": 11,
      "z": -5,
      "name": "Rock_Stone_Brick"
    },
    {
      "x": -12,
      "y": 0,
      "z": -4,
      "name": "Rock_Stone_Brick"
    },
    {
      "x": -12,
      "y": 11,
      "z": -4,
      "name": "Rock_Stone_Brick"
    },
    {
      "x": -12,
      "y": 0,
      "z": -3,
      "name": "Rock_Stone_Brick"
    },
    {
      "x": -12,
      "y": 11,
      "z": -3,
      "name": "Rock_Stone_Brick"
    },
    {
      "x": -12,
      "y": 0,
      "z": -2,
      "name": "Rock_Stone_Brick"
    },
    {
      "x": -12,
      "y": 11,
      "z": -2,
      "name": "Rock_Stone_Brick"
    },
    {
      "x": -12,
      "y": 0,
      "z": -1,
      "name": "Rock_Stone_Brick"
    },
    {
      "x": -12,
      "y": 11,
      "z": -1,
      "name": "Rock_Stone_Brick"
    },
    {
      "x": -12,
      "y": 0,
      "z": 0,
      "name": "Rock_Stone_Brick"
    },
    {
      "x": -12,
      "y": 11,
      "z": 0,
      "name": "Rock_Stone_Brick"
    },
    {
      "x": -12,
      "y": 0,
      "z": 1,
      "name": "Rock_Stone_Brick"
    },
    {
      "x": -12,
      "y": 11,
      "z": 1,
      "name": "Rock_Stone_Brick"
    },
    {
      "x": -12,
      "y": 0,
      "z": 2,
      "name": "Rock_Stone_Brick"
    },
    {
      "x": -12,
      "y": 11,
      "z": 2,
      "name": "Rock_Stone_Brick"
    },
    {
      "x": -12,
      "y": 0,
      "z": 3,
      "name": "Rock_Stone_Brick"
    },
    {
      "x": -12,
      "y": 11,
      "z": 3,
      "name": "Rock_Stone_Brick"
    },
    {
      "x": -12,
      "y": 0,
      "z": 4,
      "name": "Rock_Stone_Brick"
    },
    {
      "x": -12,
      "y": 11,
      "z": 4,
      "name": "Rock_Stone_Brick"
    },
    {
      "x": -12,
      "y": 0,
      "z": 5,
      "name": "Rock_Stone_Brick"
    },
    {
      "x": -12,
      "y": 11,
      "z": 5,
      "name": "Rock_Stone_Brick"
    },
    {
      "x": -12,
      "y": 0,
      "z": 6,
      "name": "Rock_Stone_Brick"
    },
    {
      "x": -12,
      "y": 11,
      "z": 6,
      "name": "Rock_Stone_Brick"
    },
    {
      "x": -12,
      "y": 0,
      "z": 7,
      "name": "Rock_Stone_Brick"
    },
    {
      "x": -12,
      "y": 11,
      "z": 7,
      "name": "Rock_Stone_Brick"
    },
    {
      "x": -12,
      "y": 0,
      "z": 8,
      "name": "Rock_Stone_Brick"
    },
    {
      "x": -12,
      "y": 11,
      "z": 8,
      "name": "Rock_Stone_Brick"
    },
    {
      "x": -12,
      "y": 0,
      "z": 9,
      "name": "Rock_Stone_Brick"
    },
    {
      "x": -12,
      "y": 11,
      "z": 9,
      "name": "Rock_Stone_Brick"
    },
    {
      "x": -12,
      "y": 0,
      "z": 10,
      "name": "Rock_Stone_Brick"
    },
    {
      "x": -12,
      "y": 11,
      "z": 10,
      "name": "Rock_Stone_Brick"
    },
    {
      "x": -12,
      "y": 0,
      "z": 11,
      "name": "Rock_Stone_Brick"
    },
    {
      "x": -12,
      "y": 11,
      "z": 11,
      "name": "Rock_Stone_Brick"
    },
    {
      "x": -12,
      "y": 0,
      "z": 12,
      "name": "Rock_Stone_Brick"
    },
    {
      "x": -12,
      "y": 11,
      "z": 12,
      "name": "Rock_Stone_Brick"
    },
    {
      "x": -12,
      "y": 0,
      "z": 13,
      "name": "Rock_Stone_Brick"
    },
    {
      "x": -12,
      "y": 11,
      "z": 13,
      "name": "Rock_Stone_Brick"
    },
    {
      "x": -12,
      "y": 0,
      "z": 14,
      "name": "Rock_Stone_Brick"
    },
    {
      "x": -12,
      "y": 11,
      "z": 14,
      "name": "Rock_Stone_Brick"
    },
    {
      "x": -12,
      "y": 0,
      "z": 15,
      "name": "Rock_Stone_Brick"
    },
    {
      "x": -12,
      "y": 11,
      "z": 15,
      "name": "Rock_Stone_Brick"
    },
    {
      "x": -12,
      "y": 0,
      "z": 16,
      "name": "Rock_Stone_Brick"
    },
    {
      "x": -12,
      "y": 1,
      "z": 16,
      "name": "Rock_Stone_Brick"
    },
    {
      "x": -12,
      "y": 2,
      "z": 16,
      "name": "Rock_Stone_Brick"
    },
    {
      "x": -12,
      "y": 3,
      "z": 16,
      "name": "Rock_Stone_Brick"
    },
    {
      "x": -12,
      "y": 4,
      "z": 16,
      "name": "Rock_Stone_Brick"
    },
    {
      "x": -12,
      "y": 5,
      "z": 16,
      "name": "Rock_Stone_Brick"
    },
    {
      "x": -12,
      "y": 6,
      "z": 16,
      "name": "Rock_Stone_Brick"
    },
    {
      "x": -12,
      "y": 7,
      "z": 16,
      "name": "Rock_Stone_Brick"
    },
    {
      "x": -12,
      "y": 8,
      "z": 16,
      "name": "Rock_Stone_Brick"
    },
    {
      "x": -12,
      "y": 9,
      "z": 16,
      "name": "Rock_Stone_Brick"
    },
    {
      "x": -12,
      "y": 10,
      "z": 16,
      "name": "Rock_Stone_Brick"
    },
    {
      "x": -12,
      "y": 11,
      "z": 16,
      "name": "Rock_Stone_Brick"
    },
    {
      "x": -11,
      "y": 0,
      "z": -16,
      "name": "Rock_Stone_Brick"
    },
    {
      "x": -11,
      "y": 1,
      "z": -16,
      "name": "Rock_Stone_Brick"
    },
    {
      "x": -11,
      "y": 2,
      "z": -16,
      "name": "Rock_Stone_Brick"
    },
    {
      "x": -11,
      "y": 3,
      "z": -16,
      "name": "Rock_Stone_Brick"
    },
    {
      "x": -11,
      "y": 4,
      "z": -16,
      "name": "Rock_Stone_Brick"
    },
    {
      "x": -11,
      "y": 5,
      "z": -16,
      "name": "Rock_Stone_Brick"
    },
    {
      "x": -11,
      "y": 6,
      "z": -16,
      "name": "Rock_Stone_Brick"
    },
    {
      "x": -11,
      "y": 7,
      "z": -16,
      "name": "Rock_Stone_Brick"
    },
    {
      "x": -11,
      "y": 8,
      "z": -16,
      "name": "Rock_Stone_Brick"
    },
    {
      "x": -11,
      "y": 9,
      "z": -16,
      "name": "Rock_Stone_Brick"
    },
    {
      "x": -11,
      "y": 10,
      "z": -16,
      "name": "Rock_Stone_Brick"
    },
    {
      "x": -11,
      "y": 11,
      "z": -16,
      "name": "Rock_Stone_Brick"
    },
    {
      "x": -11,
      "y": 0,
      "z": -15,
      "name": "Rock_Stone_Brick"
    },
    {
      "x": -11,
      "y": 11,
      "z": -15,
      "name": "Rock_Stone_Brick"
    },
    {
      "x": -11,
      "y": 0,
      "z": -14,
      "name": "Rock_Stone_Brick"
    },
    {
      "x": -11,
      "y": 11,
      "z": -14,
      "name": "Rock_Stone_Brick"
    },
    {
      "x": -11,
      "y": 0,
      "z": -13,
      "name": "Rock_Stone_Brick"
    },
    {
      "x": -11,
      "y": 11,
      "z": -13,
      "name": "Rock_Stone_Brick"
    },
    {
      "x": -11,
      "y": 0,
      "z": -12,
      "name": "Rock_Stone_Brick"
    },
    {
      "x": -11,
      "y": 11,
      "z": -12,
      "name": "Rock_Stone_Brick"
    },
    {
      "x": -11,
      "y": 0,
      "z": -11,
      "name": "Rock_Stone_Brick"
    },
    {
      "x": -11,
      "y": 11,
      "z": -11,
      "name": "Rock_Stone_Brick"
    },
    {
      "x": -11,
      "y": 0,
      "z": -10,
      "name": "Rock_Stone_Brick"
    },
    {
      "x": -11,
      "y": 11,
      "z": -10,
      "name": "Rock_Stone_Brick"
    },
    {
      "x": -11,
      "y": 0,
      "z": -9,
      "name": "Rock_Stone_Brick"
    },
    {
      "x": -11,
      "y": 11,
      "z": -9,
      "name": "Rock_Stone_Brick"
    },
    {
      "x": -11,
      "y": 0,
      "z": -8,
      "name": "Rock_Stone_Brick"
    },
    {
      "x": -11,
      "y": 11,
      "z": -8,
      "name": "Rock_Stone_Brick"
    },
    {
      "x": -11,
      "y": 0,
      "z": -7,
      "name": "Rock_Stone_Brick"
    },
    {
      "x": -11,
      "y": 11,
      "z": -7,
      "name": "Rock_Stone_Brick"
    },
    {
      "x": -11,
      "y": 0,
      "z": -6,
      "name": "Rock_Stone_Brick"
    },
    {
      "x": -11,
      "y": 11,
      "z": -6,
      "name": "Rock_Stone_Brick"
    },
    {
      "x": -11,
      "y": 0,
      "z": -5,
      "name": "Rock_Stone_Brick"
    },
    {
      "x": -11,
      "y": 11,
      "z": -5,
      "name": "Rock_Stone_Brick"
    },
    {
      "x": -11,
      "y": 0,
      "z": -4,
      "name": "Rock_Stone_Brick"
    },
    {
      "x": -11,
      "y": 11,
      "z": -4,
      "name": "Rock_Stone_Brick"
    },
    {
      "x": -11,
      "y": 0,
      "z": -3,
      "name": "Rock_Stone_Brick"
    },
    {
      "x": -11,
      "y": 11,
      "z": -3,
      "name": "Rock_Stone_Brick"
    },
    {
      "x": -11,
      "y": 0,
      "z": -2,
      "name": "Rock_Stone_Brick"
    },
    {
      "x": -11,
      "y": 11,
      "z": -2,
      "name": "Rock_Stone_Brick"
    },
    {
      "x": -11,
      "y": 0,
      "z": -1,
      "name": "Rock_Stone_Brick"
    },
    {
      "x": -11,
      "y": 11,
      "z": -1,
      "name": "Rock_Stone_Brick"
    },
    {
      "x": -11,
      "y": 0,
      "z": 0,
      "name": "Rock_Stone_Brick"
    },
    {
      "x": -11,
      "y": 11,
      "z": 0,
      "name": "Rock_Stone_Brick"
    },
    {
      "x": -11,
      "y": 0,
      "z": 1,
      "name": "Rock_Stone_Brick"
    },
    {
      "x": -11,
      "y": 11,
      "z": 1,
      "name": "Rock_Stone_Brick"
    },
    {
      "x": -11,
      "y": 0,
      "z": 2,
      "name": "Rock_Stone_Brick"
    },
    {
      "x": -11,
      "y": 11,
      "z": 2,
      "name": "Rock_Stone_Brick"
    },
    {
      "x": -11,
      "y": 0,
      "z": 3,
      "name": "Rock_Stone_Brick"
    },
    {
      "x": -11,
      "y": 11,
      "z": 3,
      "name": "Rock_Stone_Brick"
    },
    {
      "x": -11,
      "y": 0,
      "z": 4,
      "name": "Rock_Stone_Brick"
    },
    {
      "x": -11,
      "y": 11,
      "z": 4,
      "name": "Rock_Stone_Brick"
    },
    {
      "x": -11,
      "y": 0,
      "z": 5,
      "name": "Rock_Stone_Brick"
    },
    {
      "x": -11,
      "y": 11,
      "z": 5,
      "name": "Rock_Stone_Brick"
    },
    {
      "x": -11,
      "y": 0,
      "z": 6,
      "name": "Rock_Stone_Brick"
    },
    {
      "x": -11,
      "y": 11,
      "z": 6,
      "name": "Rock_Stone_Brick"
    },
    {
      "x": -11,
      "y": 0,
      "z": 7,
      "name": "Rock_Stone_Brick"
    },
    {
      "x": -11,
      "y": 11,
      "z": 7,
      "name": "Rock_Stone_Brick"
    },
    {
      "x": -11,
      "y": 0,
      "z": 8,
      "name": "Rock_Stone_Brick"
    },
    {
      "x": -11,
      "y": 11,
      "z": 8,
      "name": "Rock_Stone_Brick"
    },
    {
      "x": -11,
      "y": 0,
      "z": 9,
      "name": "Rock_Stone_Brick"
    },
    {
      "x": -11,
      "y": 11,
      "z": 9,
      "name": "Rock_Stone_Brick"
    },
    {
      "x": -11,
      "y": 0,
      "z": 10,
      "name": "Rock_Stone_Brick"
    },
    {
      "x": -11,
      "y": 11,
      "z": 10,
      "name": "Rock_Stone_Brick"
    },
    {
      "x": -11,
      "y": 0,
      "z": 11,
      "name": "Rock_Stone_Brick"
    },
    {
      "x": -11,
      "y": 11,
      "z": 11,
      "name": "Rock_Stone_Brick"
    },
    {
      "x": -11,
      "y": 0,
      "z": 12,
      "name": "Rock_Stone_Brick"
    },
    {
      "x": -11,
      "y": 11,
      "z": 12,
      "name": "Rock_Stone_Brick"
    },
    {
      "x": -11,
      "y": 0,
      "z": 13,
      "name": "Rock_Stone_Brick"
    },
    {
      "x": -11,
      "y": 11,
      "z": 13,
      "name": "Rock_Stone_Brick"
    },
    {
      "x": -11,
      "y": 0,
      "z": 14,
      "name": "Rock_Stone_Brick"
    },
    {
      "x": -11,
      "y": 11,
      "z": 14,
      "name": "Rock_Stone_Brick"
    },
    {
      "x": -11,
      "y": 0,
      "z": 15,
      "name": "Rock_Stone_Brick"
    },
    {
      "x": -11,
      "y": 11,
      "z": 15,
      "name": "Rock_Stone_Brick"
    },
    {
      "x": -11,
      "y": 0,
      "z": 16,
      "name": "Rock_Stone_Brick"
    },
    {
      "x": -11,
      "y": 1,
      "z": 16,
      "name": "Rock_Stone_Brick"
    },
    {
      "x": -11,
      "y": 2,
      "z": 16,
      "name": "Rock_Stone_Brick"
    },
    {
      "x": -11,
      "y": 3,
      "z": 16,
      "name": "Rock_Stone_Brick"
    },
    {
      "x": -11,
      "y": 4,
      "z": 16,
      "name": "Rock_Stone_Brick"
    },
    {
      "x": -11,
      "y": 5,
      "z": 16,
      "name": "Rock_Stone_Brick"
    },
    {
      "x": -11,
      "y": 6,
      "z": 16,
      "name": "Rock_Stone_Brick"
    },
    {
      "x": -11,
      "y": 7,
      "z": 16,
      "name": "Rock_Stone_Brick"
    },
    {
      "x": -11,
      "y": 8,
      "z": 16,
      "name": "Rock_Stone_Brick"
    },
    {
      "x": -11,
      "y": 9,
      "z": 16,
      "name": "Rock_Stone_Brick"
    },
    {
      "x": -11,
      "y": 10,
      "z": 16,
      "name": "Rock_Stone_Brick"
    },
    {
      "x": -11,
      "y": 11,
      "z": 16,
      "name": "Rock_Stone_Brick"
    },
    {
      "x": -10,
      "y": 0,
      "z": -16,
      "name": "Rock_Stone_Brick"
    },
    {
      "x": -10,
      "y": 1,
      "z": -16,
      "name": "Rock_Stone_Brick"
    },
    {
      "x": -10,
      "y": 2,
      "z": -16,
      "name": "Rock_Stone_Brick"
    },
    {
      "x": -10,
      "y": 3,
      "z": -16,
      "name": "Rock_Stone_Brick"
    },
    {
      "x": -10,
      "y": 4,
      "z": -16,
      "name": "Rock_Stone_Brick"
    },
    {
      "x": -10,
      "y": 5,
      "z": -16,
      "name": "Rock_Stone_Brick"
    },
    {
      "x": -10,
      "y": 6,
      "z": -16,
      "name": "Rock_Stone_Brick"
    },
    {
      "x": -10,
      "y": 7,
      "z": -16,
      "name": "Rock_Stone_Brick"
    },
    {
      "x": -10,
      "y": 8,
      "z": -16,
      "name": "Rock_Stone_Brick"
    },
    {
      "x": -10,
      "y": 9,
      "z": -16,
      "name": "Rock_Stone_Brick"
    },
    {
      "x": -10,
      "y": 10,
      "z": -16,
      "name": "Rock_Stone_Brick"
    },
    {
      "x": -10,
      "y": 11,
      "z": -16,
      "name": "Rock_Stone_Brick"
    },
    {
      "x": -10,
      "y": 0,
      "z": -15,
      "name": "Rock_Stone_Brick"
    },
    {
      "x": -10,
      "y": 11,
      "z": -15,
      "name": "Rock_Stone_Brick"
    },
    {
      "x": -10,
      "y": 0,
      "z": -14,
      "name": "Rock_Stone_Brick"
    },
    {
      "x": -10,
      "y": 11,
      "z": -14,
      "name": "Rock_Stone_Brick"
    },
    {
      "x": -10,
      "y": 0,
      "z": -13,
      "name": "Rock_Stone_Brick"
    },
    {
      "x": -10,
      "y": 11,
      "z": -13,
      "name": "Rock_Stone_Brick"
    },
    {
      "x": -10,
      "y": 0,
      "z": -12,
      "name": "Rock_Stone_Brick"
    },
    {
      "x": -10,
      "y": 11,
      "z": -12,
      "name": "Rock_Stone_Brick"
    },
    {
      "x": -10,
      "y": 0,
      "z": -11,
      "name": "Rock_Stone_Brick"
    },
    {
      "x": -10,
      "y": 11,
      "z": -11,
      "name": "Rock_Stone_Brick"
    },
    {
      "x": -10,
      "y": 0,
      "z": -10,
      "name": "Rock_Stone_Brick"
    },
    {
      "x": -10,
      "y": 11,
      "z": -10,
      "name": "Rock_Stone_Brick"
    },
    {
      "x": -10,
      "y": 0,
      "z": -9,
      "name": "Rock_Stone_Brick"
    },
    {
      "x": -10,
      "y": 11,
      "z": -9,
      "name": "Rock_Stone_Brick"
    },
    {
      "x": -10,
      "y": 0,
      "z": -8,
      "name": "Rock_Stone_Brick"
    },
    {
      "x": -10,
      "y": 11,
      "z": -8,
      "name": "Rock_Stone_Brick"
    },
    {
      "x": -10,
      "y": 0,
      "z": -7,
      "name": "Rock_Stone_Brick"
    },
    {
      "x": -10,
      "y": 11,
      "z": -7,
      "name": "Rock_Stone_Brick"
    },
    {
      "x": -10,
      "y": 0,
      "z": -6,
      "name": "Rock_Stone_Brick"
    },
    {
      "x": -10,
      "y": 11,
      "z": -6,
      "name": "Rock_Stone_Brick"
    },
    {
      "x": -10,
      "y": 0,
      "z": -5,
      "name": "Rock_Stone_Brick"
    },
    {
      "x": -10,
      "y": 11,
      "z": -5,
      "name": "Rock_Stone_Brick"
    },
    {
      "x": -10,
      "y": 0,
      "z": -4,
      "name": "Rock_Stone_Brick"
    },
    {
      "x": -10,
      "y": 11,
      "z": -4,
      "name": "Rock_Stone_Brick"
    },
    {
      "x": -10,
      "y": 0,
      "z": -3,
      "name": "Rock_Stone_Brick"
    },
    {
      "x": -10,
      "y": 11,
      "z": -3,
      "name": "Rock_Stone_Brick"
    },
    {
      "x": -10,
      "y": 0,
      "z": -2,
      "name": "Rock_Stone_Brick"
    },
    {
      "x": -10,
      "y": 11,
      "z": -2,
      "name": "Rock_Stone_Brick"
    },
    {
      "x": -10,
      "y": 0,
      "z": -1,
      "name": "Rock_Stone_Brick"
    },
    {
      "x": -10,
      "y": 11,
      "z": -1,
      "name": "Rock_Stone_Brick"
    },
    {
      "x": -10,
      "y": 0,
      "z": 0,
      "name": "Rock_Stone_Brick"
    },
    {
      "x": -10,
      "y": 11,
      "z": 0,
      "name": "Rock_Stone_Brick"
    },
    {
      "x": -10,
      "y": 0,
      "z": 1,
      "name": "Rock_Stone_Brick"
    },
    {
      "x": -10,
      "y": 11,
      "z": 1,
      "name": "Rock_Stone_Brick"
    },
    {
      "x": -10,
      "y": 0,
      "z": 2,
      "name": "Rock_Stone_Brick"
    },
    {
      "x": -10,
      "y": 11,
      "z": 2,
      "name": "Rock_Stone_Brick"
    },
    {
      "x": -10,
      "y": 0,
      "z": 3,
      "name": "Rock_Stone_Brick"
    },
    {
      "x": -10,
      "y": 11,
      "z": 3,
      "name": "Rock_Stone_Brick"
    },
    {
      "x": -10,
      "y": 0,
      "z": 4,
      "name": "Rock_Stone_Brick"
    },
    {
      "x": -10,
      "y": 11,
      "z": 4,
      "name": "Rock_Stone_Brick"
    },
    {
      "x": -10,
      "y": 0,
      "z": 5,
      "name": "Rock_Stone_Brick"
    },
    {
      "x": -10,
      "y": 11,
      "z": 5,
      "name": "Rock_Stone_Brick"
    },
    {
      "x": -10,
      "y": 0,
      "z": 6,
      "name": "Rock_Stone_Brick"
    },
    {
      "x": -10,
      "y": 11,
      "z": 6,
      "name": "Rock_Stone_Brick"
    },
    {
      "x": -10,
      "y": 0,
      "z": 7,
      "name": "Rock_Stone_Brick"
    },
    {
      "x": -10,
      "y": 11,
      "z": 7,
      "name": "Rock_Stone_Brick"
    },
    {
      "x": -10,
      "y": 0,
      "z": 8,
      "name": "Rock_Stone_Brick"
    },
    {
      "x": -10,
      "y": 11,
      "z": 8,
      "name": "Rock_Stone_Brick"
    },
    {
      "x": -10,
      "y": 0,
      "z": 9,
      "name": "Rock_Stone_Brick"
    },
    {
      "x": -10,
      "y": 11,
      "z": 9,
      "name": "Rock_Stone_Brick"
    },
    {
      "x": -10,
      "y": 0,
      "z": 10,
      "name": "Rock_Stone_Brick"
    },
    {
      "x": -10,
      "y": 11,
      "z": 10,
      "name": "Rock_Stone_Brick"
    },
    {
      "x": -10,
      "y": 0,
      "z": 11,
      "name": "Rock_Stone_Brick"
    },
    {
      "x": -10,
      "y": 11,
      "z": 11,
      "name": "Rock_Stone_Brick"
    },
    {
      "x": -10,
      "y": 0,
      "z": 12,
      "name": "Rock_Stone_Brick"
    },
    {
      "x": -10,
      "y": 11,
      "z": 12,
      "name": "Rock_Stone_Brick"
    },
    {
      "x": -10,
      "y": 0,
      "z": 13,
      "name": "Rock_Stone_Brick"
    },
    {
      "x": -10,
      "y": 11,
      "z": 13,
      "name": "Rock_Stone_Brick"
    },
    {
      "x": -10,
      "y": 0,
      "z": 14,
      "name": "Rock_Stone_Brick"
    },
    {
      "x": -10,
      "y": 11,
      "z": 14,
      "name": "Rock_Stone_Brick"
    },
    {
      "x": -10,
      "y": 0,
      "z": 15,
      "name": "Rock_Stone_Brick"
    },
    {
      "x": -10,
      "y": 11,
      "z": 15,
      "name": "Rock_Stone_Brick"
    },
    {
      "x": -10,
      "y": 0,
      "z": 16,
      "name": "Rock_Stone_Brick"
    },
    {
      "x": -10,
      "y": 1,
      "z": 16,
      "name": "Rock_Stone_Brick"
    },
    {
      "x": -10,
      "y": 2,
      "z": 16,
      "name": "Rock_Stone_Brick"
    },
    {
      "x": -10,
      "y": 3,
      "z": 16,
      "name": "Rock_Stone_Brick"
    },
    {
      "x": -10,
      "y": 4,
      "z": 16,
      "name": "Rock_Stone_Brick"
    },
    {
      "x": -10,
      "y": 5,
      "z": 16,
      "name": "Rock_Stone_Brick"
    },
    {
      "x": -10,
      "y": 6,
      "z": 16,
      "name": "Rock_Stone_Brick"
    },
    {
      "x": -10,
      "y": 7,
      "z": 16,
      "name": "Rock_Stone_Brick"
    },
    {
      "x": -10,
      "y": 8,
      "z": 16,
      "name": "Rock_Stone_Brick"
    },
    {
      "x": -10,
      "y": 9,
      "z": 16,
      "name": "Rock_Stone_Brick"
    },
    {
      "x": -10,
      "y": 10,
      "z": 16,
      "name": "Rock_Stone_Brick"
    },
    {
      "x": -10,
      "y": 11,
      "z": 16,
      "name": "Rock_Stone_Brick"
    },
    {
      "x": -9,
      "y": 0,
      "z": -16,
      "name": "Rock_Stone_Brick"
    },
    {
      "x": -9,
      "y": 1,
      "z": -16,
      "name": "Rock_Stone_Brick"
    },
    {
      "x": -9,
      "y": 2,
      "z": -16,
      "name": "Rock_Stone_Brick"
    },
    {
      "x": -9,
      "y": 3,
      "z": -16,
      "name": "Rock_Stone_Brick"
    },
    {
      "x": -9,
      "y": 4,
      "z": -16,
      "name": "Rock_Stone_Brick"
    },
    {
      "x": -9,
      "y": 5,
      "z": -16,
      "name": "Rock_Stone_Brick"
    },
    {
      "x": -9,
      "y": 6,
      "z": -16,
      "name": "Rock_Stone_Brick"
    },
    {
      "x": -9,
      "y": 7,
      "z": -16,
      "name": "Rock_Stone_Brick"
    },
    {
      "x": -9,
      "y": 8,
      "z": -16,
      "name": "Rock_Stone_Brick"
    },
    {
      "x": -9,
      "y": 9,
      "z": -16,
      "name": "Rock_Stone_Brick"
    },
    {
      "x": -9,
      "y": 10,
      "z": -16,
      "name": "Rock_Stone_Brick"
    },
    {
      "x": -9,
      "y": 11,
      "z": -16,
      "name": "Rock_Stone_Brick"
    },
    {
      "x": -9,
      "y": 0,
      "z": -15,
      "name": "Rock_Stone_Brick"
    },
    {
      "x": -9,
      "y": 11,
      "z": -15,
      "name": "Rock_Stone_Brick"
    },
    {
      "x": -9,
      "y": 0,
      "z": -14,
      "name": "Rock_Stone_Brick"
    },
    {
      "x": -9,
      "y": 11,
      "z": -14,
      "name": "Rock_Stone_Brick"
    },
    {
      "x": -9,
      "y": 0,
      "z": -13,
      "name": "Rock_Stone_Brick"
    },
    {
      "x": -9,
      "y": 11,
      "z": -13,
      "name": "Rock_Stone_Brick"
    },
    {
      "x": -9,
      "y": 0,
      "z": -12,
      "name": "Rock_Stone_Brick"
    },
    {
      "x": -9,
      "y": 11,
      "z": -12,
      "name": "Rock_Stone_Brick"
    },
    {
      "x": -9,
      "y": 0,
      "z": -11,
      "name": "Rock_Stone_Brick"
    },
    {
      "x": -9,
      "y": 11,
      "z": -11,
      "name": "Rock_Stone_Brick"
    },
    {
      "x": -9,
      "y": 0,
      "z": -10,
      "name": "Rock_Stone_Brick"
    },
    {
      "x": -9,
      "y": 11,
      "z": -10,
      "name": "Rock_Stone_Brick"
    },
    {
      "x": -9,
      "y": 0,
      "z": -9,
      "name": "Rock_Stone_Brick"
    },
    {
      "x": -9,
      "y": 11,
      "z": -9,
      "name": "Rock_Stone_Brick"
    },
    {
      "x": -9,
      "y": 0,
      "z": -8,
      "name": "Rock_Stone_Brick"
    },
    {
      "x": -9,
      "y": 11,
      "z": -8,
      "name": "Rock_Stone_Brick"
    },
    {
      "x": -9,
      "y": 0,
      "z": -7,
      "name": "Rock_Stone_Brick"
    },
    {
      "x": -9,
      "y": 11,
      "z": -7,
      "name": "Rock_Stone_Brick"
    },
    {
      "x": -9,
      "y": 0,
      "z": -6,
      "name": "Rock_Stone_Brick"
    },
    {
      "x": -9,
      "y": 11,
      "z": -6,
      "name": "Rock_Stone_Brick"
    },
    {
      "x": -9,
      "y": 0,
      "z": -5,
      "name": "Rock_Stone_Brick"
    },
    {
      "x": -9,
      "y": 11,
      "z": -5,
      "name": "Rock_Stone_Brick"
    },
    {
      "x": -9,
      "y": 0,
      "z": -4,
      "name": "Rock_Stone_Brick"
    },
    {
      "x": -9,
      "y": 11,
      "z": -4,
      "name": "Rock_Stone_Brick"
    },
    {
      "x": -9,
      "y": 0,
      "z": -3,
      "name": "Rock_Stone_Brick"
    },
    {
      "x": -9,
      "y": 11,
      "z": -3,
      "name": "Rock_Stone_Brick"
    },
    {
      "x": -9,
      "y": 0,
      "z": -2,
      "name": "Rock_Stone_Brick"
    },
    {
      "x": -9,
      "y": 11,
      "z": -2,
      "name": "Rock_Stone_Brick"
    },
    {
      "x": -9,
      "y": 0,
      "z": -1,
      "name": "Rock_Stone_Brick"
    },
    {
      "x": -9,
      "y": 11,
      "z": -1,
      "name": "Rock_Stone_Brick"
    },
    {
      "x": -9,
      "y": 0,
      "z": 0,
      "name": "Rock_Stone_Brick"
    },
    {
      "x": -9,
      "y": 11,
      "z": 0,
      "name": "Rock_Stone_Brick"
    },
    {
      "x": -9,
      "y": 0,
      "z": 1,
      "name": "Rock_Stone_Brick"
    },
    {
      "x": -9,
      "y": 11,
      "z": 1,
      "name": "Rock_Stone_Brick"
    },
    {
      "x": -9,
      "y": 0,
      "z": 2,
      "name": "Rock_Stone_Brick"
    },
    {
      "x": -9,
      "y": 11,
      "z": 2,
      "name": "Rock_Stone_Brick"
    },
    {
      "x": -9,
      "y": 0,
      "z": 3,
      "name": "Rock_Stone_Brick"
    },
    {
      "x": -9,
      "y": 11,
      "z": 3,
      "name": "Rock_Stone_Brick"
    },
    {
      "x": -9,
      "y": 0,
      "z": 4,
      "name": "Rock_Stone_Brick"
    },
    {
      "x": -9,
      "y": 11,
      "z": 4,
      "name": "Rock_Stone_Brick"
    },
    {
      "x": -9,
      "y": 0,
      "z": 5,
      "name": "Rock_Stone_Brick"
    },
    {
      "x": -9,
      "y": 11,
      "z": 5,
      "name": "Rock_Stone_Brick"
    },
    {
      "x": -9,
      "y": 0,
      "z": 6,
      "name": "Rock_Stone_Brick"
    },
    {
      "x": -9,
      "y": 11,
      "z": 6,
      "name": "Rock_Stone_Brick"
    },
    {
      "x": -9,
      "y": 0,
      "z": 7,
      "name": "Rock_Stone_Brick"
    },
    {
      "x": -9,
      "y": 11,
      "z": 7,
      "name": "Rock_Stone_Brick"
    },
    {
      "x": -9,
      "y": 0,
      "z": 8,
      "name": "Rock_Stone_Brick"
    },
    {
      "x": -9,
      "y": 11,
      "z": 8,
      "name": "Rock_Stone_Brick"
    },
    {
      "x": -9,
      "y": 0,
      "z": 9,
      "name": "Rock_Stone_Brick"
    },
    {
      "x": -9,
      "y": 11,
      "z": 9,
      "name": "Rock_Stone_Brick"
    },
    {
      "x": -9,
      "y": 0,
      "z": 10,
      "name": "Rock_Stone_Brick"
    },
    {
      "x": -9,
      "y": 11,
      "z": 10,
      "name": "Rock_Stone_Brick"
    },
    {
      "x": -9,
      "y": 0,
      "z": 11,
      "name": "Rock_Stone_Brick"
    },
    {
      "x": -9,
      "y": 11,
      "z": 11,
      "name": "Rock_Stone_Brick"
    },
    {
      "x": -9,
      "y": 0,
      "z": 12,
      "name": "Rock_Stone_Brick"
    },
    {
      "x": -9,
      "y": 11,
      "z": 12,
      "name": "Rock_Stone_Brick"
    },
    {
      "x": -9,
      "y": 0,
      "z": 13,
      "name": "Rock_Stone_Brick"
    },
    {
      "x": -9,
      "y": 11,
      "z": 13,
      "name": "Rock_Stone_Brick"
    },
    {
      "x": -9,
      "y": 0,
      "z": 14,
      "name": "Rock_Stone_Brick"
    },
    {
      "x": -9,
      "y": 11,
      "z": 14,
      "name": "Rock_Stone_Brick"
    },
    {
      "x": -9,
      "y": 0,
      "z": 15,
      "name": "Rock_Stone_Brick"
    },
    {
      "x": -9,
      "y": 11,
      "z": 15,
      "name": "Rock_Stone_Brick"
    },
    {
      "x": -9,
      "y": 0,
      "z": 16,
      "name": "Rock_Stone_Brick"
    },
    {
      "x": -9,
      "y": 1,
      "z": 16,
      "name": "Rock_Stone_Brick"
    },
    {
      "x": -9,
      "y": 2,
      "z": 16,
      "name": "Rock_Stone_Brick"
    },
    {
      "x": -9,
      "y": 3,
      "z": 16,
      "name": "Rock_Stone_Brick"
    },
    {
      "x": -9,
      "y": 4,
      "z": 16,
      "name": "Rock_Stone_Brick"
    },
    {
      "x": -9,
      "y": 5,
      "z": 16,
      "name": "Rock_Stone_Brick"
    },
    {
      "x": -9,
      "y": 6,
      "z": 16,
      "name": "Rock_Stone_Brick"
    },
    {
      "x": -9,
      "y": 7,
      "z": 16,
      "name": "Rock_Stone_Brick"
    },
    {
      "x": -9,
      "y": 8,
      "z": 16,
      "name": "Rock_Stone_Brick"
    },
    {
      "x": -9,
      "y": 9,
      "z": 16,
      "name": "Rock_Stone_Brick"
    },
    {
      "x": -9,
      "y": 10,
      "z": 16,
      "name": "Rock_Stone_Brick"
    },
    {
      "x": -9,
      "y": 11,
      "z": 16,
      "name": "Rock_Stone_Brick"
    },
    {
      "x": -8,
      "y": 0,
      "z": -16,
      "name": "Rock_Stone_Brick"
    },
    {
      "x": -8,
      "y": 1,
      "z": -16,
      "name": "Rock_Stone_Brick"
    },
    {
      "x": -8,
      "y": 2,
      "z": -16,
      "name": "Rock_Stone_Brick"
    },
    {
      "x": -8,
      "y": 3,
      "z": -16,
      "name": "Rock_Stone_Brick"
    },
    {
      "x": -8,
      "y": 4,
      "z": -16,
      "name": "Rock_Stone_Brick"
    },
    {
      "x": -8,
      "y": 5,
      "z": -16,
      "name": "Rock_Stone_Brick"
    },
    {
      "x": -8,
      "y": 6,
      "z": -16,
      "name": "Rock_Stone_Brick"
    },
    {
      "x": -8,
      "y": 7,
      "z": -16,
      "name": "Rock_Stone_Brick"
    },
    {
      "x": -8,
      "y": 8,
      "z": -16,
      "name": "Rock_Stone_Brick"
    },
    {
      "x": -8,
      "y": 9,
      "z": -16,
      "name": "Rock_Stone_Brick"
    },
    {
      "x": -8,
      "y": 10,
      "z": -16,
      "name": "Rock_Stone_Brick"
    },
    {
      "x": -8,
      "y": 11,
      "z": -16,
      "name": "Rock_Stone_Brick"
    },
    {
      "x": -8,
      "y": 0,
      "z": -15,
      "name": "Rock_Stone_Brick"
    },
    {
      "x": -8,
      "y": 11,
      "z": -15,
      "name": "Rock_Stone_Brick"
    },
    {
      "x": -8,
      "y": 0,
      "z": -14,
      "name": "Rock_Stone_Brick"
    },
    {
      "x": -8,
      "y": 11,
      "z": -14,
      "name": "Rock_Stone_Brick"
    },
    {
      "x": -8,
      "y": 0,
      "z": -13,
      "name": "Rock_Stone_Brick"
    },
    {
      "x": -8,
      "y": 11,
      "z": -13,
      "name": "Rock_Stone_Brick"
    },
    {
      "x": -8,
      "y": 0,
      "z": -12,
      "name": "Rock_Stone_Brick"
    },
    {
      "x": -8,
      "y": 11,
      "z": -12,
      "name": "Rock_Stone_Brick"
    },
    {
      "x": -8,
      "y": 0,
      "z": -11,
      "name": "Rock_Stone_Brick"
    },
    {
      "x": -8,
      "y": 11,
      "z": -11,
      "name": "Rock_Stone_Brick"
    },
    {
      "x": -8,
      "y": 0,
      "z": -10,
      "name": "Rock_Stone_Brick"
    },
    {
      "x": -8,
      "y": 11,
      "z": -10,
      "name": "Rock_Stone_Brick"
    },
    {
      "x": -8,
      "y": 0,
      "z": -9,
      "name": "Rock_Stone_Brick"
    },
    {
      "x": -8,
      "y": 11,
      "z": -9,
      "name": "Rock_Stone_Brick"
    },
    {
      "x": -8,
      "y": 0,
      "z": -8,
      "name": "Rock_Stone_Brick"
    },
    {
      "x": -8,
      "y": 11,
      "z": -8,
      "name": "Rock_Stone_Brick"
    },
    {
      "x": -8,
      "y": 0,
      "z": -7,
      "name": "Rock_Stone_Brick"
    },
    {
      "x": -8,
      "y": 11,
      "z": -7,
      "name": "Rock_Stone_Brick"
    },
    {
      "x": -8,
      "y": 0,
      "z": -6,
      "name": "Rock_Stone_Brick"
    },
    {
      "x": -8,
      "y": 11,
      "z": -6,
      "name": "Rock_Stone_Brick"
    },
    {
      "x": -8,
      "y": 0,
      "z": -5,
      "name": "Rock_Stone_Brick"
    },
    {
      "x": -8,
      "y": 11,
      "z": -5,
      "name": "Rock_Stone_Brick"
    },
    {
      "x": -8,
      "y": 0,
      "z": -4,
      "name": "Rock_Stone_Brick"
    },
    {
      "x": -8,
      "y": 11,
      "z": -4,
      "name": "Rock_Stone_Brick"
    },
    {
      "x": -8,
      "y": 0,
      "z": -3,
      "name": "Rock_Stone_Brick"
    },
    {
      "x": -8,
      "y": 11,
      "z": -3,
      "name": "Rock_Stone_Brick"
    },
    {
      "x": -8,
      "y": 0,
      "z": -2,
      "name": "Rock_Stone_Brick"
    },
    {
      "x": -8,
      "y": 11,
      "z": -2,
      "name": "Rock_Stone_Brick"
    },
    {
      "x": -8,
      "y": 0,
      "z": -1,
      "name": "Rock_Stone_Brick"
    },
    {
      "x": -8,
      "y": 11,
      "z": -1,
      "name": "Rock_Stone_Brick"
    },
    {
      "x": -8,
      "y": 0,
      "z": 0,
      "name": "Rock_Stone_Brick"
    },
    {
      "x": -8,
      "y": 11,
      "z": 0,
      "name": "Rock_Stone_Brick"
    },
    {
      "x": -8,
      "y": 0,
      "z": 1,
      "name": "Rock_Stone_Brick"
    },
    {
      "x": -8,
      "y": 11,
      "z": 1,
      "name": "Rock_Stone_Brick"
    },
    {
      "x": -8,
      "y": 0,
      "z": 2,
      "name": "Rock_Stone_Brick"
    },
    {
      "x": -8,
      "y": 11,
      "z": 2,
      "name": "Rock_Stone_Brick"
    },
    {
      "x": -8,
      "y": 0,
      "z": 3,
      "name": "Rock_Stone_Brick"
    },
    {
      "x": -8,
      "y": 11,
      "z": 3,
      "name": "Rock_Stone_Brick"
    },
    {
      "x": -8,
      "y": 0,
      "z": 4,
      "name": "Rock_Stone_Brick"
    },
    {
      "x": -8,
      "y": 11,
      "z": 4,
      "name": "Rock_Stone_Brick"
    },
    {
      "x": -8,
      "y": 0,
      "z": 5,
      "name": "Rock_Stone_Brick"
    },
    {
      "x": -8,
      "y": 11,
      "z": 5,
      "name": "Rock_Stone_Brick"
    },
    {
      "x": -8,
      "y": 0,
      "z": 6,
      "name": "Rock_Stone_Brick"
    },
    {
      "x": -8,
      "y": 11,
      "z": 6,
      "name": "Rock_Stone_Brick"
    },
    {
      "x": -8,
      "y": 0,
      "z": 7,
      "name": "Rock_Stone_Brick"
    },
    {
      "x": -8,
      "y": 11,
      "z": 7,
      "name": "Rock_Stone_Brick"
    },
    {
      "x": -8,
      "y": 0,
      "z": 8,
      "name": "Rock_Stone_Brick"
    },
    {
      "x": -8,
      "y": 11,
      "z": 8,
      "name": "Rock_Stone_Brick"
    },
    {
      "x": -8,
      "y": 0,
      "z": 9,
      "name": "Rock_Stone_Brick"
    },
    {
      "x": -8,
      "y": 11,
      "z": 9,
      "name": "Rock_Stone_Brick"
    },
    {
      "x": -8,
      "y": 0,
      "z": 10,
      "name": "Rock_Stone_Brick"
    },
    {
      "x": -8,
      "y": 11,
      "z": 10,
      "name": "Rock_Stone_Brick"
    },
    {
      "x": -8,
      "y": 0,
      "z": 11,
      "name": "Rock_Stone_Brick"
    },
    {
      "x": -8,
      "y": 11,
      "z": 11,
      "name": "Rock_Stone_Brick"
    },
    {
      "x": -8,
      "y": 0,
      "z": 12,
      "name": "Rock_Stone_Brick"
    },
    {
      "x": -8,
      "y": 11,
      "z": 12,
      "name": "Rock_Stone_Brick"
    },
    {
      "x": -8,
      "y": 0,
      "z": 13,
      "name": "Rock_Stone_Brick"
    },
    {
      "x": -8,
      "y": 11,
      "z": 13,
      "name": "Rock_Stone_Brick"
    },
    {
      "x": -8,
      "y": 0,
      "z": 14,
      "name": "Rock_Stone_Brick"
    },
    {
      "x": -8,
      "y": 11,
      "z": 14,
      "name": "Rock_Stone_Brick"
    },
    {
      "x": -8,
      "y": 0,
      "z": 15,
      "name": "Rock_Stone_Brick"
    },
    {
      "x": -8,
      "y": 11,
      "z": 15,
      "name": "Rock_Stone_Brick"
    },
    {
      "x": -8,
      "y": 0,
      "z": 16,
      "name": "Rock_Stone_Brick"
    },
    {
      "x": -8,
      "y": 1,
      "z": 16,
      "name": "Rock_Stone_Brick"
    },
    {
      "x": -8,
      "y": 2,
      "z": 16,
      "name": "Rock_Stone_Brick"
    },
    {
      "x": -8,
      "y": 3,
      "z": 16,
      "name": "Rock_Stone_Brick"
    },
    {
      "x": -8,
      "y": 4,
      "z": 16,
      "name": "Rock_Stone_Brick"
    },
    {
      "x": -8,
      "y": 5,
      "z": 16,
      "name": "Rock_Stone_Brick"
    },
    {
      "x": -8,
      "y": 6,
      "z": 16,
      "name": "Rock_Stone_Brick"
    },
    {
      "x": -8,
      "y": 7,
      "z": 16,
      "name": "Rock_Stone_Brick"
    },
    {
      "x": -8,
      "y": 8,
      "z": 16,
      "name": "Rock_Stone_Brick"
    },
    {
      "x": -8,
      "y": 9,
      "z": 16,
      "name": "Rock_Stone_Brick"
    },
    {
      "x": -8,
      "y": 10,
      "z": 16,
      "name": "Rock_Stone_Brick"
    },
    {
      "x": -8,
      "y": 11,
      "z": 16,
      "name": "Rock_Stone_Brick"
    },
    {
      "x": -7,
      "y": 0,
      "z": -16,
      "name": "Rock_Stone_Brick"
    },
    {
      "x": -7,
      "y": 1,
      "z": -16,
      "name": "Rock_Stone_Brick"
    },
    {
      "x": -7,
      "y": 2,
      "z": -16,
      "name": "Rock_Stone_Brick"
    },
    {
      "x": -7,
      "y": 3,
      "z": -16,
      "name": "Rock_Stone_Brick"
    },
    {
      "x": -7,
      "y": 4,
      "z": -16,
      "name": "Rock_Stone_Brick"
    },
    {
      "x": -7,
      "y": 5,
      "z": -16,
      "name": "Rock_Stone_Brick"
    },
    {
      "x": -7,
      "y": 6,
      "z": -16,
      "name": "Rock_Stone_Brick"
    },
    {
      "x": -7,
      "y": 7,
      "z": -16,
      "name": "Rock_Stone_Brick"
    },
    {
      "x": -7,
      "y": 8,
      "z": -16,
      "name": "Rock_Stone_Brick"
    },
    {
      "x": -7,
      "y": 9,
      "z": -16,
      "name": "Rock_Stone_Brick"
    },
    {
      "x": -7,
      "y": 10,
      "z": -16,
      "name": "Rock_Stone_Brick"
    },
    {
      "x": -7,
      "y": 11,
      "z": -16,
