{
  "version": 8,
  "blockIdVersion": 10,
  "anchorX": 0,
  "anchorY": 1,
  "anchorZ": -2,
  "blocks": [
    {
      "x": 0,
      "y": 1,
      "z": -2,
      "name": "Rock_Stone_Brick"
    },
    {
      "x": 0,
      "y": 2,
      "z": -2,
      "name": "Rock_Stone_Brick_Stairs",
      "rotation": 2
    },
    {
      "x": 0,
      "y": 1,
      "z": -1,
      "name": "Rock_Stone_Brick"
    },
    {
      "x": 0,
      "y": 2,
      "z": -1,
      "name": "Rock_Stone_Brick"
    },
    {
      "x": 0,
      "y": 3,
      "z": -1,
      "name": "Rock_Stone_Brick_Stairs",
      "rotation": 2
    },
    {
      "x": 0,
      "y": 1,
      "z": 0,
      "name": "Rock_Stone_Brick"
    },
    {
      "x": 0,
      "y": 2,
      "z": 0,
      "name": "Rock_Stone_Brick"
    },
    {
      "x": 0,
      "y": 3,
      "z": 0,
      "name": "Rock_Stone_Brick"
    },
    {
      "x": 0,
      "y": 4,
      "z": 0,
      "name": "Rock_Stone_Brick_Stairs",
      "rotation": 2
    },
    {
      "x": 0,
      "y": 1,
      "z": 1,
      "name": "Rock_Stone_Brick"
    },
    {
      "x": 0,
      "y": 2,
      "z": 1,
      "name": "Rock_Stone_Brick"
    },
    {
      "x": 0,
      "y": 3,
      "z": 1,
      "name": "Rock_Stone_Brick"
    },
    {
      "x": 0,
      "y": 4,
      "z": 1,
      "name": "Rock_Stone_Brick"
    },
    {
      "x": 0,
      "y": 5,
      "z": 1,
      "name": "Rock_Stone_Brick_Stairs",
      "rotation": 2
    },
    {
      "x": 0,
      "y": 1,
      "z": 2,
      "name": "Rock_Stone_Brick"
    },
    {
      "x": 0,
      "y": 2,
      "z": 2,
      "name": "Rock_Stone_Brick"
    },
    {
      "x": 0,
      "y": 3,
      "z": 2,
      "name": "Rock_Stone_Brick"
    },
    {
      "x": 0,
      "y": 4,
      "z": 2,
      "name": "Rock_Stone_Brick"
    },
    {
      "x": 0,
      "y": 5,
      "z": 2,
      "name": "Rock_Stone_Brick"
    },
    {
      "x": 0,
      "y": 6,
      "z": 2,
      "name": "Rock_Stone_Brick_Stairs",
      "rotation": 2
    },
    {
      "x": 0,
      "y": 1,
      "z": 3,
      "name": "Rock_Stone_Brick"
    },
    {
      "x": 0,
      "y": 3,
      "z": 3,
      "name": "Rock_Stone_Brick"
    },
    {
      "x": 0,
      "y": 4,
      "z": 3,
      "name": "Rock_Stone_Brick"
    },
    {
      "x": 0,
      "y": 5,
      "z": 3,
      "name": "Rock_Stone_Brick"
    },
    {
      "x": 0,
      "y": 6,
      "z": 3,
      "name": "Rock_Stone_Brick"
    },
    {
      "x": 0,
      "y": 1,
      "z": 4,
      "name": "Rock_Stone_Brick"
    },
    {
      "x": 0,
      "y": 4,
      "z": 4,
      "name": "Rock_Stone_Brick"
    },
    {
      "x": 0,
      "y": 5,
      "z": 4,
      "name": "Rock_Stone_Brick"
    },
    {
      "x": 0,
      "y": 4,
      "z": 5,
      "name": "Rock_Stone_Brick"
    },
    {
      "x": 0,
      "y": 5,
      "z": 5,
      "name": "Rock_Stone_Brick"
    },
    {
      "x": 0,
      "y": 1,
      "z": 6,
      "name": "Rock_Stone_Brick"
    },
    {
      "x": 0,
      "y": 3,
      "z": 6,
      "name": "Rock_Stone_Brick"
    },
    {
      "x": 0,
      "y": 4,
      "z": 6,
      "name": "Rock_Stone_Brick"
    },
    {
      "x": 0,
      "y": 5,
      "z": 6,
      "name": "Rock_Stone_Brick"
    },
    {
      "x": 0,
      "y": 6,
      "z": 6,
      "name": "Rock_Stone_Brick"
    },
    {
      "x": 0,
      "y": 1,
      "z": 7,
      "name": "Rock_Stone_Brick"
    },
    {
      "x": 0,
      "y": 2,
      "z": 7,
      "name": "Rock_Stone_Brick"
    },
    {
      "x": 0,
      "y": 3,
      "z": 7,
      "name": "Rock_Stone_Brick"
    },
    {
      "x": 0,
      "y": 4,
      "z": 7,
      "name": "Rock_Stone_Brick"
    },
    {
      "x": 0,
      "y": 5,
      "z": 7,
      "name": "Rock_Stone_Brick"
    },
    {
      "x": 0,
      "y": 6,
      "z": 7,
      "name": "Rock_Stone_Brick_Stairs",
      "rotation": 3
    },
    {
      "x": 0,
      "y": 1,
      "z": 8,
      "name": "Rock_Stone_Brick"
    },
    {
      "x": 0,
      "y": 2,
      "z": 8,
      "name": "Rock_Stone_Brick"
    },
    {
      "x": 0,
      "y": 3,
      "z": 8,
      "name": "Rock_Stone_Brick"
    },
    {
      "x": 0,
      "y": 4,
      "z": 8,
      "name": "Rock_Stone_Brick"
    },
    {
      "x": 0,
      "y": 5,
      "z": 8,
      "name": "Rock_Stone_Brick"
    },
    {
      "x": 0,
      "y": 6,
      "z": 8,
      "name": "Rock_Stone_Brick_Stairs",
      "rotation": 3
    },
    {
      "x": 0,
      "y": 1,
      "z": 9,
      "name": "Rock_Stone_Brick"
    },
    {
      "x": 0,
      "y": 2,
      "z": 9,
      "name": "Rock_Stone_Brick"
    },
    {
      "x": 0,
      "y": 3,
      "z": 9,
      "name": "Rock_Stone_Brick"
    },
    {
      "x": 0,
      "y": 4,
      "z": 9,
      "name": "Rock_Stone_Brick"
    },
    {
      "x": 0,
      "y": 5,
      "z": 9,
      "name": "Rock_Stone_Brick"
    },
    {
      "x": 0,
      "y": 6,
      "z": 9,
      "name": "Rock_Stone_Brick"
    },
    {
      "x": 1,
      "y": 1,
      "z": -2,
      "name": "Rock_Stone_Brick_Stairs",
      "rotation": 2
    },
    {
      "x": 1,
      "y": 1,
      "z": -1,
      "name": "Rock_Stone_Brick"
    },
    {
      "x": 1,
      "y": 2,
      "z": -1,
      "name": "Rock_Stone_Brick_Stairs",
      "rotation": 2
    },
    {
      "x": 1,
      "y": 1,
      "z": 0,
      "name": "Rock_Stone_Brick"
    },
    {
      "x": 1,
      "y": 2,
      "z": 0,
      "name": "Rock_Stone_Brick"
    },
    {
      "x": 1,
      "y": 3,
      "z": 0,
      "name": "Rock_Stone_Brick_Stairs",
      "rotation": 2
    },
    {
      "x": 1,
      "y": 2,
      "z": 1,
      "name": "Rock_Stone_Brick_Stairs",
      "rotation": 10
    },
    {
      "x": 1,
      "y": 3,
      "z": 1,
      "name": "Rock_Stone_Brick"
    },
    {
      "x": 1,
      "y": 4,
      "z": 1,
      "name": "Rock_Stone_Brick_Stairs",
      "rotation": 2
    },
    {
      "x": 1,
      "y": 1,
      "z": 2,
      "name": "Deco_SpiderWeb_Full"
    },
    {
      "x": 1,
      "y": 3,
      "z": 2,
      "name": "Rock_Stone_Brick_Stairs",
      "rotation": 10
    },
    {
      "x": 1,
      "y": 4,
      "z": 2,
      "name": "Rock_Stone_Brick"
    },
    {
      "x": 1,
      "y": 5,
      "z": 2,
      "name": "Rock_Stone_Brick_Stairs",
      "rotation": 2
    },
    {
      "x": 1,
      "y": 4,
      "z": 3,
      "name": "Rock_Stone_Brick_Stairs",
      "rotation": 10
    },
    {
      "x": 1,
      "y": 5,
      "z": 3,
      "name": "Rock_Stone_Brick"
    },
    {
      "x": 1,
      "y": 1,
      "z": 4,
      "name": "Rubble_Stone_Medium"
    },
    {
      "x": 1,
      "y": 4,
      "z": 4,
      "name": "Deco_SpiderWeb",
      "rotation": 10
    },
    {
      "x": 1,
      "y": 5,
      "z": 4,
      "name": "Rock_Stone_Brick"
    },
    {
      "x": 1,
      "y": 5,
      "z": 5,
      "name": "Rock_Stone_Brick"
    },
    {
      "x": 1,
      "y": 5,
      "z": 6,
      "name": "Rock_Stone_Brick"
    },
    {
      "x": 1,
      "y": 1,
      "z": 7,
      "name": "Rubble_Stone"
    },
    {
      "x": 1,
      "y": 5,
      "z": 7,
      "name": "Rock_Stone_Brick"
    },
    {
      "x": 1,
      "y": 5,
      "z": 8,
      "name": "Rock_Stone_Brick"
    },
    {
      "x": 1,
      "y": 1,
      "z": 9,
      "name": "Rock_Stone_Brick"
    },
    {
      "x": 1,
      "y": 2,
      "z": 9,
      "name": "Rock_Stone_Brick"
    },
    {
      "x": 1,
      "y": 3,
      "z": 9,
      "name": "Rock_Stone_Brick"
    },
    {
      "x": 1,
      "y": 4,
      "z": 9,
      "name": "Rock_Stone_Brick"
    },
    {
      "x": 1,
      "y": 5,
      "z": 9,
      "name": "Rock_Stone_Brick"
    },
    {
      "x": 1,
      "y": 6,
      "z": 9,
      "name": "Rock_Stone_Brick"
    },
    {
      "x": 2,
      "y": 1,
      "z": -2,
      "name": "Rock_Stone_Brick_Stairs",
      "rotation": 2
    },
    {
      "x": 2,
      "y": 1,
      "z": -1,
      "name": "Rock_Stone_Brick"
    },
    {
      "x": 2,
      "y": 2,
      "z": -1,
      "name": "Rock_Stone_Brick_Stairs",
      "rotation": 2
    },
    {
      "x": 2,
      "y": 1,
      "z": 0,
      "name": "Rock_Stone_Brick"
    },
    {
      "x": 2,
      "y": 2,
      "z": 0,
      "name": "Rock_Stone_Brick"
    },
    {
      "x": 2,
      "y": 3,
      "z": 0,
      "name": "Rock_Stone_Brick_Stairs",
      "rotation": 2
    },
    {
      "x": 2,
      "y": 1,
      "z": 1,
      "name": "Rock_Stone_Brick_Stairs",
      "rotation": 10
    },
    {
      "x": 2,
      "y": 2,
      "z": 1,
      "name": "Rock_Stone_Brick"
    },
    {
      "x": 2,
      "y": 3,
      "z": 1,
      "name": "Rock_Stone_Brick"
    },
    {
      "x": 2,
      "y": 4,
      "z": 1,
      "name": "Rock_Stone_Brick_Stairs",
      "rotation": 2
    },
    {
      "x": 2,
      "y": 2,
      "z": 2,
      "name": "Rock_Stone_Brick_Stairs",
      "rotation": 10
    },
    {
      "x": 2,
      "y": 3,
      "z": 2,
      "name": "Rock_Stone_Brick"
    },
    {
      "x": 2,
      "y": 4,
      "z": 2,
      "name": "Rock_Stone_Brick"
    },
    {
      "x": 2,
      "y": 5,
      "z": 2,
      "name": "Rock_Stone_Brick_Stairs",
      "rotation": 2
    },
    {
      "x": 2,
      "y": 3,
      "z": 3,
      "name": "Rock_Stone_Brick_Stairs",
      "rotation": 10
    },
    {
      "x": 2,
      "y": 4,
      "z": 3,
      "name": "Rock_Stone_Brick"
    },
    {
      "x": 2,
      "y": 5,
      "z": 3,
      "name": "Rock_Stone_Brick"
    },
    {
      "x": 2,
      "y": 4,
      "z": 4,
      "name": "Rock_Stone_Brick_Stairs",
      "rotation": 10
    },
    {
      "x": 2,
      "y": 5,
      "z": 4,
      "name": "Rock_Stone_Brick"
    },
    {
      "x": 2,
      "y": 5,
      "z": 5,
      "name": "Rock_Stone_Brick"
    },
    {
      "x": 2,
      "y": 5,
      "z": 6,
      "name": "Rock_Stone_Brick"
    },
    {
      "x": 2,
      "y": 5,
      "z": 7,
      "name": "Rock_Stone_Brick"
    },
    {
      "x": 2,
      "y": 5,
      "z": 8,
      "name": "Rock_Stone_Brick"
    },
    {
      "x": 2,
      "y": 1,
      "z": 9,
      "name": "Rock_Stone_Brick"
    },
    {
      "x": 2,
      "y": 2,
      "z": 9,
      "name": "Rock_Stone_Brick"
    },
    {
      "x": 2,
      "y": 3,
      "z": 9,
      "name": "Rock_Stone_Brick"
    },
    {
      "x": 2,
      "y": 4,
      "z": 9,
      "name": "Rock_Stone_Brick"
    },
    {
      "x": 2,
      "y": 5,
      "z": 9,
      "name": "Rock_Stone_Brick"
    },
    {
      "x": 2,
      "y": 6,
      "z": 9,
      "name": "Rock_Stone_Brick"
    },
    {
      "x": 3,
      "y": 1,
      "z": -2,
      "name": "Rock_Stone_Brick"
    },
    {
      "x": 3,
      "y": 2,
      "z": -2,
      "name": "Rock_Stone_Brick_Stairs",
      "rotation": 2
    },
    {
      "x": 3,
      "y": 1,
      "z": -1,
      "name": "Rock_Stone_Brick"
    },
    {
      "x": 3,
      "y": 2,
      "z": -1,
      "name": "Rock_Stone_Brick"
    },
    {
      "x": 3,
      "y": 3,
      "z": -1,
      "name": "Rock_Stone_Brick_Stairs",
      "rotation": 2
    },
    {
      "x": 3,
      "y": 1,
      "z": 0,
      "name": "Rock_Stone_Brick"
    },
    {
      "x": 3,
      "y": 2,
      "z": 0,
      "name": "Rock_Stone_Brick_Ornate"
    },
    {
      "x": 3,
      "y": 3,
      "z": 0,
      "name": "Rock_Stone_Brick"
    },
    {
      "x": 3,
      "y": 4,
      "z": 0,
      "name": "Rock_Stone_Brick"
    },
    {
      "x": 3,
      "y": 5,
      "z": 0,
      "name": "Rock_Stone_Brick"
    },
    {
      "x": 3,
      "y": 6,
      "z": 0,
      "name": "Rock_Stone_Brick"
    },
    {
      "x": 3,
      "y": 1,
      "z": 1,
      "name": "Deco_SpiderWeb"
    },
    {
      "x": 3,
      "y": 2,
      "z": 1,
      "name": "Rock_Stone_Brick_Stairs",
      "rotation": 10
    },
    {
      "x": 3,
      "y": 3,
      "z": 1,
      "name": "Rock_Stone_Brick"
    },
    {
      "x": 3,
      "y": 4,
      "z": 1,
      "name": "Rock_Stone_Brick"
    },
    {
      "x": 3,
      "y": 5,
      "z": 1,
      "name": "Rock_Stone_Brick"
    },
    {
      "x": 3,
      "y": 6,
      "z": 1,
      "name": "Rock_Stone_Brick_Stairs",
      "rotation": 3
    },
    {
      "x": 3,
      "y": 3,
      "z": 2,
      "name": "Rock_Stone_Brick_Stairs",
      "rotation": 10
    },
    {
      "x": 3,
      "y": 4,
      "z": 2,
      "name": "Rock_Stone_Brick"
    },
    {
      "x": 3,
      "y": 5,
      "z": 2,
      "name": "Rock_Stone_Brick"
    },
    {
      "x": 3,
      "y": 6,
      "z": 2,
      "name": "Rock_Stone_Brick_Stairs",
      "rotation": 3
    },
    {
      "x": 3,
      "y": 4,
      "z": 3,
      "name": "Rock_Stone_Brick_Stairs",
      "rotation": 10
    },
    {
      "x": 3,
      "y": 5,
      "z": 3,
      "name": "Rock_Stone_Brick"
    },
    {
      "x": 3,
      "y": 6,
      "z": 3,
      "name": "Rock_Stone_Brick"
    },
    {
      "x": 3,
      "y": 1,
      "z": 4,
      "name": "Rubble_Stone"
    },
    {
      "x": 3,
      "y": 5,
      "z": 4,
      "name": "Rock_Stone_Brick"
    },
    {
      "x": 3,
      "y": 5,
      "z": 5,
      "name": "Rock_Stone_Brick"
    },
    {
      "x": 3,
      "y": 5,
      "z": 6,
      "name": "Rock_Stone_Brick"
    },
    {
      "x": 3,
      "y": 5,
      "z": 7,
      "name": "Rock_Stone_Brick"
    },
    {
      "x": 3,
      "y": 1,
      "z": 8,
      "name": "Deco_Treasure",
      "rotation": 2
    },
    {
      "x": 3,
      "y": 5,
      "z": 8,
      "name": "Rock_Stone_Brick"
    },
    {
      "x": 3,
      "y": 1,
      "z": 9,
      "name": "Rock_Stone_Brick"
    },
    {
      "x": 3,
      "y": 2,
      "z": 9,
      "name": "Rock_Stone_Brick"
    },
    {
      "x": 3,
      "y": 3,
      "z": 9,
      "name": "Rock_Stone_Brick"
    },
    {
      "x": 3,
      "y": 4,
      "z": 9,
      "name": "Rock_Stone_Brick"
    },
    {
      "x": 3,
      "y": 5,
      "z": 9,
      "name": "Rock_Stone_Brick"
    },
    {
      "x": 3,
      "y": 6,
      "z": 9,
      "name": "Rock_Stone_Brick"
    },
    {
      "x": 4,
      "y": 4,
      "z": 0,
      "name": "Rock_Stone_Brick_Stairs",
      "rotation": 11
    },
    {
      "x": 4,
      "y": 5,
      "z": 0,
      "name": "Rock_Stone_Brick"
    },
    {
      "x": 4,
      "y": 5,
      "z": 1,
      "name": "Rock_Stone_Brick"
    },
    {
      "x": 4,
      "y": 5,
      "z": 2,
      "name": "Rock_Stone_Brick"
    },
    {
      "x": 4,
      "y": 5,
      "z": 3,
      "name": "Rock_Stone_Brick"
    },
    {
      "x": 4,
      "y": 5,
      "z": 4,
      "name": "Rock_Stone_Brick"
    },
    {
      "x": 4,
      "y": 5,
      "z": 5,
      "name": "Rock_Stone_Brick"
    },
    {
      "x": 4,
      "y": 5,
      "z": 6,
      "name": "Rock_Stone_Brick"
    },
    {
      "x": 4,
      "y": 1,
      "z": 7,
      "name": "Deco_Treasure",
      "rotation": 2
    },
    {
      "x": 4,
      "y": 5,
      "z": 7,
      "name": "Rock_Stone_Brick"
    },
    {
      "x": 4,
      "y": 1,
      "z": 8,
      "name": "Deco_Treasure_Pile_Large",
      "rotation": 2
    },
    {
      "x": 4,
      "y": 5,
      "z": 8,
      "name": "Rock_Stone_Brick"
    },
    {
      "x": 4,
      "y": 1,
      "z": 9,
      "name": "Rock_Stone_Brick"
    },
    {
      "x": 4,
      "y": 2,
      "z": 9,
      "name": "Rock_Stone_Brick"
    },
    {
      "x": 4,
      "y": 3,
      "z": 9,
      "name": "Rock_Stone_Brick"
    },
    {
      "x": 4,
      "y": 4,
      "z": 9,
      "name": "Rock_Stone_Brick"
    },
    {
      "x": 4,
      "y": 5,
      "z": 9,
      "name": "Rock_Stone_Brick"
    },
    {
      "x": 4,
      "y": 6,
      "z": 9,
      "name": "Rock_Stone_Brick"
    },
    {
      "x": 5,
      "y": 4,
      "z": 0,
      "name": "Rock_Stone_Brick_Stairs",
      "rotation": 9
    },
    {
      "x": 5,
      "y": 5,
      "z": 0,
      "name": "Rock_Stone_Brick"
    },
    {
      "x": 5,
      "y": 6,
      "z": 0,
      "name": "Prefab_Spawner_Block",
      "components": {
        "Components": {
          "PlacedByInteraction": {
            "WhoPlacedUuid": {
              "$binary": "30E5va+4QA2ISsflEWOC9g==",
              "$type": "04"
            }
          },
          "prefabspawner": {
            "Position": {
              "X": 5,
              "Y": 5,
              "Z": 2
            },
            "PrefabPath": "Refresh_Studios/Skeleton_Dungeon/Bridge1",
            "FitHeightmap": false,
            "InheritSeed": true,
            "InheritHeightCondition": true
          }
        }
      },
      "rotation": 2
    },
    {
      "x": 5,
      "y": 1,
      "z": 1,
      "name": "Rubble_Stone"
    },
    {
      "x": 5,
      "y": 5,
      "z": 1,
      "name": "Rock_Stone_Brick"
    },
    {
      "x": 5,
      "y": 5,
      "z": 2,
      "name": "Rock_Stone_Brick"
    },
    {
      "x": 5,
      "y": 5,
      "z": 3,
      "name": "Rock_Stone_Brick"
    },
    {
      "x": 5,
      "y": 6,
      "z": 3,
      "name": "Rubble_Stone"
    },
    {
      "x": 5,
      "y": 5,
      "z": 4,
      "name": "Rock_Stone_Brick"
    },
    {
      "x": 5,
      "y": 5,
      "z": 5,
      "name": "Rock_Stone_Brick"
    },
    {
      "x": 5,
      "y": 5,
      "z": 6,
      "name": "Rock_Stone_Brick"
    },
    {
      "x": 5,
      "y": 5,
      "z": 7,
      "name": "Rock_Stone_Brick"
    },
    {
      "x": 5,
      "y": 9,
      "z": 7,
      "name": "Furniture_Human_Ruins_Banner",
      "rotation": 2
    },
    {
      "x": 5,
      "y": 1,
      "z": 8,
      "name": "Deco_Treasure_Pile_Small",
      "rotation": 2
    },
    {
      "x": 5,
      "y": 5,
      "z": 8,
      "name": "Rock_Stone_Brick"
    },
    {
      "x": 5,
      "y": 1,
      "z": 9,
      "name": "Rock_Stone_Brick"
    },
    {
      "x": 5,
      "y": 2,
      "z": 9,
      "name": "Rock_Stone_Brick"
    },
    {
      "x": 5,
      "y": 3,
      "z": 9,
      "name": "Rock_Stone_Brick"
    },
    {
      "x": 5,
      "y": 4,
      "z": 9,
      "name": "Rock_Stone_Brick"
    },
    {
      "x": 5,
      "y": 5,
      "z": 9,
      "name": "Rock_Stone_Brick"
    },
    {
      "x": 5,
      "y": 6,
      "z": 9,
      "name": "Rock_Stone_Brick"
    },
    {
      "x": 6,
      "y": 1,
      "z": 0,
      "name": "Rock_Stone_Brick"
    },
    {
      "x": 6,
      "y": 2,
      "z": 0,
      "name": "Rock_Stone_Brick_Ornate"
    },
    {
      "x": 6,
      "y": 3,
      "z": 0,
      "name": "Rock_Stone_Brick"
    },
    {
      "x": 6,
      "y": 4,
      "z": 0,
      "name": "Rock_Stone_Brick"
    },
    {
      "x": 6,
      "y": 5,
      "z": 0,
      "name": "Rock_Stone_Brick"
    },
    {
      "x": 6,
      "y": 6,
      "z": 0,
      "name": "Rock_Stone_Brick"
    },
    {
      "x": 6,
      "y": 5,
      "z": 1,
      "name": "Rock_Stone_Brick"
    },
    {
      "x": 6,
      "y": 5,
      "z": 2,
      "name": "Rock_Stone_Brick"
    },
    {
      "x": 6,
      "y": 6,
      "z": 2,
      "name": "Rubble_Stone_Medium"
    },
    {
      "x": 6,
      "y": 5,
      "z": 3,
      "name": "Rock_Stone_Brick"
    },
    {
      "x": 6,
      "y": 6,
      "z": 3,
      "name": "Rock_Stone_Brick"
    },
    {
      "x": 6,
      "y": 7,
      "z": 3,
      "name": "Rock_Stone_Brick"
    },
    {
      "x": 6,
      "y": 5,
      "z": 4,
      "name": "Rock_Stone_Brick"
    },
    {
      "x": 6,
      "y": 6,
      "z": 4,
      "name": "Rock_Stone_Brick"
    },
    {
      "x": 6,
      "y": 7,
      "z": 4,
      "name": "Rock_Stone_Brick_Ornate"
    },
    {
      "x": 6,
      "y": 8,
      "z": 4,
      "name": "Rock_Stone_Brick"
    },
    {
      "x": 6,
      "y": 9,
      "z": 4,
      "name": "Rock_Stone_Brick"
    },
    {
      "x": 6,
      "y": 5,
      "z": 5,
      "name": "Rock_Stone_Brick"
    },
    {
      "x": 6,
      "y": 9,
      "z": 5,
      "name": "Rock_Stone_Brick_Stairs",
      "rotation": 10
    },
    {
      "x": 6,
      "y": 10,
      "z": 5,
      "name": "Rock_Stone_Brick"
    },
    {
      "x": 6,
      "y": 5,
      "z": 6,
      "name": "Rock_Stone_Brick"
    },
    {
      "x": 6,
      "y": 9,
      "z": 6,
      "name": "Rock_Stone_Brick_Stairs",
      "rotation": 8
    },
    {
      "x": 6,
      "y": 10,
      "z": 6,
      "name": "Rock_Stone_Brick"
    },
    {
      "x": 6,
      "y": 5,
      "z": 7,
      "name": "Rock_Stone_Brick"
    },
    {
      "x": 6,
      "y": 6,
      "z": 7,
      "name": "Rock_Stone_Brick"
    },
    {
      "x": 6,
      "y": 7,
      "z": 7,
      "name": "Rock_Stone_Brick_Ornate"
    },
    {
      "x": 6,
      "y": 8,
      "z": 7,
      "name": "Rock_Stone_Brick"
    },
    {
      "x": 6,
      "y": 9,
      "z": 7,
      "name": "Rock_Stone_Brick"
    },
    {
      "x": 6,
      "y": 10,
      "z": 7,
      "name": "Rock_Stone_Brick"
    },
    {
      "x": 6,
      "y": 1,
      "z": 8,
      "name": "Deco_Treasure",
      "rotation": 2
    },
    {
      "x": 6,
      "y": 5,
      "z": 8,
      "name": "Rock_Stone_Brick"
    },
    {
      "x": 6,
      "y": 6,
      "z": 8,
      "name": "Rock_Stone_Brick"
    },
    {
      "x": 6,
      "y": 7,
      "z": 8,
      "name": "Rock_Stone_Brick"
    },
    {
      "x": 6,
      "y": 8,
      "z": 8,
      "name": "Rock_Stone_Brick"
    },
    {
      "x": 6,
      "y": 9,
      "z": 8,
      "name": "Rock_Stone_Brick"
    },
    {
      "x": 6,
      "y": 10,
      "z": 8,
      "name": "Rock_Stone_Brick_Stairs",
      "rotation": 3
    },
    {
      "x": 6,
      "y": 1,
      "z": 9,
      "name": "Rock_Stone_Brick"
    },
    {
      "x": 6,
      "y": 2,
      "z": 9,
      "name": "Rock_Stone_Brick"
    },
    {
      "x": 6,
      "y": 3,
      "z": 9,
      "name": "Rock_Stone_Brick"
    },
    {
      "x": 6,
      "y": 4,
      "z": 9,
      "name": "Rock_Stone_Brick"
    },
    {
      "x": 6,
      "y": 5,
      "z": 9,
      "name": "Rock_Stone_Brick"
    },
    {
      "x": 6,
      "y": 6,
      "z": 9,
      "name": "Rock_Stone_Brick"
    },
    {
      "x": 6,
      "y": 7,
      "z": 9,
      "name": "Rock_Stone_Brick"
    },
    {
      "x": 6,
      "y": 8,
      "z": 9,
      "name": "Rock_Stone_Brick"
    },
    {
      "x": 6,
      "y": 9,
      "z": 9,
      "name": "Rock_Stone_Brick"
    },
    {
      "x": 6,
      "y": 10,
      "z": 9,
      "name": "Rock_Stone_Brick_Stairs",
      "rotation": 3
    },
    {
      "x": 7,
      "y": 1,
      "z": 0,
      "name": "Rock_Stone_Brick"
    },
    {
      "x": 7,
      "y": 4,
      "z": 0,
      "name": "Rock_Stone_Brick"
    },
    {
      "x": 7,
      "y": 5,
      "z": 0,
      "name": "Rock_Stone_Brick"
    },
    {
      "x": 7,
      "y": 6,
      "z": 0,
      "name": "Rock_Stone_Brick_Stairs",
      "rotation": 2
    },
    {
      "x": 7,
      "y": 1,
      "z": 1,
      "name": "Rubble_Stone_Medium"
    },
    {
      "x": 7,
      "y": 5,
      "z": 1,
      "name": "Rock_Stone_Brick"
    },
    {
      "x": 7,
      "y": 5,
      "z": 4,
      "name": "Rock_Stone_Brick"
    },
    {
      "x": 7,
      "y": 1,
      "z": 5,
      "name": "Rubble_Stone_Medium"
    },
    {
      "x": 7,
      "y": 5,
      "z": 5,
      "name": "Rock_Stone_Brick"
    },
    {
      "x": 7,
      "y": 10,
      "z": 5,
      "name": "Rock_Stone_Brick"
    },
    {
      "x": 7,
      "y": 5,
      "z": 6,
      "name": "Rock_Stone_Brick"
    },
    {
      "x": 7,
      "y": 10,
      "z": 6,
      "name": "Rock_Stone_Brick"
    },
    {
      "x": 7,
      "y": 5,
      "z": 7,
      "name": "Rock_Stone_Brick"
    },
    {
      "x": 7,
      "y": 10,
      "z": 7,
      "name": "Rock_Stone_Brick"
    },
    {
      "x": 7,
      "y": 4,
      "z": 8,
      "name": "Deco_SpiderWeb",
      "rotation": 8
    },
    {
      "x": 7,
      "y": 5,
      "z": 8,
      "name": "Rock_Stone_Brick"
    },
    {
      "x": 7,
      "y": 6,
      "z": 8,
      "name": "Block_Spawner_Block",
      "components": {
        "Components": {
          "PlacedByInteraction": {
            "WhoPlacedUuid": {
              "$binary": "30E5va+4QA2ISsflEWOC9g==",
              "$type": "04"
            }
          },
          "BlockSpawner": {
            "BlockSpawnerId": "YUNGs_HyDungeons_Skeleton_Dungeon_Common"
          }
        }
      },
      "rotation": 2
    },
    {
      "x": 7,
      "y": 9,
      "z": 8,
      "name": "Deco_SpiderWeb",
      "rotation": 8
    },
    {
      "x": 7,
      "y": 10,
      "z": 8,
      "name": "Rock_Stone_Brick"
    },
    {
      "x": 7,
      "y": 1,
      "z": 9,
      "name": "Rock_Stone_Brick"
    },
    {
      "x": 7,
      "y": 2,
      "z": 9,
      "name": "Rock_Stone_Brick"
    },
    {
      "x": 7,
      "y": 3,
      "z": 9,
      "name": "Rock_Stone_Brick"
    },
    {
      "x": 7,
      "y": 4,
      "z": 9,
      "name": "Rock_Stone_Brick"
    },
    {
      "x": 7,
      "y": 5,
      "z": 9,
      "name": "Rock_Stone_Brick"
    },
    {
      "x": 7,
      "y": 6,
      "z": 9,
      "name": "Rock_Stone_Brick"
    },
    {
      "x": 7,
      "y": 7,
      "z": 9,
      "name": "Rock_Stone_Brick"
    },
    {
      "x": 7,
      "y": 8,
      "z": 9,
      "name": "Rock_Stone_Brick"
    },
    {
      "x": 7,
      "y": 9,
      "z": 9,
      "name": "Rock_Stone_Brick"
    },
    {
      "x": 7,
      "y": 10,
      "z": 9,
      "name": "Rock_Stone_Brick"
    },
    {
      "x": 8,
      "y": 1,
      "z": 0,
      "name": "Rubble_Stone"
    },
    {
      "x": 8,
      "y": 4,
      "z": 0,
      "name": "Rock_Stone_Brick"
    },
    {
      "x": 8,
      "y": 5,
      "z": 0,
      "name": "Rock_Stone_Brick"
    },
    {
      "x": 8,
      "y": 6,
      "z": 0,
      "name": "Rock_Stone_Brick_Stairs",
      "rotation": 2
    },
    {
      "x": 8,
      "y": 5,
      "z": 3,
      "name": "Rock_Stone_Brick"
    },
    {
      "x": 8,
      "y": 6,
      "z": 3,
      "name": "Rock_Stone_Brick"
    },
    {
      "x": 8,
      "y": 7,
      "z": 3,
      "name": "Rock_Stone_Brick"
    },
    {
      "x": 8,
      "y": 9,
      "z": 3,
      "name": "Rock_Stone_Brick"
    },
    {
      "x": 8,
      "y": 10,
      "z": 3,
      "name": "Rock_Stone_Brick_Stairs",
      "rotation": 2
    },
    {
      "x": 8,
      "y": 5,
      "z": 4,
      "name": "Rock_Stone_Brick"
    },
    {
      "x": 8,
      "y": 6,
      "z": 4,
      "name": "Block_Spawner_Block",
      "components": {
        "Components": {
          "PlacedByInteraction": {
            "WhoPlacedUuid": {
              "$binary": "30E5va+4QA2ISsflEWOC9g==",
              "$type": "04"
            }
          },
          "BlockSpawner": {
            "BlockSpawnerId": "YUNGs_HyDungeons_Skeleton_Dungeon_Pot_Small"
          }
        }
      }
    },
    {
      "x": 8,
      "y": 10,
      "z": 4,
      "name": "Rock_Stone_Brick"
    },
    {
      "x": 8,
      "y": 5,
      "z": 5,
      "name": "Rock_Stone_Brick"
    },
    {
      "x": 8,
      "y": 10,
      "z": 5,
      "name": "Rock_Stone_Brick"
    },
    {
      "x": 8,
      "y": 1,
      "z": 6,
      "name": "Rubble_Stone"
    },
    {
      "x": 8,
      "y": 5,
      "z": 6,
      "name": "Rock_Stone_Brick"
    },
    {
      "x": 8,
      "y": 10,
      "z": 6,
      "name": "Rock_Stone_Brick"
    },
    {
      "x": 8,
      "y": 5,
      "z": 7,
      "name": "Rock_Stone_Brick"
    },
    {
      "x": 8,
      "y": 10,
      "z": 7,
      "name": "Rock_Stone_Brick"
    },
    {
      "x": 8,
      "y": 5,
      "z": 8,
      "name": "Rock_Stone_Brick"
    },
    {
      "x": 8,
      "y": 6,
      "z": 8,
      "name": "Block_Spawner_Block",
      "components": {
        "Components": {
          "PlacedByInteraction": {
            "WhoPlacedUuid": {
              "$binary": "30E5va+4QA2ISsflEWOC9g==",
              "$type": "04"
            }
          },
          "BlockSpawner": {
            "BlockSpawnerId": "YUNGs_HyDungeons_Skeleton_Dungeon_Pot"
          }
        }
      },
      "rotation": 2
    },
    {
      "x": 8,
      "y": 10,
      "z": 8,
      "name": "Rock_Stone_Brick"
    },
    {
      "x": 8,
      "y": 1,
      "z": 9,
      "name": "Rock_Stone_Brick"
    },
    {
      "x": 8,
      "y": 2,
      "z": 9,
      "name": "Rock_Stone_Brick"
    },
    {
      "x": 8,
      "y": 3,
      "z": 9,
      "name": "Rock_Stone_Brick"
    },
    {
      "x": 8,
      "y": 4,
      "z": 9,
      "name": "Rock_Stone_Brick"
    },
    {
      "x": 8,
      "y": 5,
      "z": 9,
      "name": "Rock_Stone_Brick"
    },
    {
      "x": 8,
      "y": 6,
      "z": 9,
      "name": "Rock_Stone_Brick"
    },
    {
      "x": 8,
      "y": 7,
      "z": 9,
      "name": "Rock_Stone_Brick"
    },
    {
      "x": 8,
      "y": 8,
      "z": 9,
      "name": "Rock_Stone_Brick"
    },
    {
      "x": 8,
      "y": 9,
      "z": 9,
      "name": "Rock_Stone_Brick"
    },
    {
      "x": 8,
      "y": 10,
      "z": 9,
      "name": "Rock_Stone_Brick"
    },
    {
      "x": 9,
      "y": 1,
      "z": 0,
      "name": "Rock_Stone_Brick"
    },
    {
      "x": 9,
      "y": 2,
      "z": 0,
      "name": "Rock_Stone_Brick"
    },
    {
      "x": 9,
      "y": 3,
      "z": 0,
      "name": "Rock_Stone_Brick"
    },
    {
      "x": 9,
      "y": 4,
      "z": 0,
      "name": "Rock_Stone_Brick"
    },
    {
      "x": 9,
      "y": 5,
      "z": 0,
      "name": "Rock_Stone_Brick"
    },
    {
      "x": 9,
      "y": 6,
      "z": 0,
      "name": "Rock_Stone_Brick"
    },
    {
      "x": 9,
      "y": 1,
      "z": 1,
      "name": "Rock_Stone_Brick"
    },
    {
      "x": 9,
      "y": 2,
      "z": 1,
      "name": "Rock_Stone_Brick"
    },
    {
      "x": 9,
      "y": 3,
      "z": 1,
      "name": "Rock_Stone_Brick"
    },
    {
      "x": 9,
      "y": 4,
      "z": 1,
      "name": "Rock_Stone_Brick"
    },
    {
      "x": 9,
      "y": 5,
      "z": 1,
      "name": "Rock_Stone_Brick"
    },
    {
      "x": 9,
      "y": 6,
      "z": 1,
      "name": "Rock_Stone_Brick"
    },
    {
      "x": 9,
      "y": 1,
      "z": 2,
      "name": "Rock_Stone_Brick"
    },
    {
      "x": 9,
      "y": 2,
      "z": 2,
      "name": "Rock_Stone_Brick"
    },
    {
      "x": 9,
      "y": 3,
      "z": 2,
      "name": "Rock_Stone_Brick"
    },
    {
      "x": 9,
      "y": 4,
      "z": 2,
      "name": "Rock_Stone_Brick"
    },
    {
      "x": 9,
      "y": 5,
      "z": 2,
      "name": "Rock_Stone_Brick"
    },
    {
      "x": 9,
      "y": 6,
      "z": 2,
      "name": "Rock_Stone_Brick"
    },
    {
      "x": 9,
      "y": 1,
      "z": 3,
      "name": "Rock_Stone_Brick"
    },
    {
      "x": 9,
      "y": 2,
      "z": 3,
      "name": "Rock_Stone_Brick"
    },
    {
      "x": 9,
      "y": 3,
      "z": 3,
      "name": "Rock_Stone_Brick"
    },
    {
      "x": 9,
      "y": 4,
      "z": 3,
      "name": "Rock_Stone_Brick"
    },
    {
      "x": 9,
      "y": 5,
      "z": 3,
      "name": "Rock_Stone_Brick"
    },
    {
      "x": 9,
      "y": 6,
      "z": 3,
      "name": "Rock_Stone_Brick"
    },
    {
      "x": 9,
      "y": 7,
      "z": 3,
      "name": "Rock_Stone_Brick"
    },
    {
      "x": 9,
      "y": 8,
      "z": 3,
      "name": "Rock_Stone_Brick"
    },
    {
      "x": 9,
      "y": 9,
      "z": 3,
      "name": "Rock_Stone_Brick"
    },
    {
      "x": 9,
      "y": 10,
      "z": 3,
      "name": "Rock_Stone_Brick"
    },
    {
      "x": 9,
      "y": 1,
      "z": 4,
      "name": "Rock_Stone_Brick"
    },
    {
      "x": 9,
      "y": 2,
      "z": 4,
      "name": "Rock_Stone_Brick"
    },
    {
      "x": 9,
      "y": 3,
      "z": 4,
      "name": "Rock_Stone_Brick"
    },
    {
      "x": 9,
      "y": 4,
      "z": 4,
      "name": "Rock_Stone_Brick"
    },
    {
      "x": 9,
      "y": 5,
      "z": 4,
      "name": "Rock_Stone_Brick"
    },
    {
      "x": 9,
      "y": 6,
      "z": 4,
      "name": "Rock_Stone_Brick"
    },
    {
      "x": 9,
      "y": 7,
      "z": 4,
      "name": "Rock_Stone_Brick"
    },
    {
      "x": 9,
      "y": 8,
      "z": 4,
      "name": "Rock_Stone_Brick"
    },
    {
      "x": 9,
      "y": 9,
      "z": 4,
      "name": "Rock_Stone_Brick"
    },
    {
      "x": 9,
      "y": 10,
      "z": 4,
      "name": "Rock_Stone_Brick"
    },
    {
      "x": 9,
      "y": 1,
      "z": 5,
      "name": "Rock_Stone_Brick"
    },
    {
      "x": 9,
      "y": 2,
      "z": 5,
      "name": "Rock_Stone_Brick"
    },
    {
      "x": 9,
      "y": 3,
      "z": 5,
      "name": "Rock_Stone_Brick"
    },
    {
      "x": 9,
      "y": 4,
      "z": 5,
      "name": "Rock_Stone_Brick"
    },
    {
      "x": 9,
      "y": 5,
      "z": 5,
      "name": "Rock_Stone_Brick"
    },
    {
      "x": 9,
      "y": 6,
      "z": 5,
      "name": "Rock_Stone_Brick"
    },
    {
      "x": 9,
      "y": 7,
      "z": 5,
      "name": "Rock_Stone_Brick"
    },
    {
      "x": 9,
      "y": 8,
      "z": 5,
      "name": "Rock_Stone_Brick"
    },
    {
      "x": 9,
      "y": 9,
      "z": 5,
      "name": "Rock_Stone_Brick"
    },
    {
      "x": 9,
      "y": 10,
      "z": 5,
      "name": "Rock_Stone_Brick"
    },
    {
      "x": 9,
      "y": 1,
      "z": 6,
      "name": "Rock_Stone_Brick"
    },
    {
      "x": 9,
      "y": 2,
      "z": 6,
      "name": "Rock_Stone_Brick"
    },
    {
      "x": 9,
      "y": 3,
      "z": 6,
      "name": "Rock_Stone_Brick"
    },
    {
      "x": 9,
      "y": 4,
      "z": 6,
      "name": "Rock_Stone_Brick"
    },
    {
      "x": 9,
      "y": 5,
      "z": 6,
      "name": "Rock_Stone_Brick"
    },
    {
      "x": 9,
      "y": 6,
      "z": 6,
      "name": "Rock_Stone_Brick"
    },
    {
      "x": 9,
      "y": 7,
      "z": 6,
      "name": "Rock_Stone_Brick"
    },
    {
      "x": 9,
      "y": 8,
      "z": 6,
      "name": "Rock_Stone_Brick"
    },
    {
      "x": 9,
      "y": 9,
      "z": 6,
      "name": "Rock_Stone_Brick"
    },
    {
      "x": 9,
      "y": 10,
      "z": 6,
      "name": "Rock_Stone_Brick"
    },
    {
      "x": 9,
      "y": 1,
      "z": 7,
      "name": "Rock_Stone_Brick"
    },
    {
      "x": 9,
      "y": 2,
      "z": 7,
      "name": "Rock_Stone_Brick"
    },
    {
      "x": 9,
      "y": 3,
      "z": 7,
      "name": "Rock_Stone_Brick"
    },
    {
      "x": 9,
      "y": 4,
      "z": 7,
      "name": "Rock_Stone_Brick"
    },
    {
      "x": 9,
      "y": 5,
      "z": 7,
      "name": "Rock_Stone_Brick"
    },
    {
      "x": 9,
      "y": 6,
      "z": 7,
      "name": "Rock_Stone_Brick"
    },
    {
      "x": 9,
      "y": 7,
      "z": 7,
      "name": "Rock_Stone_Brick"
    },
    {
      "x": 9,
      "y": 8,
      "z": 7,
      "name": "Rock_Stone_Brick"
    },
    {
      "x": 9,
      "y": 9,
      "z": 7,
      "name": "Rock_Stone_Brick"
    },
    {
      "x": 9,
      "y": 10,
      "z": 7,
      "name": "Rock_Stone_Brick"
    },
    {
      "x": 9,
      "y": 1,
      "z": 8,
      "name": "Rock_Stone_Brick"
    },
    {
      "x": 9,
      "y": 2,
      "z": 8,
      "name": "Rock_Stone_Brick"
    },
    {
      "x": 9,
      "y": 3,
      "z": 8,
      "name": "Rock_Stone_Brick"
    },
    {
      "x": 9,
      "y": 4,
      "z": 8,
      "name": "Rock_Stone_Brick"
    },
    {
      "x": 9,
      "y": 5,
      "z": 8,
      "name": "Rock_Stone_Brick"
    },
    {
      "x": 9,
      "y": 6,
      "z": 8,
      "name": "Rock_Stone_Brick"
    },
    {
      "x": 9,
      "y": 7,
      "z": 8,
      "name": "Rock_Stone_Brick"
    },
    {
      "x": 9,
      "y": 8,
      "z": 8,
      "name": "Rock_Stone_Brick"
    },
    {
      "x": 9,
      "y": 9,
      "z": 8,
      "name": "Rock_Stone_Brick"
    },
    {
      "x": 9,
      "y": 10,
      "z": 8,
      "name": "Rock_Stone_Brick"
    },
    {
      "x": 9,
      "y": 1,
      "z": 9,
      "name": "Rock_Stone_Brick"
    },
    {
      "x": 9,
      "y": 2,
      "z": 9,
      "name": "Rock_Stone_Brick"
    },
    {
      "x": 9,
      "y": 3,
      "z": 9,
      "name": "Rock_Stone_Brick"
    },
    {
      "x": 9,
      "y": 4,
      "z": 9,
      "name": "Rock_Stone_Brick"
    },
    {
      "x": 9,
      "y": 5,
      "z": 9,
      "name": "Rock_Stone_Brick"
    },
    {
      "x": 9,
      "y": 6,
      "z": 9,
      "name": "Rock_Stone_Brick"
    },
    {
      "x": 9,
      "y": 7,
      "z": 9,
      "name": "Rock_Stone_Brick"
    },
    {
      "x": 9,
      "y": 8,
      "z": 9,
      "name": "Rock_Stone_Brick"
    },
    {
      "x": 9,
      "y": 9,
      "z": 9,
      "name": "Rock_Stone_Brick"
    },
    {
      "x": 9,
      "y": 10,
      "z": 9,
      "name": "Rock_Stone_Brick"
    }
  ],
  "entities": [
    {
      "Components": {
        "EffectController": {},
        "DisplayName": {
          "DisplayName": {
            "MessageId": "server.npcRoles.Skeleton_Knight.name",
            "Bold": null,
            "Italic": null,
            "Monospace": null,
            "Underline": null
          }
        },
        "UIComponentList": {},
        "Transform": {
          "Position": {
            "X": 5.468111038208008,
            "Y": 1.8198204040527344,
            "Z": 6.002777099609375
          },
          "Rotation": {
            "Pitch": 0.0,
            "Yaw": 0.19250620901584625,
            "Roll": 0.0
          }
        },
        "Velocity": {
          "Velocity": {
            "X": 0.0,
            "Y": 0.0,
            "Z": 0.0
          }
        },
        "Interactions": {
          "Interactions": {
            "Use": "*UseNPC"
          }
        },
        "Model": {
          "Model": {
            "Id": "Skeleton_Knight",
            "Scale": 1.0,
            "Static": false
          }
        },
        "UUID": {
          "UUID": {
            "$binary": "YfXOk6EUMECZSaiEG0wSYw==",
            "$type": "04"
          }
        },
        "EntityStats": {
          "Version": 5,
          "Stats": {
            "Oxygen": {
              "Id": "Oxygen",
              "Value": 100.0
            },
            "Mana": {
              "Id": "Mana",
              "Value": 0.0
            },
            "Health": {
              "Id": "Health",
              "Value": 59.0
            },
            "GlidingActive": {
              "Id": "GlidingActive",
              "Value": 0.0
            },
            "Immunity": {
              "Id": "Immunity",
              "Value": 0.0
            },
            "SignatureCharges": {
              "Id": "SignatureCharges",
              "Value": 0.0
            },
            "Stamina": {
              "Id": "Stamina",
              "Value": 10.0
            },
            "Ammo": {
              "Id": "Ammo",
              "Value": 0.0
            },
            "Unknown": {
              "Id": "Unknown",
              "Value": 0.0
            },
            "SignatureEnergy": {
              "Id": "SignatureEnergy",
              "Value": 0.0
            },
            "DeployablePreview": {
              "Id": "DeployablePreview",
              "Value": 0.0
            },
            "StaminaRegenDelay": {
              "Id": "StaminaRegenDelay",
              "Value": 0.0
            },
            "MagicCharges": {
              "Id": "MagicCharges",
              "Value": 0.0
            }
          }
        },
        "NPC": {
          "Version": 5,
          "UUID": {
            "$binary": "93BqlsQGOVSLfKUj2TvzoA==",
            "$type": "04"
          },
          "Inventory": {
            "Version": 4,
            "Storage": {
              "Id": "Empty"
            },
            "Armor": {
              "Id": "Simple",
              "Capacity": 4,
              "Items": {}
            },
            "HotBar": {
              "Id": "Simple",
              "Capacity": 3,
              "Items": {
                "0": {
                  "Id": "Weapon_Sword_Steel_Rusty",
                  "Quantity": 1,
                  "Durability": 80.0,
                  "MaxDurability": 80.0,
                  "OverrideDroppedItemAnimation": false
                }
              }
            },
            "Utility": {
              "Id": "Simple",
              "Capacity": 2,
              "Items": {
                "0": {
                  "Id": "Weapon_Shield_Rusty",
                  "Quantity": 1,
                  "Durability": 0.0,
                  "MaxDurability": 0.0,
                  "OverrideDroppedItemAnimation": false
                }
              }
            },
            "Backpack": {
              "Id": "Empty"
            },
            "ActiveHotbarSlot": 0,
            "Tool": {
              "Id": "Empty"
            },
            "ActiveToolsSlot": -1,
            "ActiveUtilitySlot": 0,
            "SortType": "Name"
          },
          "HvrPhs": 0.0,
          "HvrHght": 0.0,
          "MdlScl": 1.0,
          "SpawnInstant": "0001-01-01T12:00:00Z",
          "WorldgenId": 0,
          "PathManager": {},
          "LeashPos": {
            "X": 5.468111038208008,
            "Y": 55.819820404052734,
            "Z": 105.00277709960938
          },
          "LeashHdg": 0.19250620901584625,
          "LeashPtch": 0.0,
          "RoleName": "Skeleton_Knight"
        },
        "HeadRotation": {
          "Rotation": {
            "Pitch": 0.0,
            "Yaw": 0.19250620901584625,
            "Roll": 0.0
          }
        }
      }
    },
    {
      "Components": {
        "EffectController": {},
        "DisplayName": {
          "DisplayName": {
            "MessageId": "server.npcRoles.Skeleton_Archer.name",
            "Bold": null,
            "Italic": null,
            "Monospace": null,
            "Underline": null
          }
        },
        "UIComponentList": {},
        "Transform": {
          "Position": {
            "X": 4.559581756591797,
            "Y": 6.0,
            "Z": 6.110328674316406
          },
          "Rotation": {
            "Pitch": 0.0,
            "Yaw": 0.17870309948921204,
            "Roll": 0.0
          }
        },
        "Velocity": {
          "Velocity": {
            "X": 0.0,
            "Y": 0.0,
            "Z": 0.0
          }
        },
        "Interactions": {
          "Interactions": {
            "Use": "*UseNPC"
          }
        },
        "Model": {
          "Model": {
            "Id": "Skeleton_Archer",
            "Scale": 1.0,
            "Static": false
          }
        },
        "UUID": {
          "UUID": {
            "$binary": "v0IBpJMhP7KtcUHBzQIPfQ==",
            "$type": "04"
          }
        },
        "EntityStats": {
          "Version": 5,
          "Stats": {
            "Oxygen": {
              "Id": "Oxygen",
              "Value": 100.0
            },
            "Mana": {
              "Id": "Mana",
              "Value": 0.0
            },
            "Health": {
              "Id": "Health",
              "Value": 29.0
            },
            "GlidingActive": {
              "Id": "GlidingActive",
              "Value": 0.0
            },
            "Immunity": {
              "Id": "Immunity",
              "Value": 0.0
            },
            "SignatureCharges": {
              "Id": "SignatureCharges",
              "Value": 0.0
            },
            "Stamina": {
              "Id": "Stamina",
              "Value": 10.0
            },
            "Ammo": {
              "Id": "Ammo",
              "Value": 0.0
            },
            "Unknown": {
              "Id": "Unknown",
              "Value": 0.0
            },
            "SignatureEnergy": {
              "Id": "SignatureEnergy",
              "Value": 0.0
            },
            "DeployablePreview": {
              "Id": "DeployablePreview",
              "Value": 0.0
            },
            "StaminaRegenDelay": {
              "Id": "StaminaRegenDelay",
              "Value": 0.0
            },
            "MagicCharges": {
              "Id": "MagicCharges",
              "Value": 0.0
            }
          }
        },
        "NPC": {
          "Version": 5,
          "UUID": {
            "$binary": "7vZgykaaOfKmwURCBfB0gQ==",
            "$type": "04"
          },
          "Inventory": {
            "Version": 4,
            "Storage": {
              "Id": "Empty"
            },
            "Armor": {
              "Id": "Simple",
              "Capacity": 4,
              "Items": {}
            },
            "HotBar": {
              "Id": "Simple",
              "Capacity": 3,
              "Items": {
                "0": {
                  "Id": "Weapon_Shortbow_Iron_Rusty",
                  "Quantity": 1,
                  "Durability": 120.0,
                  "MaxDurability": 120.0,
                  "OverrideDroppedItemAnimation": false
                }
              }
            },
            "Utility": {
              "Id": "Simple",
              "Capacity": 2,
              "Items": {
                "0": {
                  "Id": "Furniture_Crude_Torch",
                  "Quantity": 1,
                  "Durability": 0.0,
                  "MaxDurability": 0.0,
                  "OverrideDroppedItemAnimation": false
                }
              }
            },
            "Backpack": {
              "Id": "Empty"
            },
            "ActiveHotbarSlot": 0,
            "Tool": {
              "Id": "Empty"
            },
            "ActiveToolsSlot": -1,
            "ActiveUtilitySlot": -1,
            "SortType": "Name"
          },
          "HvrPhs": 0.0,
          "HvrHght": 0.0,
          "MdlScl": 1.0,
          "SpawnInstant": "0001-01-01T12:00:00Z",
          "WorldgenId": 0,
          "PathManager": {},
          "LeashPos": {
            "X": 4.559581756591797,
            "Y": 60.0,
            "Z": 105.1103286743164
          },
          "LeashHdg": 0.17870309948921204,
          "LeashPtch": 0.0,
          "RoleName": "Skeleton_Archer"
        },
        "HeadRotation": {
          "Rotation": {
            "Pitch": 0.0,
            "Yaw": 0.17870309948921204,
            "Roll": 0.0
          }
        }
      }
    },
    {
      "Components": {
        "EffectController": {},
        "DisplayName": {
          "DisplayName": {
            "MessageId": "server.npcRoles.Skeleton_Archer.name",
            "Bold": null,
            "Italic": null,
            "Monospace": null,
            "Underline": null
          }
        },
        "UIComponentList": {},
        "Transform": {
          "Position": {
            "X": 2.31573486328125,
            "Y": 6.0,
            "Z": 6.347171783447266
          },
          "Rotation": {
            "Pitch": 0.0,
            "Yaw": 0.17870309948921204,
            "Roll": 0.0
          }
        },
        "Velocity": {
          "Velocity": {
            "X": 0.0,
            "Y": 0.0,
            "Z": 0.0
          }
        },
        "Interactions": {
          "Interactions": {
            "Use": "*UseNPC"
          }
        },
        "Model": {
          "Model": {
            "Id": "Skeleton_Archer",
            "Scale": 1.0,
            "Static": false
          }
        },
        "UUID": {
          "UUID": {
            "$binary": "JsIsPPQDPxOK7jH6Zfk79w==",
            "$type": "04"
          }
        },
        "EntityStats": {
          "Version": 5,
          "Stats": {
            "Oxygen": {
              "Id": "Oxygen",
              "Value": 100.0
            },
            "Mana": {
              "Id": "Mana",
              "Value": 0.0
            },
            "Health": {
              "Id": "Health",
              "Value": 29.0
            },
            "GlidingActive": {
              "Id": "GlidingActive",
              "Value": 0.0
            },
            "Immunity": {
              "Id": "Immunity",
              "Value": 0.0
            },
            "SignatureCharges": {
              "Id": "SignatureCharges",
              "Value": 0.0
            },
            "Stamina": {
              "Id": "Stamina",
              "Value": 10.0
            },
            "Ammo": {
              "Id": "Ammo",
              "Value": 0.0
            },
            "Unknown": {
              "Id": "Unknown",
              "Value": 0.0
            },
            "SignatureEnergy": {
              "Id": "SignatureEnergy",
              "Value": 0.0
            },
            "DeployablePreview": {
              "Id": "DeployablePreview",
              "Value": 0.0
            },
            "StaminaRegenDelay": {
              "Id": "StaminaRegenDelay",
              "Value": 0.0
            },
            "MagicCharges": {
              "Id": "MagicCharges",
              "Value": 0.0
            }
          }
        },
        "NPC": {
          "Version": 5,
          "UUID": {
            "$binary": "RKwDQDbIMPmRVZIpoRHnFQ==",
            "$type": "04"
          },
          "Inventory": {
            "Version": 4,
            "Storage": {
              "Id": "Empty"
            },
            "Armor": {
              "Id": "Simple",
              "Capacity": 4,
              "Items": {}
            },
            "HotBar": {
              "Id": "Simple",
              "Capacity": 3,
              "Items": {
                "0": {
                  "Id": "Weapon_Shortbow_Iron_Rusty",
                  "Quantity": 1,
                  "Durability": 120.0,
                  "MaxDurability": 120.0,
                  "OverrideDroppedItemAnimation": false
                }
              }
            },
            "Utility": {
              "Id": "Simple",
              "Capacity": 2,
              "Items": {
                "0": {
                  "Id": "Furniture_Crude_Torch",
                  "Quantity": 1,
                  "Durability": 0.0,
                  "MaxDurability": 0.0,
                  "OverrideDroppedItemAnimation": false
                }
              }
            },
            "Backpack": {
              "Id": "Empty"
            },
            "ActiveHotbarSlot": 0,
            "Tool": {
              "Id": "Empty"
            },
            "ActiveToolsSlot": -1,
            "ActiveUtilitySlot": -1,
            "SortType": "Name"
          },
          "HvrPhs": 0.0,
          "HvrHght": 0.0,
          "MdlScl": 1.0,
          "SpawnInstant": "0001-01-01T12:00:00Z",
          "WorldgenId": 0,
          "PathManager": {},
          "LeashPos": {
            "X": 2.31573486328125,
            "Y": 60.0,
            "Z": 105.34717178344727
          },
          "LeashHdg": 0.17870309948921204,
          "LeashPtch": 0.0,
          "RoleName": "Skeleton_Archer"
        },
        "HeadRotation": {
          "Rotation": {
            "Pitch": 0.0,
            "Yaw": 0.17870309948921204,
            "Roll": 0.0
          }
        }
      }
    }
  ]
}