{
  "version": 8,
  "blockIdVersion": 10,
  "anchorX": 0,
  "anchorY": 5,
  "anchorZ": -5,
  "blocks": [
    {
      "x": -4,
      "y": 0,
      "z": -2,
      "name": "Rock_Stone_Brick",
      "rotation": 2
    },
    {
      "x": -4,
      "y": 1,
      "z": -2,
      "name": "Rock_Stone_Brick_Ornate",
      "rotation": 2
    },
    {
      "x": -4,
      "y": 2,
      "z": -2,
      "name": "Rock_Stone_Brick",
      "rotation": 2
    },
    {
      "x": -4,
      "y": 3,
      "z": -2,
      "name": "Rock_Stone_Brick",
      "rotation": 2
    },
    {
      "x": -4,
      "y": 4,
      "z": -2,
      "name": "Rock_Stone_Brick",
      "rotation": 2
    },
    {
      "x": -4,
      "y": 5,
      "z": -2,
      "name": "Rock_Stone_Brick",
      "rotation": 2
    },
    {
      "x": -4,
      "y": 6,
      "z": -2,
      "name": "*Furniture_Human_Ruins_Torch_State_Definitions_On",
      "rotation": 1
    },
    {
      "x": -4,
      "y": 3,
      "z": -1,
      "name": "Rock_Stone_Brick_Stairs",
      "rotation": 10
    },
    {
      "x": -4,
      "y": 4,
      "z": -1,
      "name": "Rock_Stone_Brick",
      "rotation": 2
    },
    {
      "x": -4,
      "y": 5,
      "z": -1,
      "name": "Rock_Stone_Brick_Stairs",
      "rotation": 1
    },
    {
      "x": -4,
      "y": 3,
      "z": 0,
      "name": "Rock_Stone_Brick_Stairs",
      "rotation": 8
    },
    {
      "x": -4,
      "y": 4,
      "z": 0,
      "name": "Rock_Stone_Brick",
      "rotation": 2
    },
    {
      "x": -4,
      "y": 5,
      "z": 0,
      "name": "Rock_Stone_Brick_Stairs",
      "rotation": 1
    },
    {
      "x": -4,
      "y": 0,
      "z": 1,
      "name": "Rock_Stone_Brick",
      "rotation": 2
    },
    {
      "x": -4,
      "y": 1,
      "z": 1,
      "name": "Rock_Stone_Brick_Ornate",
      "rotation": 2
    },
    {
      "x": -4,
      "y": 2,
      "z": 1,
      "name": "Rock_Stone_Brick",
      "rotation": 2
    },
    {
      "x": -4,
      "y": 3,
      "z": 1,
      "name": "Rock_Stone_Brick",
      "rotation": 2
    },
    {
      "x": -4,
      "y": 4,
      "z": 1,
      "name": "Rock_Stone_Brick",
      "rotation": 2
    },
    {
      "x": -4,
      "y": 5,
      "z": 1,
      "name": "Rock_Stone_Brick",
      "rotation": 2
    },
    {
      "x": -4,
      "y": 3,
      "z": 2,
      "name": "Rock_Stone_Brick_Stairs",
      "rotation": 10
    },
    {
      "x": -4,
      "y": 4,
      "z": 2,
      "name": "Rock_Stone_Brick",
      "rotation": 2
    },
    {
      "x": -4,
      "y": 5,
      "z": 2,
      "name": "Rock_Stone_Brick_Stairs",
      "rotation": 1
    },
    {
      "x": -4,
      "y": 3,
      "z": 3,
      "name": "Rock_Stone_Brick_Stairs",
      "rotation": 8
    },
    {
      "x": -4,
      "y": 4,
      "z": 3,
      "name": "Rock_Stone_Brick",
      "rotation": 2
    },
    {
      "x": -4,
      "y": 5,
      "z": 3,
      "name": "Rock_Stone_Brick_Stairs",
      "rotation": 1
    },
    {
      "x": -4,
      "y": 0,
      "z": 4,
      "name": "Rock_Stone_Brick",
      "rotation": 2
    },
    {
      "x": -4,
      "y": 1,
      "z": 4,
      "name": "Rock_Stone_Brick_Ornate",
      "rotation": 2
    },
    {
      "x": -4,
      "y": 2,
      "z": 4,
      "name": "Rock_Stone_Brick",
      "rotation": 2
    },
    {
      "x": -4,
      "y": 3,
      "z": 4,
      "name": "Rock_Stone_Brick",
      "rotation": 2
    },
    {
      "x": -4,
      "y": 4,
      "z": 4,
      "name": "Rock_Stone_Brick",
      "rotation": 2
    },
    {
      "x": -4,
      "y": 5,
      "z": 4,
      "name": "Rock_Stone_Brick",
      "rotation": 2
    },
    {
      "x": -4,
      "y": 6,
      "z": 4,
      "name": "*Furniture_Human_Ruins_Torch_State_Definitions_On",
      "rotation": 2
    },
    {
      "x": -3,
      "y": 3,
      "z": -2,
      "name": "Rock_Stone_Brick_Stairs",
      "rotation": 11
    },
    {
      "x": -3,
      "y": 4,
      "z": -2,
      "name": "Rock_Stone_Brick",
      "rotation": 2
    },
    {
      "x": -3,
      "y": 5,
      "z": -2,
      "name": "Rock_Stone_Brick_Stairs",
      "rotation": 2
    },
    {
      "x": -3,
      "y": 4,
      "z": -1,
      "name": "Rock_Stone_Brick",
      "rotation": 2
    },
    {
      "x": -3,
      "y": 4,
      "z": 0,
      "name": "Rock_Stone_Brick",
      "rotation": 2
    },
    {
      "x": -3,
      "y": 0,
      "z": 1,
      "name": "Block_Spawner_Block",
      "components": {
        "Components": {
          "PlacedByInteraction": {
            "WhoPlacedUuid": {
              "$binary": "30E5va+4QA2ISsflEWOC9g==",
              "$type": "04"
            }
          },
          "BlockSpawner": {
            "BlockSpawnerId": "YUNGs_HyDungeons_Skeleton_Dungeon_Crate_Storage"
          }
        }
      },
      "rotation": 1
    },
    {
      "x": -3,
      "y": 4,
      "z": 1,
      "name": "Rock_Stone_Brick",
      "rotation": 2
    },
    {
      "x": -3,
      "y": 4,
      "z": 2,
      "name": "Rock_Stone_Brick",
      "rotation": 2
    },
    {
      "x": -3,
      "y": 4,
      "z": 3,
      "name": "Rock_Stone_Brick",
      "rotation": 2
    },
    {
      "x": -3,
      "y": 3,
      "z": 4,
      "name": "Rock_Stone_Brick_Stairs",
      "rotation": 11
    },
    {
      "x": -3,
      "y": 4,
      "z": 4,
      "name": "Rock_Stone_Brick",
      "rotation": 2
    },
    {
      "x": -3,
      "y": 5,
      "z": 4,
      "name": "Rock_Stone_Brick_Stairs"
    },
    {
      "x": -2,
      "y": 3,
      "z": -2,
      "name": "Rock_Stone_Brick_Stairs",
      "rotation": 9
    },
    {
      "x": -2,
      "y": 4,
      "z": -2,
      "name": "Rock_Stone_Brick",
      "rotation": 2
    },
    {
      "x": -2,
      "y": 5,
      "z": -2,
      "name": "Rock_Stone_Brick_Stairs",
      "rotation": 2
    },
    {
      "x": -2,
      "y": 4,
      "z": -1,
      "name": "Rock_Stone_Brick",
      "rotation": 2
    },
    {
      "x": -2,
      "y": 4,
      "z": 0,
      "name": "Rock_Stone_Brick",
      "rotation": 2
    },
    {
      "x": -2,
      "y": 4,
      "z": 1,
      "name": "Rock_Stone_Brick",
      "rotation": 2
    },
    {
      "x": -2,
      "y": 4,
      "z": 2,
      "name": "Rock_Stone_Brick",
      "rotation": 2
    },
    {
      "x": -2,
      "y": 5,
      "z": 2,
      "name": "Rubble_Stone"
    },
    {
      "x": -2,
      "y": 4,
      "z": 3,
      "name": "Rock_Stone_Brick",
      "rotation": 2
    },
    {
      "x": -2,
      "y": 3,
      "z": 4,
      "name": "Rock_Stone_Brick_Stairs",
      "rotation": 9
    },
    {
      "x": -2,
      "y": 4,
      "z": 4,
      "name": "Rock_Stone_Brick",
      "rotation": 2
    },
    {
      "x": -2,
      "y": 5,
      "z": 4,
      "name": "Rock_Stone_Brick_Stairs"
    },
    {
      "x": -1,
      "y": 4,
      "z": -4,
      "name": "Rock_Stone_Brick",
      "rotation": 2
    },
    {
      "x": -1,
      "y": 5,
      "z": -4,
      "name": "Rock_Stone_Brick",
      "rotation": 2
    },
    {
      "x": -1,
      "y": 4,
      "z": -3,
      "name": "Rock_Stone_Brick",
      "rotation": 2
    },
    {
      "x": -1,
      "y": 5,
      "z": -3,
      "name": "Rock_Stone_Brick",
      "rotation": 2
    },
    {
      "x": -1,
      "y": 0,
      "z": -2,
      "name": "Rock_Stone_Brick",
      "rotation": 2
    },
    {
      "x": -1,
      "y": 1,
      "z": -2,
      "name": "Rock_Stone_Brick_Ornate",
      "rotation": 2
    },
    {
      "x": -1,
      "y": 2,
      "z": -2,
      "name": "Rock_Stone_Brick",
      "rotation": 2
    },
    {
      "x": -1,
      "y": 3,
      "z": -2,
      "name": "Rock_Stone_Brick",
      "rotation": 2
    },
    {
      "x": -1,
      "y": 4,
      "z": -2,
      "name": "Rock_Stone_Brick",
      "rotation": 2
    },
    {
      "x": -1,
      "y": 5,
      "z": -2,
      "name": "Rock_Stone_Brick",
      "rotation": 2
    },
    {
      "x": -1,
      "y": 3,
      "z": -1,
      "name": "Rock_Stone_Brick_Stairs",
      "rotation": 10
    },
    {
      "x": -1,
      "y": 4,
      "z": -1,
      "name": "Rock_Stone_Brick",
      "rotation": 2
    },
    {
      "x": -1,
      "y": 0,
      "z": 0,
      "name": "Block_Spawner_Block",
      "components": {
        "Components": {
          "PlacedByInteraction": {
            "WhoPlacedUuid": {
              "$binary": "30E5va+4QA2ISsflEWOC9g==",
              "$type": "04"
            }
          },
          "BlockSpawner": {
            "BlockSpawnerId": "YUNGs_HyDungeons_Skeleton_Dungeon_Crate_Storage"
          }
        }
      },
      "rotation": 2
    },
    {
      "x": -1,
      "y": 4,
      "z": 0,
      "name": "Rock_Stone_Brick",
      "rotation": 2
    },
    {
      "x": -1,
      "y": 0,
      "z": 1,
      "name": "Furniture_Ancient_Crate",
      "rotation": 3
    },
    {
      "x": -1,
      "y": 1,
      "z": 1,
      "name": "Furniture_Ancient_Crate",
      "rotation": 3
    },
    {
      "x": -1,
      "y": 4,
      "z": 1,
      "name": "Rock_Stone_Brick",
      "rotation": 2
    },
    {
      "x": -1,
      "y": 0,
      "z": 2,
      "name": "Furniture_Ancient_Crate",
      "rotation": 3
    },
    {
      "x": -1,
      "y": 4,
      "z": 2,
      "name": "Rock_Stone_Brick",
      "rotation": 2
    },
    {
      "x": -1,
      "y": 4,
      "z": 3,
      "name": "Rock_Stone_Brick",
      "rotation": 2
    },
    {
      "x": -1,
      "y": 0,
      "z": 4,
      "name": "Rock_Stone_Brick",
      "rotation": 2
    },
    {
      "x": -1,
      "y": 1,
      "z": 4,
      "name": "Rock_Stone_Brick_Ornate"
    },
    {
      "x": -1,
      "y": 2,
      "z": 4,
      "name": "Rock_Stone_Brick",
      "rotation": 2
    },
    {
      "x": -1,
      "y": 3,
      "z": 4,
      "name": "Rock_Stone_Brick",
      "rotation": 2
    },
    {
      "x": -1,
      "y": 4,
      "z": 4,
      "name": "Rock_Stone_Brick",
      "rotation": 2
    },
    {
      "x": -1,
      "y": 5,
      "z": 4,
      "name": "Rock_Stone_Brick",
      "rotation": 2
    },
    {
      "x": -1,
      "y": 4,
      "z": 5,
      "name": "Rock_Stone_Brick",
      "rotation": 2
    },
    {
      "x": -1,
      "y": 5,
      "z": 5,
      "name": "Rock_Stone_Brick",
      "rotation": 2
    },
    {
      "x": -1,
      "y": 4,
      "z": 6,
      "name": "Rock_Stone_Brick",
      "rotation": 2
    },
    {
      "x": -1,
      "y": 5,
      "z": 6,
      "name": "Rock_Stone_Brick",
      "rotation": 2
    },
    {
      "x": 0,
      "y": 5,
      "z": -5,
      "name": "Empty"
    },
    {
      "x": 0,
      "y": 4,
      "z": -4,
      "name": "Rock_Stone_Brick"
    },
    {
      "x": 0,
      "y": 4,
      "z": -3,
      "name": "Rock_Stone_Brick"
    },
    {
      "x": 0,
      "y": 5,
      "z": -3,
      "name": "Rubble_Stone"
    },
    {
      "x": 0,
      "y": 3,
      "z": -2,
      "name": "Rock_Stone_Brick_Stairs",
      "rotation": 11
    },
    {
      "x": 0,
      "y": 4,
      "z": -2,
      "name": "Rock_Stone_Brick"
    },
    {
      "x": 0,
      "y": 3,
      "z": -1,
      "name": "Deco_SpiderWeb",
      "rotation": 11
    },
    {
      "x": 0,
      "y": 4,
      "z": -1,
      "name": "Rock_Stone_Brick"
    },
    {
      "x": 0,
      "y": 0,
      "z": 0,
      "name": "Block_Spawner_Block",
      "components": {
        "Components": {
          "PlacedByInteraction": {
            "WhoPlacedUuid": {
              "$binary": "30E5va+4QA2ISsflEWOC9g==",
              "$type": "04"
            }
          },
          "BlockSpawner": {
            "BlockSpawnerId": "YUNGs_HyDungeons_Skeleton_Dungeon_Crate_Storage"
          }
        }
      },
      "rotation": 2
    },
    {
      "x": 0,
      "y": 4,
      "z": 0,
      "name": "Rock_Stone_Brick"
    },
    {
      "x": 0,
      "y": 0,
      "z": 1,
      "name": "Furniture_Ancient_Crate",
      "rotation": 3
    },
    {
      "x": 0,
      "y": 1,
      "z": 1,
      "name": "Block_Spawner_Block",
      "components": {
        "Components": {
          "PlacedByInteraction": {
            "WhoPlacedUuid": {
              "$binary": "30E5va+4QA2ISsflEWOC9g==",
              "$type": "04"
            }
          },
          "BlockSpawner": {
            "BlockSpawnerId": "YUNGs_HyDungeons_Skeleton_Dungeon_Crate_Storage"
          }
        }
      },
      "rotation": 1
    },
    {
      "x": 0,
      "y": 2,
      "z": 1,
      "name": "Furniture_Ancient_Crate",
      "rotation": 3
    },
    {
      "x": 0,
      "y": 4,
      "z": 1,
      "name": "Rock_Stone_Brick"
    },
    {
      "x": 0,
      "y": 0,
      "z": 2,
      "name": "Block_Spawner_Block",
      "components": {
        "Components": {
          "PlacedByInteraction": {
            "WhoPlacedUuid": {
              "$binary": "30E5va+4QA2ISsflEWOC9g==",
              "$type": "04"
            }
          },
          "BlockSpawner": {
            "BlockSpawnerId": "YUNGs_HyDungeons_Skeleton_Dungeon_Crate_Storage"
          }
        }
      }
    },
    {
      "x": 0,
      "y": 1,
      "z": 2,
      "name": "Block_Spawner_Block",
      "components": {
        "Components": {
          "PlacedByInteraction": {
            "WhoPlacedUuid": {
              "$binary": "30E5va+4QA2ISsflEWOC9g==",
              "$type": "04"
            }
          },
          "BlockSpawner": {
            "BlockSpawnerId": "YUNGs_HyDungeons_Skeleton_Dungeon_Crate_Storage"
          }
        }
      }
    },
    {
      "x": 0,
      "y": 4,
      "z": 2,
      "name": "Rock_Stone_Brick"
    },
    {
      "x": 0,
      "y": 4,
      "z": 3,
      "name": "Rock_Stone_Brick"
    },
    {
      "x": 0,
      "y": 3,
      "z": 4,
      "name": "Rock_Stone_Brick_Stairs",
      "rotation": 11
    },
    {
      "x": 0,
      "y": 4,
      "z": 4,
      "name": "Rock_Stone_Brick"
    },
    {
      "x": 0,
      "y": 4,
      "z": 5,
      "name": "Rock_Stone_Brick"
    },
    {
      "x": 0,
      "y": 4,
      "z": 6,
      "name": "Rock_Stone_Brick"
    },
    {
      "x": 1,
      "y": 4,
      "z": -4,
      "name": "Rock_Stone_Brick"
    },
    {
      "x": 1,
      "y": 4,
      "z": -3,
      "name": "Rock_Stone_Brick"
    },
    {
      "x": 1,
      "y": 3,
      "z": -2,
      "name": "Rock_Stone_Brick_Stairs",
      "rotation": 9
    },
    {
      "x": 1,
      "y": 4,
      "z": -2,
      "name": "Rock_Stone_Brick"
    },
    {
      "x": 1,
      "y": 4,
      "z": -1,
      "name": "Rock_Stone_Brick"
    },
    {
      "x": 1,
      "y": 4,
      "z": 0,
      "name": "Rock_Stone_Brick"
    },
    {
      "x": 1,
      "y": 0,
      "z": 1,
      "name": "Furniture_Ancient_Crate",
      "rotation": 3
    },
    {
      "x": 1,
      "y": 4,
      "z": 1,
      "name": "Rock_Stone_Brick"
    },
    {
      "x": 1,
      "y": 4,
      "z": 2,
      "name": "Rock_Stone_Brick"
    },
    {
      "x": 1,
      "y": 4,
      "z": 3,
      "name": "Rock_Stone_Brick"
    },
    {
      "x": 1,
      "y": 3,
      "z": 4,
      "name": "Rock_Stone_Brick_Stairs",
      "rotation": 9
    },
    {
      "x": 1,
      "y": 4,
      "z": 4,
      "name": "Rock_Stone_Brick"
    },
    {
      "x": 1,
      "y": 4,
      "z": 5,
      "name": "Rock_Stone_Brick"
    },
    {
      "x": 1,
      "y": 4,
      "z": 6,
      "name": "Rock_Stone_Brick"
    },
    {
      "x": 2,
      "y": 4,
      "z": -4,
      "name": "Rock_Stone_Brick"
    },
    {
      "x": 2,
      "y": 5,
      "z": -4,
      "name": "Rock_Stone_Brick"
    },
    {
      "x": 2,
      "y": 4,
      "z": -3,
      "name": "Rock_Stone_Brick"
    },
    {
      "x": 2,
      "y": 5,
      "z": -3,
      "name": "Rock_Stone_Brick"
    },
    {
      "x": 2,
      "y": 0,
      "z": -2,
      "name": "Rock_Stone_Brick"
    },
    {
      "x": 2,
      "y": 1,
      "z": -2,
      "name": "Rock_Stone_Brick"
    },
    {
      "x": 2,
      "y": 2,
      "z": -2,
      "name": "Rock_Stone_Brick"
    },
    {
      "x": 2,
      "y": 3,
      "z": -2,
      "name": "Rock_Stone_Brick"
    },
    {
      "x": 2,
      "y": 4,
      "z": -2,
      "name": "Rock_Stone_Brick"
    },
    {
      "x": 2,
      "y": 5,
      "z": -2,
      "name": "Rock_Stone_Brick"
    },
    {
      "x": 2,
      "y": 4,
      "z": -1,
      "name": "Rock_Stone_Brick"
    },
    {
      "x": 2,
      "y": 4,
      "z": 0,
      "name": "Rock_Stone_Brick"
    },
    {
      "x": 2,
      "y": 4,
      "z": 1,
      "name": "Rock_Stone_Brick"
    },
    {
      "x": 2,
      "y": 4,
      "z": 2,
      "name": "Rock_Stone_Brick"
    },
    {
      "x": 2,
      "y": 0,
      "z": 3,
      "name": "Block_Spawner_Block",
      "components": {
        "Components": {
          "PlacedByInteraction": {
            "WhoPlacedUuid": {
              "$binary": "30E5va+4QA2ISsflEWOC9g==",
              "$type": "04"
            }
          },
          "BlockSpawner": {
            "BlockSpawnerId": "YUNGs_HyDungeons_Skeleton_Dungeon_Crate_Storage"
          }
        }
      },
      "rotation": 2
    },
    {
      "x": 2,
      "y": 4,
      "z": 3,
      "name": "Rock_Stone_Brick"
    },
    {
      "x": 2,
      "y": 0,
      "z": 4,
      "name": "Rock_Stone_Brick"
    },
    {
      "x": 2,
      "y": 1,
      "z": 4,
      "name": "Rock_Stone_Brick_Ornate"
    },
    {
      "x": 2,
      "y": 2,
      "z": 4,
      "name": "Rock_Stone_Brick"
    },
    {
      "x": 2,
      "y": 3,
      "z": 4,
      "name": "Rock_Stone_Brick"
    },
    {
      "x": 2,
      "y": 4,
      "z": 4,
      "name": "Rock_Stone_Brick"
    },
    {
      "x": 2,
      "y": 5,
      "z": 4,
      "name": "Rock_Stone_Brick"
    },
    {
      "x": 2,
      "y": 4,
      "z": 5,
      "name": "Rock_Stone_Brick"
    },
    {
      "x": 2,
      "y": 5,
      "z": 5,
      "name": "Rock_Stone_Brick"
    },
    {
      "x": 2,
      "y": 4,
      "z": 6,
      "name": "Rock_Stone_Brick"
    },
    {
      "x": 2,
      "y": 5,
      "z": 6,
      "name": "Rock_Stone_Brick"
    },
    {
      "x": 3,
      "y": 3,
      "z": -2,
      "name": "Rock_Stone_Brick_Stairs",
      "rotation": 11
    },
    {
      "x": 3,
      "y": 4,
      "z": -2,
      "name": "Rock_Stone_Brick"
    },
    {
      "x": 3,
      "y": 5,
      "z": -2,
      "name": "Rock_Stone_Brick_Stairs",
      "rotation": 2
    },
    {
      "x": 3,
      "y": 4,
      "z": -1,
      "name": "Rock_Stone_Brick"
    },
    {
      "x": 3,
      "y": 4,
      "z": 0,
      "name": "Rock_Stone_Brick"
    },
    {
      "x": 3,
      "y": 5,
      "z": 0,
      "name": "Deco_Bone_Pile"
    },
    {
      "x": 3,
      "y": 4,
      "z": 1,
      "name": "Rock_Stone_Brick"
    },
    {
      "x": 3,
      "y": 4,
      "z": 2,
      "name": "Rock_Stone_Brick"
    },
    {
      "x": 3,
      "y": 4,
      "z": 3,
      "name": "Rock_Stone_Brick"
    },
    {
      "x": 3,
      "y": 3,
      "z": 4,
      "name": "Rock_Stone_Brick_Stairs",
      "rotation": 11
    },
    {
      "x": 3,
      "y": 4,
      "z": 4,
      "name": "Rock_Stone_Brick"
    },
    {
      "x": 3,
      "y": 5,
      "z": 4,
      "name": "Rock_Stone_Brick_Stairs"
    },
    {
      "x": 4,
      "y": 3,
      "z": -2,
      "name": "Rock_Stone_Brick_Stairs",
      "rotation": 9
    },
    {
      "x": 4,
      "y": 4,
      "z": -2,
      "name": "Rock_Stone_Brick"
    },
    {
      "x": 4,
      "y": 5,
      "z": -2,
      "name": "Rock_Stone_Brick_Stairs",
      "rotation": 2
    },
    {
      "x": 4,
      "y": 4,
      "z": -1,
      "name": "Rock_Stone_Brick"
    },
    {
      "x": 4,
      "y": 4,
      "z": 0,
      "name": "Rock_Stone_Brick"
    },
    {
      "x": 4,
      "y": 4,
      "z": 1,
      "name": "Rock_Stone_Brick"
    },
    {
      "x": 4,
      "y": 4,
      "z": 2,
      "name": "Rock_Stone_Brick"
    },
    {
      "x": 4,
      "y": 5,
      "z": 2,
      "name": "Deco_Book_Pile_Small",
      "rotation": 3
    },
    {
      "x": 4,
      "y": 3,
      "z": 3,
      "name": "Deco_SpiderWeb",
      "rotation": 8
    },
    {
      "x": 4,
      "y": 4,
      "z": 3,
      "name": "Rock_Stone_Brick"
    },
    {
      "x": 4,
      "y": 5,
      "z": 3,
      "name": "Deco_Pot_Clay_Broken"
    },
    {
      "x": 4,
      "y": 3,
      "z": 4,
      "name": "Rock_Stone_Brick_Stairs",
      "rotation": 9
    },
    {
      "x": 4,
      "y": 4,
      "z": 4,
      "name": "Rock_Stone_Brick"
    },
    {
      "x": 4,
      "y": 5,
      "z": 4,
      "name": "Rock_Stone_Brick_Stairs"
    },
    {
      "x": 5,
      "y": 0,
      "z": -2,
      "name": "Rock_Stone_Brick"
    },
    {
      "x": 5,
      "y": 1,
      "z": -2,
      "name": "Rock_Stone_Brick_Ornate"
    },
    {
      "x": 5,
      "y": 2,
      "z": -2,
      "name": "Rock_Stone_Brick"
    },
    {
      "x": 5,
      "y": 3,
      "z": -2,
      "name": "Rock_Stone_Brick"
    },
    {
      "x": 5,
      "y": 4,
      "z": -2,
      "name": "Rock_Stone_Brick"
    },
    {
      "x": 5,
      "y": 5,
      "z": -2,
      "name": "Rock_Stone_Brick"
    },
    {
      "x": 5,
      "y": 6,
      "z": -2,
      "name": "*Furniture_Human_Ruins_Torch_State_Definitions_Off"
    },
    {
      "x": 5,
      "y": 3,
      "z": -1,
      "name": "Rock_Stone_Brick_Stairs",
      "rotation": 10
    },
    {
      "x": 5,
      "y": 4,
      "z": -1,
      "name": "Rock_Stone_Brick"
    },
    {
      "x": 5,
      "y": 5,
      "z": -1,
      "name": "Rock_Stone_Brick_Stairs",
      "rotation": 3
    },
    {
      "x": 5,
      "y": 3,
      "z": 0,
      "name": "Rock_Stone_Brick_Stairs",
      "rotation": 8
    },
    {
      "x": 5,
      "y": 4,
      "z": 0,
      "name": "Rock_Stone_Brick"
    },
    {
      "x": 5,
      "y": 5,
      "z": 0,
      "name": "Rock_Stone_Brick_Stairs",
      "rotation": 3
    },
    {
      "x": 5,
      "y": 0,
      "z": 1,
      "name": "Rock_Stone_Brick"
    },
    {
      "x": 5,
      "y": 1,
      "z": 1,
      "name": "Rock_Stone_Brick_Ornate"
    },
    {
      "x": 5,
      "y": 2,
      "z": 1,
      "name": "Rock_Stone_Brick"
    },
    {
      "x": 5,
      "y": 3,
      "z": 1,
      "name": "Rock_Stone_Brick"
    },
    {
      "x": 5,
      "y": 4,
      "z": 1,
      "name": "Rock_Stone_Brick"
    },
    {
      "x": 5,
      "y": 5,
      "z": 1,
      "name": "Rock_Stone_Brick"
    },
    {
      "x": 5,
      "y": 3,
      "z": 2,
      "name": "Rock_Stone_Brick_Stairs",
      "rotation": 10
    },
    {
      "x": 5,
      "y": 4,
      "z": 2,
      "name": "Rock_Stone_Brick"
    },
    {
      "x": 5,
      "y": 5,
      "z": 2,
      "name": "Rock_Stone_Brick_Stairs",
      "rotation": 3
    },
    {
      "x": 5,
      "y": 3,
      "z": 3,
      "name": "Rock_Stone_Brick_Stairs",
      "rotation": 8
    },
    {
      "x": 5,
      "y": 4,
      "z": 3,
      "name": "Rock_Stone_Brick"
    },
    {
      "x": 5,
      "y": 5,
      "z": 3,
      "name": "Rock_Stone_Brick_Stairs",
      "rotation": 3
    },
    {
      "x": 5,
      "y": 0,
      "z": 4,
      "name": "Rock_Stone_Brick"
    },
    {
      "x": 5,
      "y": 1,
      "z": 4,
      "name": "Rock_Stone_Brick_Ornate"
    },
    {
      "x": 5,
      "y": 2,
      "z": 4,
      "name": "Rock_Stone_Brick"
    },
    {
      "x": 5,
      "y": 3,
      "z": 4,
      "name": "Rock_Stone_Brick"
    },
    {
      "x": 5,
      "y": 4,
      "z": 4,
      "name": "Rock_Stone_Brick"
    },
    {
      "x": 5,
      "y": 5,
      "z": 4,
      "name": "Rock_Stone_Brick"
    }
  ]
}