{
  "version": 8,
  "blockIdVersion": 10,
  "anchorX": -35,
  "anchorY": 1,
  "anchorZ": -28,
  "blocks": [
    {
      "x": -35,
      "y": 1,
      "z": -28,
      "name": "Rock_Stone_Brick",
      "rotation": 2
    },
    {
      "x": -35,
      "y": 2,
      "z": -28,
      "name": "Rock_Stone_Brick_Ornate"
    },
    {
      "x": -35,
      "y": 3,
      "z": -28,
      "name": "Rock_Stone_Brick",
      "rotation": 2
    },
    {
      "x": -35,
      "y": 4,
      "z": -28,
      "name": "Rock_Stone_Brick",
      "rotation": 2
    },
    {
      "x": -35,
      "y": 5,
      "z": -28,
      "name": "Rock_Stone_Brick",
      "rotation": 2
    },
    {
      "x": -35,
      "y": 6,
      "z": -28,
      "name": "Rock_Stone_Brick",
      "rotation": 2
    },
    {
      "x": -35,
      "y": 1,
      "z": -27,
      "name": "Rock_Stone_Brick",
      "rotation": 2
    },
    {
      "x": -35,
      "y": 2,
      "z": -27,
      "name": "Rock_Stone_Brick",
      "rotation": 2
    },
    {
      "x": -35,
      "y": 3,
      "z": -27,
      "name": "Rock_Stone_Brick",
      "rotation": 2
    },
    {
      "x": -35,
      "y": 4,
      "z": -27,
      "name": "Rock_Stone_Brick",
      "rotation": 2
    },
    {
      "x": -35,
      "y": 5,
      "z": -27,
      "name": "Rock_Stone_Brick",
      "rotation": 2
    },
    {
      "x": -35,
      "y": 6,
      "z": -27,
      "name": "Rock_Stone_Brick",
      "rotation": 2
    },
    {
      "x": -35,
      "y": 1,
      "z": -26,
      "name": "Rock_Stone_Brick",
      "rotation": 2
    },
    {
      "x": -35,
      "y": 2,
      "z": -26,
      "name": "Rock_Stone_Brick",
      "rotation": 2
    },
    {
      "x": -35,
      "y": 3,
      "z": -26,
      "name": "Rock_Stone_Brick",
      "rotation": 2
    },
    {
      "x": -35,
      "y": 4,
      "z": -26,
      "name": "Rock_Stone_Brick",
      "rotation": 2
    },
    {
      "x": -35,
      "y": 5,
      "z": -26,
      "name": "Rock_Stone_Brick",
      "rotation": 2
    },
    {
      "x": -35,
      "y": 6,
      "z": -26,
      "name": "Rock_Stone_Brick",
      "rotation": 2
    },
    {
      "x": -35,
      "y": 1,
      "z": -25,
      "name": "Rock_Stone_Brick",
      "rotation": 2
    },
    {
      "x": -35,
      "y": 2,
      "z": -25,
      "name": "Rock_Stone_Brick",
      "rotation": 2
    },
    {
      "x": -35,
      "y": 3,
      "z": -25,
      "name": "Rock_Stone_Brick",
      "rotation": 2
    },
    {
      "x": -35,
      "y": 4,
      "z": -25,
      "name": "Rock_Stone_Brick",
      "rotation": 2
    },
    {
      "x": -35,
      "y": 5,
      "z": -25,
      "name": "Rock_Stone_Brick",
      "rotation": 2
    },
    {
      "x": -35,
      "y": 6,
      "z": -25,
      "name": "Rock_Stone_Brick",
      "rotation": 2
    },
    {
      "x": -35,
      "y": 1,
      "z": -24,
      "name": "Rock_Stone_Brick",
      "rotation": 2
    },
    {
      "x": -35,
      "y": 2,
      "z": -24,
      "name": "Rock_Stone_Brick",
      "rotation": 2
    },
    {
      "x": -35,
      "y": 3,
      "z": -24,
      "name": "Rock_Stone_Brick",
      "rotation": 2
    },
    {
      "x": -35,
      "y": 4,
      "z": -24,
      "name": "Rock_Stone_Brick",
      "rotation": 2
    },
    {
      "x": -35,
      "y": 5,
      "z": -24,
      "name": "Rock_Stone_Brick",
      "rotation": 2
    },
    {
      "x": -35,
      "y": 6,
      "z": -24,
      "name": "Rock_Stone_Brick",
      "rotation": 2
    },
    {
      "x": -35,
      "y": 1,
      "z": -23,
      "name": "Rock_Stone_Brick",
      "rotation": 2
    },
    {
      "x": -35,
      "y": 2,
      "z": -23,
      "name": "Rock_Stone_Brick",
      "rotation": 2
    },
    {
      "x": -35,
      "y": 3,
      "z": -23,
      "name": "Rock_Stone_Brick",
      "rotation": 2
    },
    {
      "x": -35,
      "y": 4,
      "z": -23,
      "name": "Rock_Stone_Brick",
      "rotation": 2
    },
    {
      "x": -35,
      "y": 5,
      "z": -23,
      "name": "Rock_Stone_Brick",
      "rotation": 2
    },
    {
      "x": -35,
      "y": 6,
      "z": -23,
      "name": "Rock_Stone_Brick",
      "rotation": 2
    },
    {
      "x": -35,
      "y": 1,
      "z": -22,
      "name": "Rock_Stone_Brick",
      "rotation": 2
    },
    {
      "x": -35,
      "y": 2,
      "z": -22,
      "name": "Rock_Stone_Brick",
      "rotation": 2
    },
    {
      "x": -35,
      "y": 3,
      "z": -22,
      "name": "Rock_Stone_Brick",
      "rotation": 2
    },
    {
      "x": -35,
      "y": 4,
      "z": -22,
      "name": "Rock_Stone_Brick",
      "rotation": 2
    },
    {
      "x": -35,
      "y": 5,
      "z": -22,
      "name": "Rock_Stone_Brick",
      "rotation": 2
    },
    {
      "x": -35,
      "y": 6,
      "z": -22,
      "name": "Rock_Stone_Brick",
      "rotation": 2
    },
    {
      "x": -35,
      "y": 1,
      "z": -21,
      "name": "Rock_Stone_Brick",
      "rotation": 2
    },
    {
      "x": -35,
      "y": 2,
      "z": -21,
      "name": "Rock_Stone_Brick",
      "rotation": 2
    },
    {
      "x": -35,
      "y": 3,
      "z": -21,
      "name": "Rock_Stone_Brick",
      "rotation": 2
    },
    {
      "x": -35,
      "y": 4,
      "z": -21,
      "name": "Rock_Stone_Brick",
      "rotation": 2
    },
    {
      "x": -35,
      "y": 5,
      "z": -21,
      "name": "Rock_Stone_Brick",
      "rotation": 2
    },
    {
      "x": -35,
      "y": 6,
      "z": -21,
      "name": "Rock_Stone_Brick",
      "rotation": 2
    },
    {
      "x": -35,
      "y": 1,
      "z": -20,
      "name": "Rock_Stone_Brick",
      "rotation": 2
    },
    {
      "x": -35,
      "y": 2,
      "z": -20,
      "name": "Rock_Stone_Brick",
      "rotation": 2
    },
    {
      "x": -35,
      "y": 3,
      "z": -20,
      "name": "Rock_Stone_Brick",
      "rotation": 2
    },
    {
      "x": -35,
      "y": 4,
      "z": -20,
      "name": "Rock_Stone_Brick",
      "rotation": 2
    },
    {
      "x": -35,
      "y": 5,
      "z": -20,
      "name": "Rock_Stone_Brick",
      "rotation": 2
    },
    {
      "x": -35,
      "y": 6,
      "z": -20,
      "name": "Rock_Stone_Brick",
      "rotation": 2
    },
    {
      "x": -35,
      "y": 1,
      "z": -19,
      "name": "Rock_Stone_Brick",
      "rotation": 2
    },
    {
      "x": -35,
      "y": 2,
      "z": -19,
      "name": "Rock_Stone_Brick",
      "rotation": 2
    },
    {
      "x": -35,
      "y": 3,
      "z": -19,
      "name": "Rock_Stone_Brick",
      "rotation": 2
    },
    {
      "x": -35,
      "y": 4,
      "z": -19,
      "name": "Rock_Stone_Brick",
      "rotation": 2
    },
    {
      "x": -35,
      "y": 5,
      "z": -19,
      "name": "Rock_Stone_Brick",
      "rotation": 2
    },
    {
      "x": -35,
      "y": 6,
      "z": -19,
      "name": "Rock_Stone_Brick",
      "rotation": 2
    },
    {
      "x": -34,
      "y": 4,
      "z": -28,
      "name": "Rock_Stone_Brick_Stairs",
      "rotation": 11
    },
    {
      "x": -34,
      "y": 5,
      "z": -28,
      "name": "Rock_Stone_Brick",
      "rotation": 2
    },
    {
      "x": -34,
      "y": 6,
      "z": -28,
      "name": "Rock_Stone_Brick_Stairs",
      "rotation": 2
    },
    {
      "x": -34,
      "y": 5,
      "z": -27,
      "name": "Rock_Stone_Brick",
      "rotation": 2
    },
    {
      "x": -34,
      "y": 5,
      "z": -26,
      "name": "Rock_Stone_Brick",
      "rotation": 2
    },
    {
      "x": -34,
      "y": 5,
      "z": -25,
      "name": "Rock_Stone_Brick",
      "rotation": 2
    },
    {
      "x": -34,
      "y": 5,
      "z": -24,
      "name": "Rock_Stone_Brick",
      "rotation": 2
    },
    {
      "x": -34,
      "y": 5,
      "z": -23,
      "name": "Rock_Stone_Brick",
      "rotation": 2
    },
    {
      "x": -34,
      "y": 5,
      "z": -22,
      "name": "Rock_Stone_Brick",
      "rotation": 2
    },
    {
      "x": -34,
      "y": 6,
      "z": -22,
      "name": "Deco_Bucket"
    },
    {
      "x": -34,
      "y": 5,
      "z": -21,
      "name": "Rock_Stone_Brick",
      "rotation": 2
    },
    {
      "x": -34,
      "y": 1,
      "z": -20,
      "name": "Block_Spawner_Block",
      "components": {
        "Components": {
          "PlacedByInteraction": {
            "WhoPlacedUuid": {
              "$binary": "30E5va+4QA2ISsflEWOC9g==",
              "$type": "04"
            }
          },
          "BlockSpawner": {
            "BlockSpawnerId": "YUNGs_HyDungeons_Skeleton_Dungeon_Crate"
          }
        }
      },
      "rotation": 2
    },
    {
      "x": -34,
      "y": 5,
      "z": -20,
      "name": "Rock_Stone_Brick",
      "rotation": 2
    },
    {
      "x": -34,
      "y": 1,
      "z": -19,
      "name": "Rock_Stone_Brick",
      "rotation": 2
    },
    {
      "x": -34,
      "y": 2,
      "z": -19,
      "name": "Rock_Stone_Brick",
      "rotation": 2
    },
    {
      "x": -34,
      "y": 3,
      "z": -19,
      "name": "Rock_Stone_Brick",
      "rotation": 2
    },
    {
      "x": -34,
      "y": 4,
      "z": -19,
      "name": "Rock_Stone_Brick",
      "rotation": 2
    },
    {
      "x": -34,
      "y": 5,
      "z": -19,
      "name": "Rock_Stone_Brick",
      "rotation": 2
    },
    {
      "x": -34,
      "y": 6,
      "z": -19,
      "name": "Rock_Stone_Brick",
      "rotation": 2
    },
    {
      "x": -33,
      "y": 4,
      "z": -28,
      "name": "Rock_Stone_Brick_Stairs",
      "rotation": 9
    },
    {
      "x": -33,
      "y": 5,
      "z": -28,
      "name": "Rock_Stone_Brick",
      "rotation": 2
    },
    {
      "x": -33,
      "y": 6,
      "z": -28,
      "name": "Rock_Stone_Brick_Stairs",
      "rotation": 2
    },
    {
      "x": -33,
      "y": 5,
      "z": -27,
      "name": "Rock_Stone_Brick",
      "rotation": 2
    },
    {
      "x": -33,
      "y": 5,
      "z": -26,
      "name": "Rock_Stone_Brick",
      "rotation": 2
    },
    {
      "x": -33,
      "y": 6,
      "z": -26,
      "name": "Deco_Bone_Pile"
    },
    {
      "x": -33,
      "y": 1,
      "z": -25,
      "name": "Deco_Bone_Pile"
    },
    {
      "x": -33,
      "y": 5,
      "z": -25,
      "name": "Rock_Stone_Brick",
      "rotation": 2
    },
    {
      "x": -33,
      "y": 5,
      "z": -24,
      "name": "Rock_Stone_Brick",
      "rotation": 2
    },
    {
      "x": -33,
      "y": 1,
      "z": -23,
      "name": "Rubble_Stone"
    },
    {
      "x": -33,
      "y": 5,
      "z": -23,
      "name": "Rock_Stone_Brick",
      "rotation": 2
    },
    {
      "x": -33,
      "y": 5,
      "z": -22,
      "name": "Rock_Stone_Brick",
      "rotation": 2
    },
    {
      "x": -33,
      "y": 5,
      "z": -21,
      "name": "Rock_Stone_Brick",
      "rotation": 2
    },
    {
      "x": -33,
      "y": 4,
      "z": -20,
      "name": "Deco_SpiderWeb",
      "rotation": 8
    },
    {
      "x": -33,
      "y": 5,
      "z": -20,
      "name": "Rock_Stone_Brick",
      "rotation": 2
    },
    {
      "x": -33,
      "y": 1,
      "z": -19,
      "name": "Rock_Stone_Brick",
      "rotation": 2
    },
    {
      "x": -33,
      "y": 2,
      "z": -19,
      "name": "Rock_Stone_Brick",
      "rotation": 2
    },
    {
      "x": -33,
      "y": 3,
      "z": -19,
      "name": "Rock_Stone_Brick",
      "rotation": 2
    },
    {
      "x": -33,
      "y": 4,
      "z": -19,
      "name": "Rock_Stone_Brick",
      "rotation": 2
    },
    {
      "x": -33,
      "y": 5,
      "z": -19,
      "name": "Rock_Stone_Brick",
      "rotation": 2
    },
    {
      "x": -33,
      "y": 6,
      "z": -19,
      "name": "Rock_Stone_Brick",
      "rotation": 2
    },
    {
      "x": -32,
      "y": 1,
      "z": -28,
      "name": "Rock_Stone_Brick",
      "rotation": 2
    },
    {
      "x": -32,
      "y": 2,
      "z": -28,
      "name": "Rock_Stone_Brick_Ornate"
    },
    {
      "x": -32,
      "y": 3,
      "z": -28,
      "name": "Rock_Stone_Brick",
      "rotation": 2
    },
    {
      "x": -32,
      "y": 4,
      "z": -28,
      "name": "Rock_Stone_Brick",
      "rotation": 2
    },
    {
      "x": -32,
      "y": 5,
      "z": -28,
      "name": "Rock_Stone_Brick",
      "rotation": 2
    },
    {
      "x": -32,
      "y": 6,
      "z": -28,
      "name": "Rock_Stone_Brick",
      "rotation": 2
    },
    {
      "x": -32,
      "y": 5,
      "z": -27,
      "name": "Rock_Stone_Brick",
      "rotation": 2
    },
    {
      "x": -32,
      "y": 5,
      "z": -26,
      "name": "Rock_Stone_Brick",
      "rotation": 2
    },
    {
      "x": -32,
      "y": 5,
      "z": -25,
      "name": "Rock_Stone_Brick",
      "rotation": 2
    },
    {
      "x": -32,
      "y": 6,
      "z": -25,
      "name": "Deco_Bone_Skulls"
    },
    {
      "x": -32,
      "y": 5,
      "z": -24,
      "name": "Rock_Stone_Brick",
      "rotation": 2
    },
    {
      "x": -32,
      "y": 1,
      "z": -23,
      "name": "Furniture_Human_Ruins_Coffin",
      "filler": 992,
      "rotation": 1
    },
    {
      "x": -32,
      "y": 5,
      "z": -23,
      "name": "Rock_Stone_Brick",
      "rotation": 2
    },
    {
      "x": -32,
      "y": 1,
      "z": -22,
      "name": "Furniture_Human_Ruins_Coffin",
      "rotation": 1
    },
    {
      "x": -32,
      "y": 5,
      "z": -22,
      "name": "Rock_Stone_Brick",
      "rotation": 2
    },
    {
      "x": -32,
      "y": 5,
      "z": -21,
      "name": "Rock_Stone_Brick",
      "rotation": 2
    },
    {
      "x": -32,
      "y": 5,
      "z": -20,
      "name": "Rock_Stone_Brick",
      "rotation": 2
    },
    {
      "x": -32,
      "y": 6,
      "z": -20,
      "name": "Block_Spawner_Block",
      "components": {
        "Components": {
          "PlacedByInteraction": {
            "WhoPlacedUuid": {
              "$binary": "30E5va+4QA2ISsflEWOC9g==",
              "$type": "04"
            }
          },
          "BlockSpawner": {
            "BlockSpawnerId": "YUNGs_HyDungeons_Skeleton_Dungeon_Pot"
          }
        }
      },
      "rotation": 2
    },
    {
      "x": -32,
      "y": 1,
      "z": -19,
      "name": "Rock_Stone_Brick",
      "rotation": 2
    },
    {
      "x": -32,
      "y": 2,
      "z": -19,
      "name": "Rock_Stone_Brick",
      "rotation": 2
    },
    {
      "x": -32,
      "y": 3,
      "z": -19,
      "name": "Rock_Stone_Brick",
      "rotation": 2
    },
    {
      "x": -32,
      "y": 4,
      "z": -19,
      "name": "Rock_Stone_Brick",
      "rotation": 2
    },
    {
      "x": -32,
      "y": 5,
      "z": -19,
      "name": "Rock_Stone_Brick",
      "rotation": 2
    },
    {
      "x": -32,
      "y": 6,
      "z": -19,
      "name": "Rock_Stone_Brick",
      "rotation": 2
    },
    {
      "x": -31,
      "y": 1,
      "z": -28,
      "name": "Rubble_Stone"
    },
    {
      "x": -31,
      "y": 3,
      "z": -28,
      "name": "Rock_Stone_Brick",
      "rotation": 2
    },
    {
      "x": -31,
      "y": 4,
      "z": -28,
      "name": "Rock_Stone_Brick",
      "rotation": 2
    },
    {
      "x": -31,
      "y": 5,
      "z": -28,
      "name": "Rock_Stone_Brick",
      "rotation": 2
    },
    {
      "x": -31,
      "y": 5,
      "z": -27,
      "name": "Rock_Stone_Brick",
      "rotation": 2
    },
    {
      "x": -31,
      "y": 5,
      "z": -26,
      "name": "Rock_Stone_Brick",
      "rotation": 2
    },
    {
      "x": -31,
      "y": 5,
      "z": -25,
      "name": "Rock_Stone_Brick",
      "rotation": 2
    },
    {
      "x": -31,
      "y": 5,
      "z": -24,
      "name": "Rock_Stone_Brick",
      "rotation": 2
    },
    {
      "x": -31,
      "y": 5,
      "z": -23,
      "name": "Rock_Stone_Brick",
      "rotation": 2
    },
    {
      "x": -31,
      "y": 5,
      "z": -22,
      "name": "Rock_Stone_Brick",
      "rotation": 2
    },
    {
      "x": -31,
      "y": 1,
      "z": -21,
      "name": "Deco_Bone_Pile"
    },
    {
      "x": -31,
      "y": 5,
      "z": -21,
      "name": "Rock_Stone_Brick",
      "rotation": 2
    },
    {
      "x": -31,
      "y": 5,
      "z": -20,
      "name": "Rock_Stone_Brick",
      "rotation": 2
    },
    {
      "x": -31,
      "y": 1,
      "z": -19,
      "name": "Rock_Stone_Brick",
      "rotation": 2
    },
    {
      "x": -31,
      "y": 2,
      "z": -19,
      "name": "Rock_Stone_Brick",
      "rotation": 2
    },
    {
      "x": -31,
      "y": 3,
      "z": -19,
      "name": "Rock_Stone_Brick",
      "rotation": 2
    },
    {
      "x": -31,
      "y": 4,
      "z": -19,
      "name": "Rock_Stone_Brick",
      "rotation": 2
    },
    {
      "x": -31,
      "y": 5,
      "z": -19,
      "name": "Rock_Stone_Brick",
      "rotation": 2
    },
    {
      "x": -31,
      "y": 6,
      "z": -19,
      "name": "Rock_Stone_Brick",
      "rotation": 2
    },
    {
      "x": -30,
      "y": 1,
      "z": -28,
      "name": "Rock_Stone_Brick",
      "rotation": 2
    },
    {
      "x": -30,
      "y": 2,
      "z": -28,
      "name": "Rubble_Stone_Medium"
    },
    {
      "x": -30,
      "y": 3,
      "z": -28,
      "name": "Rock_Stone_Brick",
      "rotation": 2
    },
    {
      "x": -30,
      "y": 4,
      "z": -28,
      "name": "Rock_Stone_Brick",
      "rotation": 2
    },
    {
      "x": -30,
      "y": 5,
      "z": -28,
      "name": "Rock_Stone_Brick",
      "rotation": 2
    },
    {
      "x": -30,
      "y": 5,
      "z": -27,
      "name": "Rock_Stone_Brick",
      "rotation": 2
    },
    {
      "x": -30,
      "y": 5,
      "z": -26,
      "name": "Rock_Stone_Brick",
      "rotation": 2
    },
    {
      "x": -30,
      "y": 5,
      "z": -25,
      "name": "Rock_Stone_Brick",
      "rotation": 2
    },
    {
      "x": -30,
      "y": 5,
      "z": -24,
      "name": "Rock_Stone_Brick",
      "rotation": 2
    },
    {
      "x": -30,
      "y": 5,
      "z": -23,
      "name": "Rock_Stone_Brick",
      "rotation": 2
    },
    {
      "x": -30,
      "y": 5,
      "z": -22,
      "name": "Rock_Stone_Brick",
      "rotation": 2
    },
    {
      "x": -30,
      "y": 5,
      "z": -21,
      "name": "Rock_Stone_Brick",
      "rotation": 2
    },
    {
      "x": -30,
      "y": 5,
      "z": -20,
      "name": "Rock_Stone_Brick",
      "rotation": 2
    },
    {
      "x": -30,
      "y": 1,
      "z": -19,
      "name": "Rock_Stone_Brick",
      "rotation": 2
    },
    {
      "x": -30,
      "y": 2,
      "z": -19,
      "name": "Rock_Stone_Brick",
      "rotation": 2
    },
    {
      "x": -30,
      "y": 3,
      "z": -19,
      "name": "Rock_Stone_Brick",
      "rotation": 2
    },
    {
      "x": -30,
      "y": 4,
      "z": -19,
      "name": "Rock_Stone_Brick",
      "rotation": 2
    },
    {
      "x": -30,
      "y": 5,
      "z": -19,
      "name": "Rock_Stone_Brick",
      "rotation": 2
    },
    {
      "x": -30,
      "y": 6,
      "z": -19,
      "name": "Rock_Stone_Brick",
      "rotation": 2
    },
    {
      "x": -29,
      "y": 1,
      "z": -28,
      "name": "Rock_Stone_Brick",
      "rotation": 2
    },
    {
      "x": -29,
      "y": 2,
      "z": -28,
      "name": "Rock_Stone_Brick",
      "rotation": 2
    },
    {
      "x": -29,
      "y": 3,
      "z": -28,
      "name": "Rock_Stone_Brick",
      "rotation": 2
    },
    {
      "x": -29,
      "y": 4,
      "z": -28,
      "name": "Rock_Stone_Brick",
      "rotation": 2
    },
    {
      "x": -29,
      "y": 5,
      "z": -28,
      "name": "Rock_Stone_Brick",
      "rotation": 2
    },
    {
      "x": -29,
      "y": 6,
      "z": -28,
      "name": "Rock_Stone_Brick",
      "rotation": 2
    },
    {
      "x": -29,
      "y": 5,
      "z": -27,
      "name": "Rock_Stone_Brick",
      "rotation": 2
    },
    {
      "x": -29,
      "y": 5,
      "z": -26,
      "name": "Rock_Stone_Brick",
      "rotation": 2
    },
    {
      "x": -29,
      "y": 5,
      "z": -25,
      "name": "Rock_Stone_Brick",
      "rotation": 2
    },
    {
      "x": -29,
      "y": 5,
      "z": -24,
      "name": "Rock_Stone_Brick",
      "rotation": 2
    },
    {
      "x": -29,
      "y": 1,
      "z": -23,
      "name": "Furniture_Human_Ruins_Coffin",
      "filler": 992,
      "rotation": 1
    },
    {
      "x": -29,
      "y": 5,
      "z": -23,
      "name": "Rock_Stone_Brick",
      "rotation": 2
    },
    {
      "x": -29,
      "y": 1,
      "z": -22,
      "name": "Furniture_Human_Ruins_Coffin",
      "rotation": 1
    },
    {
      "x": -29,
      "y": 5,
      "z": -22,
      "name": "Rock_Stone_Brick",
      "rotation": 2
    },
    {
      "x": -29,
      "y": 5,
      "z": -21,
      "name": "Rock_Stone_Brick",
      "rotation": 2
    },
    {
      "x": -29,
      "y": 5,
      "z": -20,
      "name": "Rock_Stone_Brick",
      "rotation": 2
    },
    {
      "x": -29,
      "y": 6,
      "z": -20,
      "name": "Deco_Pot_Clay_Broken"
    },
    {
      "x": -29,
      "y": 1,
      "z": -19,
      "name": "Rock_Stone_Brick",
      "rotation": 2
    },
    {
      "x": -29,
      "y": 2,
      "z": -19,
      "name": "Rock_Stone_Brick",
      "rotation": 2
    },
    {
      "x": -29,
      "y": 3,
      "z": -19,
      "name": "Rock_Stone_Brick",
      "rotation": 2
    },
    {
      "x": -29,
      "y": 4,
      "z": -19,
      "name": "Rock_Stone_Brick",
      "rotation": 2
    },
    {
      "x": -29,
      "y": 5,
      "z": -19,
      "name": "Rock_Stone_Brick",
      "rotation": 2
    },
    {
      "x": -29,
      "y": 6,
      "z": -19,
      "name": "Rock_Stone_Brick",
      "rotation": 2
    },
    {
      "x": -28,
      "y": 1,
      "z": -28,
      "name": "Rock_Stone_Brick",
      "rotation": 2
    },
    {
      "x": -28,
      "y": 4,
      "z": -28,
      "name": "Rock_Stone_Brick",
      "rotation": 2
    },
    {
      "x": -28,
      "y": 5,
      "z": -28,
      "name": "Rock_Stone_Brick",
      "rotation": 2
    },
    {
      "x": -28,
      "y": 6,
      "z": -28,
      "name": "Rock_Stone_Brick_Stairs",
      "rotation": 2
    },
    {
      "x": -28,
      "y": 1,
      "z": -27,
      "name": "Rubble_Stone"
    },
    {
      "x": -28,
      "y": 5,
      "z": -27,
      "name": "Rock_Stone_Brick",
      "rotation": 2
    },
    {
      "x": -28,
      "y": 5,
      "z": -26,
      "name": "Rock_Stone_Brick",
      "rotation": 2
    },
    {
      "x": -28,
      "y": 5,
      "z": -25,
      "name": "Rock_Stone_Brick",
      "rotation": 2
    },
    {
      "x": -28,
      "y": 5,
      "z": -24,
      "name": "Rock_Stone_Brick",
      "rotation": 2
    },
    {
      "x": -28,
      "y": 5,
      "z": -23,
      "name": "Rock_Stone_Brick",
      "rotation": 2
    },
    {
      "x": -28,
      "y": 1,
      "z": -22,
      "name": "Deco_Bone_Pile"
    },
    {
      "x": -28,
      "y": 5,
      "z": -22,
      "name": "Rock_Stone_Brick",
      "rotation": 2
    },
    {
      "x": -28,
      "y": 5,
      "z": -21,
      "name": "Rock_Stone_Brick",
      "rotation": 2
    },
    {
      "x": -28,
      "y": 1,
      "z": -20,
      "name": "Deco_Bone_Skulls"
    },
    {
      "x": -28,
      "y": 5,
      "z": -20,
      "name": "Rock_Stone_Brick",
      "rotation": 2
    },
    {
      "x": -28,
      "y": 1,
      "z": -19,
      "name": "Rock_Stone_Brick",
      "rotation": 2
    },
    {
      "x": -28,
      "y": 2,
      "z": -19,
      "name": "Rock_Stone_Brick",
      "rotation": 2
    },
    {
      "x": -28,
      "y": 3,
      "z": -19,
      "name": "Rock_Stone_Brick",
      "rotation": 2
    },
    {
      "x": -28,
      "y": 4,
      "z": -19,
      "name": "Rock_Stone_Brick",
      "rotation": 2
    },
    {
      "x": -28,
      "y": 5,
      "z": -19,
      "name": "Rock_Stone_Brick",
      "rotation": 2
    },
    {
      "x": -28,
      "y": 6,
      "z": -19,
      "name": "Rock_Stone_Brick",
      "rotation": 2
    },
    {
      "x": -27,
      "y": 1,
      "z": -28,
      "name": "Rock_Stone_Brick",
      "rotation": 2
    },
    {
      "x": -27,
      "y": 2,
      "z": -28,
      "name": "Rock_Stone_Brick",
      "rotation": 2
    },
    {
      "x": -27,
      "y": 3,
      "z": -28,
      "name": "Rock_Stone_Brick",
      "rotation": 2
    },
    {
      "x": -27,
      "y": 4,
      "z": -28,
      "name": "Rock_Stone_Brick",
      "rotation": 2
    },
    {
      "x": -27,
      "y": 5,
      "z": -28,
      "name": "Rock_Stone_Brick",
      "rotation": 2
    },
    {
      "x": -27,
      "y": 6,
      "z": -28,
      "name": "Rock_Stone_Brick_Stairs",
      "rotation": 2
    },
    {
      "x": -27,
      "y": 5,
      "z": -27,
      "name": "Rock_Stone_Brick",
      "rotation": 2
    },
    {
      "x": -27,
      "y": 5,
      "z": -26,
      "name": "Rock_Stone_Brick",
      "rotation": 2
    },
    {
      "x": -27,
      "y": 1,
      "z": -25,
      "name": "Rubble_Stone"
    },
    {
      "x": -27,
      "y": 5,
      "z": -25,
      "name": "Rock_Stone_Brick",
      "rotation": 2
    },
    {
      "x": -27,
      "y": 5,
      "z": -24,
      "name": "Rock_Stone_Brick",
      "rotation": 2
    },
    {
      "x": -27,
      "y": 1,
      "z": -23,
      "name": "Rubble_Stone"
    },
    {
      "x": -27,
      "y": 5,
      "z": -23,
      "name": "Rock_Stone_Brick",
      "rotation": 2
    },
    {
      "x": -27,
      "y": 1,
      "z": -22,
      "name": "Rubble_Stone_Medium"
    },
    {
      "x": -27,
      "y": 5,
      "z": -22,
      "name": "Rock_Stone_Brick",
      "rotation": 2
    },
    {
      "x": -27,
      "y": 5,
      "z": -21,
      "name": "Rock_Stone_Brick",
      "rotation": 2
    },
    {
      "x": -27,
      "y": 1,
      "z": -20,
      "name": "Deco_SpiderWeb",
      "rotation": 2
    },
    {
      "x": -27,
      "y": 4,
      "z": -20,
      "name": "Deco_SpiderWeb",
      "rotation": 8
    },
    {
      "x": -27,
      "y": 5,
      "z": -20,
      "name": "Rock_Stone_Brick",
      "rotation": 2
    },
    {
      "x": -27,
      "y": 1,
      "z": -19,
      "name": "Rock_Stone_Brick",
      "rotation": 2
    },
    {
      "x": -27,
      "y": 2,
      "z": -19,
      "name": "Rock_Stone_Brick",
      "rotation": 2
    },
    {
      "x": -27,
      "y": 3,
      "z": -19,
      "name": "Rock_Stone_Brick",
      "rotation": 2
    },
    {
      "x": -27,
      "y": 4,
      "z": -19,
      "name": "Rock_Stone_Brick",
      "rotation": 2
    },
    {
      "x": -27,
      "y": 5,
      "z": -19,
      "name": "Rock_Stone_Brick",
      "rotation": 2
    },
    {
      "x": -27,
      "y": 6,
      "z": -19,
      "name": "Rock_Stone_Brick",
      "rotation": 2
    },
    {
      "x": -26,
      "y": 1,
      "z": -28,
      "name": "Rock_Stone_Brick",
      "rotation": 2
    },
    {
      "x": -26,
      "y": 2,
      "z": -28,
      "name": "Rock_Stone_Brick_Ornate"
    },
    {
      "x": -26,
      "y": 3,
      "z": -28,
      "name": "Rock_Stone_Brick",
      "rotation": 2
    },
    {
      "x": -26,
      "y": 4,
      "z": -28,
      "name": "Rock_Stone_Brick",
      "rotation": 2
    },
    {
      "x": -26,
      "y": 5,
      "z": -28,
      "name": "Rock_Stone_Brick",
      "rotation": 2
    },
    {
      "x": -26,
      "y": 6,
      "z": -28,
      "name": "Rock_Stone_Brick",
      "rotation": 2
    },
    {
      "x": -26,
      "y": 4,
      "z": -27,
      "name": "Rock_Stone_Brick_Stairs",
      "rotation": 10
    },
    {
      "x": -26,
      "y": 5,
      "z": -27,
      "name": "Rock_Stone_Brick",
      "rotation": 2
    },
    {
      "x": -26,
      "y": 6,
      "z": -27,
      "name": "Rock_Stone_Brick_Stairs",
      "rotation": 1
    },
    {
      "x": -26,
      "y": 4,
      "z": -26,
      "name": "Rock_Stone_Brick_Stairs",
      "rotation": 8
    },
    {
      "x": -26,
      "y": 5,
      "z": -26,
      "name": "Rock_Stone_Brick",
      "rotation": 2
    },
    {
      "x": -26,
      "y": 6,
      "z": -26,
      "name": "Rock_Stone_Brick_Stairs",
      "rotation": 1
    },
    {
      "x": -26,
      "y": 1,
      "z": -25,
      "name": "Rock_Stone_Brick",
      "rotation": 2
    },
    {
      "x": -26,
      "y": 2,
      "z": -25,
      "name": "Rock_Stone_Brick_Ornate"
    },
    {
      "x": -26,
      "y": 4,
      "z": -25,
      "name": "Rock_Stone_Brick",
      "rotation": 2
    },
    {
      "x": -26,
      "y": 5,
      "z": -25,
      "name": "Rock_Stone_Brick",
      "rotation": 2
    },
    {
      "x": -26,
      "y": 6,
      "z": -25,
      "name": "Rock_Stone_Brick",
      "rotation": 2
    },
    {
      "x": -26,
      "y": 1,
      "z": -24,
      "name": "Rock_Stone_Brick",
      "rotation": 2
    },
    {
      "x": -26,
      "y": 5,
      "z": -24,
      "name": "Rock_Stone_Brick",
      "rotation": 2
    },
    {
      "x": -26,
      "y": 1,
      "z": -23,
      "name": "Rock_Stone_Brick",
      "rotation": 2
    },
    {
      "x": -26,
      "y": 2,
      "z": -23,
      "name": "Rubble_Stone_Medium"
    },
    {
      "x": -26,
      "y": 4,
      "z": -23,
      "name": "Rock_Stone_Brick",
      "rotation": 2
    },
    {
      "x": -26,
      "y": 5,
      "z": -23,
      "name": "Rock_Stone_Brick",
      "rotation": 2
    },
    {
      "x": -26,
      "y": 6,
      "z": -23,
      "name": "Prefab_Spawner_Block",
      "components": {
        "Components": {
          "PlacedByInteraction": {
            "WhoPlacedUuid": {
              "$binary": "30E5va+4QA2ISsflEWOC9g==",
              "$type": "04"
            }
          },
          "prefabspawner": {
            "Position": {
              "X": 9,
              "Y": 5,
              "Z": 5
            },
            "PrefabPath": "Refresh_Studios/Skeleton_Dungeon/Bridge2",
            "FitHeightmap": false,
            "InheritSeed": true,
            "InheritHeightCondition": true
          }
        }
      },
      "rotation": 1
    },
    {
      "x": -26,
      "y": 1,
      "z": -22,
      "name": "Rock_Stone_Brick",
      "rotation": 2
    },
    {
      "x": -26,
      "y": 2,
      "z": -22,
      "name": "Rock_Stone_Brick",
      "rotation": 2
    },
    {
      "x": -26,
      "y": 3,
      "z": -22,
      "name": "Rubble_Stone"
    },
    {
      "x": -26,
      "y": 5,
      "z": -22,
      "name": "Rock_Stone_Brick",
      "rotation": 2
    },
    {
      "x": -26,
      "y": 6,
      "z": -22,
      "name": "Rock_Stone_Brick",
      "rotation": 2
    },
    {
      "x": -26,
      "y": 1,
      "z": -21,
      "name": "Rock_Stone_Brick",
      "rotation": 2
    },
    {
      "x": -26,
      "y": 2,
      "z": -21,
      "name": "Rock_Stone_Brick",
      "rotation": 2
    },
    {
      "x": -26,
      "y": 3,
      "z": -21,
      "name": "Rock_Stone_Brick",
      "rotation": 2
    },
    {
      "x": -26,
      "y": 4,
      "z": -21,
      "name": "Rubble_Stone_Medium"
    },
    {
      "x": -26,
      "y": 5,
      "z": -21,
      "name": "Rock_Stone_Brick",
      "rotation": 2
    },
    {
      "x": -26,
      "y": 6,
      "z": -21,
      "name": "Rock_Stone_Brick_Stairs",
      "rotation": 1
    },
    {
      "x": -26,
      "y": 1,
      "z": -20,
      "name": "Rock_Stone_Brick",
      "rotation": 2
    },
    {
      "x": -26,
      "y": 2,
      "z": -20,
      "name": "Rock_Stone_Brick",
      "rotation": 2
    },
    {
      "x": -26,
      "y": 3,
      "z": -20,
      "name": "Rock_Stone_Brick",
      "rotation": 2
    },
    {
      "x": -26,
      "y": 4,
      "z": -20,
      "name": "Rock_Stone_Brick",
      "rotation": 2
    },
    {
      "x": -26,
      "y": 5,
      "z": -20,
      "name": "Rock_Stone_Brick",
      "rotation": 2
    },
    {
      "x": -26,
      "y": 6,
      "z": -20,
      "name": "Rock_Stone_Brick_Stairs",
      "rotation": 1
    },
    {
      "x": -26,
      "y": 1,
      "z": -19,
      "name": "Rock_Stone_Brick",
      "rotation": 2
    },
    {
      "x": -26,
      "y": 2,
      "z": -19,
      "name": "Rock_Stone_Brick",
      "rotation": 2
    },
    {
      "x": -26,
      "y": 3,
      "z": -19,
      "name": "Rock_Stone_Brick",
      "rotation": 2
    },
    {
      "x": -26,
      "y": 4,
      "z": -19,
      "name": "Rock_Stone_Brick",
      "rotation": 2
    },
    {
      "x": -26,
      "y": 5,
      "z": -19,
      "name": "Rock_Stone_Brick",
      "rotation": 2
    },
    {
      "x": -26,
      "y": 6,
      "z": -19,
      "name": "Rock_Stone_Brick",
      "rotation": 2
    }
  ],
  "entities": [
    {
      "Components": {
        "EffectController": {},
        "DisplayName": {
          "DisplayName": {
            "MessageId": "server.npcRoles.Skeleton_Archer.name",
            "Bold": null,
            "Italic": null,
            "Monospace": null,
            "Underline": null
          }
        },
        "UIComponentList": {},
        "Transform": {
          "Position": {
            "X": -30.316152572631836,
            "Y": 6.0,
            "Z": -20.513389587402344
          },
          "Rotation": {
            "Pitch": 0.0,
            "Yaw": -0.29988476634025574,
            "Roll": 0.0
          }
        },
        "Velocity": {
          "Velocity": {
            "X": 0.0,
            "Y": 0.0,
            "Z": 0.0
          }
        },
        "Interactions": {
          "Interactions": {
            "Use": "*UseNPC"
          }
        },
        "Model": {
          "Model": {
            "Id": "Skeleton_Archer",
            "Scale": 1.0,
            "Static": false
          }
        },
        "UUID": {
          "UUID": {
            "$binary": "GcoQvcPBOSi4XUalZxf56w==",
            "$type": "04"
          }
        },
        "EntityStats": {
          "Version": 5,
          "Stats": {
            "Oxygen": {
              "Id": "Oxygen",
              "Value": 100.0
            },
            "Mana": {
              "Id": "Mana",
              "Value": 0.0
            },
            "Health": {
              "Id": "Health",
              "Value": 29.0
            },
            "GlidingActive": {
              "Id": "GlidingActive",
              "Value": 0.0
            },
            "Immunity": {
              "Id": "Immunity",
              "Value": 0.0
            },
            "SignatureCharges": {
              "Id": "SignatureCharges",
              "Value": 0.0
            },
            "Stamina": {
              "Id": "Stamina",
              "Value": 10.0
            },
            "Ammo": {
              "Id": "Ammo",
              "Value": 0.0
            },
            "Unknown": {
              "Id": "Unknown",
              "Value": 0.0
            },
            "SignatureEnergy": {
              "Id": "SignatureEnergy",
              "Value": 0.0
            },
            "DeployablePreview": {
              "Id": "DeployablePreview",
              "Value": 0.0
            },
            "StaminaRegenDelay": {
              "Id": "StaminaRegenDelay",
              "Value": 0.0
            },
            "MagicCharges": {
              "Id": "MagicCharges",
              "Value": 0.0
            }
          }
        },
        "NPC": {
          "Version": 5,
          "UUID": {
            "$binary": "07mglyegOdes63Np0Ejhdw==",
            "$type": "04"
          },
          "Inventory": {
            "Version": 4,
            "Storage": {
              "Id": "Empty"
            },
            "Armor": {
              "Id": "Simple",
              "Capacity": 4,
              "Items": {}
            },
            "HotBar": {
              "Id": "Simple",
              "Capacity": 3,
              "Items": {
                "0": {
                  "Id": "Weapon_Shortbow_Iron_Rusty",
                  "Quantity": 1,
                  "Durability": 120.0,
                  "MaxDurability": 120.0,
                  "OverrideDroppedItemAnimation": false
                }
              }
            },
            "Utility": {
              "Id": "Simple",
              "Capacity": 2,
              "Items": {
                "0": {
                  "Id": "Furniture_Crude_Torch",
                  "Quantity": 1,
                  "Durability": 0.0,
                  "MaxDurability": 0.0,
                  "OverrideDroppedItemAnimation": false
                }
              }
            },
            "Backpack": {
              "Id": "Empty"
            },
            "ActiveHotbarSlot": 0,
            "Tool": {
              "Id": "Empty"
            },
            "ActiveToolsSlot": -1,
            "ActiveUtilitySlot": -1,
            "SortType": "Name"
          },
          "HvrPhs": 0.0,
          "HvrHght": 0.0,
          "MdlScl": 1.0,
          "SpawnInstant": "0001-01-01T12:00:00Z",
          "WorldgenId": 0,
          "PathManager": {},
          "LeashPos": {
            "X": 4.683847427368164,
            "Y": 60.0,
            "Z": 79.48661041259766
          },
          "LeashHdg": -0.29988476634025574,
          "LeashPtch": 0.0,
          "RoleName": "Skeleton_Archer"
        },
        "HeadRotation": {
          "Rotation": {
            "Pitch": 0.0,
            "Yaw": -0.29988476634025574,
            "Roll": 0.0
          }
        }
      }
    },
    {
      "Components": {
        "EffectController": {},
        "DisplayName": {
          "DisplayName": {
            "MessageId": "server.npcRoles.Skeleton_Archer.name",
            "Bold": null,
            "Italic": null,
            "Monospace": null,
            "Underline": null
          }
        },
        "UIComponentList": {},
        "Transform": {
          "Position": {
            "X": -31.837050437927246,
            "Y": 6.0,
            "Z": -22.07489776611328
          },
          "Rotation": {
            "Pitch": 0.0,
            "Yaw": -0.29988476634025574,
            "Roll": 0.0
          }
        },
        "Velocity": {
          "Velocity": {
            "X": 0.0,
            "Y": 0.0,
            "Z": 0.0
          }
        },
        "Interactions": {
          "Interactions": {
            "Use": "*UseNPC"
          }
        },
        "Model": {
          "Model": {
            "Id": "Skeleton_Archer",
            "Scale": 1.0,
            "Static": false
          }
        },
        "UUID": {
          "UUID": {
            "$binary": "v6Bh3x6oOf2kPAkUq/se2g==",
            "$type": "04"
          }
        },
        "EntityStats": {
          "Version": 5,
          "Stats": {
            "Oxygen": {
              "Id": "Oxygen",
              "Value": 100.0
            },
            "Mana": {
              "Id": "Mana",
              "Value": 0.0
            },
            "Health": {
              "Id": "Health",
              "Value": 29.0
            },
            "GlidingActive": {
              "Id": "GlidingActive",
              "Value": 0.0
            },
            "Immunity": {
              "Id": "Immunity",
              "Value": 0.0
            },
            "SignatureCharges": {
              "Id": "SignatureCharges",
              "Value": 0.0
            },
            "Stamina": {
              "Id": "Stamina",
              "Value": 10.0
            },
            "Ammo": {
              "Id": "Ammo",
              "Value": 0.0
            },
            "Unknown": {
              "Id": "Unknown",
              "Value": 0.0
            },
            "SignatureEnergy": {
              "Id": "SignatureEnergy",
              "Value": 0.0
            },
            "DeployablePreview": {
              "Id": "DeployablePreview",
              "Value": 0.0
            },
            "StaminaRegenDelay": {
              "Id": "StaminaRegenDelay",
              "Value": 0.0
            },
            "MagicCharges": {
              "Id": "MagicCharges",
              "Value": 0.0
            }
          }
        },
        "NPC": {
          "Version": 5,
          "UUID": {
            "$binary": "lUbPkefLMmaNWae36LDnEg==",
            "$type": "04"
          },
          "Inventory": {
            "Version": 4,
            "Storage": {
              "Id": "Empty"
            },
            "Armor": {
              "Id": "Simple",
              "Capacity": 4,
              "Items": {}
            },
            "HotBar": {
              "Id": "Simple",
              "Capacity": 3,
              "Items": {
                "0": {
                  "Id": "Weapon_Shortbow_Iron_Rusty",
                  "Quantity": 1,
                  "Durability": 120.0,
                  "MaxDurability": 120.0,
                  "OverrideDroppedItemAnimation": false
                }
              }
            },
            "Utility": {
              "Id": "Simple",
              "Capacity": 2,
              "Items": {
                "0": {
                  "Id": "Furniture_Crude_Torch",
                  "Quantity": 1,
                  "Durability": 0.0,
                  "MaxDurability": 0.0,
                  "OverrideDroppedItemAnimation": false
                }
              }
            },
            "Backpack": {
              "Id": "Empty"
            },
            "ActiveHotbarSlot": 0,
            "Tool": {
              "Id": "Empty"
            },
            "ActiveToolsSlot": -1,
            "ActiveUtilitySlot": -1,
            "SortType": "Name"
          },
          "HvrPhs": 0.0,
          "HvrHght": 0.0,
          "MdlScl": 1.0,
          "SpawnInstant": "0001-01-01T12:00:00Z",
          "WorldgenId": 0,
          "PathManager": {},
          "LeashPos": {
            "X": 3.162949562072754,
            "Y": 60.0,
            "Z": 77.92510223388672
          },
          "LeashHdg": -0.29988476634025574,
          "LeashPtch": 0.0,
          "RoleName": "Skeleton_Archer"
        },
        "HeadRotation": {
          "Rotation": {
            "Pitch": 0.0,
            "Yaw": -0.29988476634025574,
            "Roll": 0.0
          }
        }
      }
    }
  ]
}