{
  "version": 8,
  "blockIdVersion": 11,
  "anchorX": 0,
  "anchorY": 0,
  "anchorZ": 0,
  "blocks": [
    {
      "x": -2,
      "y": 0,
      "z": -7,
      "name": "Rock_Volcanic"
    },
    {
      "x": -2,
      "y": 1,
      "z": -7,
      "name": "Rock_Volcanic"
    },
    {
      "x": -2,
      "y": 2,
      "z": -7,
      "name": "Rock_Volcanic"
    },
    {
      "x": -2,
      "y": 3,
      "z": -7,
      "name": "Rock_Volcanic"
    },
    {
      "x": -2,
      "y": 4,
      "z": -7,
      "name": "Rock_Volcanic"
    },
    {
      "x": -2,
      "y": 0,
      "z": -6,
      "name": "Rock_Volcanic"
    },
    {
      "x": -2,
      "y": 1,
      "z": -6,
      "name": "Rock_Volcanic"
    },
    {
      "x": -2,
      "y": 2,
      "z": -6,
      "name": "Rock_Volcanic"
    },
    {
      "x": -2,
      "y": 3,
      "z": -6,
      "name": "Rock_Volcanic"
    },
    {
      "x": -2,
      "y": 4,
      "z": -6,
      "name": "Rock_Volcanic"
    },
    {
      "x": -2,
      "y": 0,
      "z": -5,
      "name": "Rock_Volcanic"
    },
    {
      "x": -2,
      "y": 1,
      "z": -5,
      "name": "Rock_Volcanic"
    },
    {
      "x": -2,
      "y": 2,
      "z": -5,
      "name": "Rock_Volcanic"
    },
    {
      "x": -2,
      "y": 3,
      "z": -5,
      "name": "Rock_Volcanic"
    },
    {
      "x": -2,
      "y": 4,
      "z": -5,
      "name": "Rock_Volcanic"
    },
    {
      "x": -2,
      "y": 0,
      "z": -4,
      "name": "Rock_Volcanic"
    },
    {
      "x": -2,
      "y": 1,
      "z": -4,
      "name": "Rock_Volcanic"
    },
    {
      "x": -2,
      "y": 2,
      "z": -4,
      "name": "Rock_Volcanic"
    },
    {
      "x": -2,
      "y": 3,
      "z": -4,
      "name": "Rock_Volcanic"
    },
    {
      "x": -2,
      "y": 4,
      "z": -4,
      "name": "Rock_Volcanic"
    },
    {
      "x": -2,
      "y": 0,
      "z": -3,
      "name": "Rock_Volcanic"
    },
    {
      "x": -2,
      "y": 1,
      "z": -3,
      "name": "Rock_Volcanic"
    },
    {
      "x": -2,
      "y": 2,
      "z": -3,
      "name": "Rock_Volcanic"
    },
    {
      "x": -2,
      "y": 3,
      "z": -3,
      "name": "Rock_Volcanic"
    },
    {
      "x": -2,
      "y": 4,
      "z": -3,
      "name": "Rock_Volcanic"
    },
    {
      "x": -2,
      "y": 0,
      "z": -2,
      "name": "Cloth_Block_Wool_Black"
    },
    {
      "x": -2,
      "y": 1,
      "z": -2,
      "name": "Cloth_Block_Wool_Black"
    },
    {
      "x": -2,
      "y": 2,
      "z": -2,
      "name": "Cloth_Block_Wool_Black"
    },
    {
      "x": -2,
      "y": 3,
      "z": -2,
      "name": "Cloth_Block_Wool_Black"
    },
    {
      "x": -2,
      "y": 4,
      "z": -2,
      "name": "Cloth_Block_Wool_Black"
    },
    {
      "x": -2,
      "y": 0,
      "z": -1,
      "name": "Cloth_Block_Wool_Black"
    },
    {
      "x": -2,
      "y": 1,
      "z": -1,
      "name": "Rock_Basalt_Brick"
    },
    {
      "x": -2,
      "y": 2,
      "z": -1,
      "name": "Rock_Basalt_Brick"
    },
    {
      "x": -2,
      "y": 3,
      "z": -1,
      "name": "Rock_Basalt_Brick"
    },
    {
      "x": -2,
      "y": 4,
      "z": -1,
      "name": "Cloth_Block_Wool_Black"
    },
    {
      "x": -2,
      "y": 0,
      "z": 0,
      "name": "Cloth_Block_Wool_Black"
    },
    {
      "x": -2,
      "y": 1,
      "z": 0,
      "name": "Rock_Basalt_Brick"
    },
    {
      "x": -2,
      "y": 2,
      "z": 0,
      "name": "Rock_Basalt_Brick"
    },
    {
      "x": -2,
      "y": 3,
      "z": 0,
      "name": "Rock_Basalt_Brick"
    },
    {
      "x": -2,
      "y": 4,
      "z": 0,
      "name": "Cloth_Block_Wool_Black"
    },
    {
      "x": -2,
      "y": 0,
      "z": 1,
      "name": "Cloth_Block_Wool_Black"
    },
    {
      "x": -2,
      "y": 1,
      "z": 1,
      "name": "Rock_Basalt_Brick"
    },
    {
      "x": -2,
      "y": 2,
      "z": 1,
      "name": "Rock_Basalt_Brick"
    },
    {
      "x": -2,
      "y": 3,
      "z": 1,
      "name": "Rock_Basalt_Brick"
    },
    {
      "x": -2,
      "y": 4,
      "z": 1,
      "name": "Cloth_Block_Wool_Black"
    },
    {
      "x": -2,
      "y": 0,
      "z": 2,
      "name": "Cloth_Block_Wool_Black"
    },
    {
      "x": -2,
      "y": 1,
      "z": 2,
      "name": "Rock_Basalt_Brick"
    },
    {
      "x": -2,
      "y": 2,
      "z": 2,
      "name": "Rock_Basalt_Brick"
    },
    {
      "x": -2,
      "y": 3,
      "z": 2,
      "name": "Rock_Basalt_Brick"
    },
    {
      "x": -2,
      "y": 4,
      "z": 2,
      "name": "Cloth_Block_Wool_Black"
    },
    {
      "x": -2,
      "y": 0,
      "z": 3,
      "name": "Cloth_Block_Wool_Black"
    },
    {
      "x": -2,
      "y": 1,
      "z": 3,
      "name": "Rock_Basalt_Brick"
    },
    {
      "x": -2,
      "y": 2,
      "z": 3,
      "name": "Rock_Basalt_Brick"
    },
    {
      "x": -2,
      "y": 3,
      "z": 3,
      "name": "Rock_Basalt_Brick"
    },
    {
      "x": -2,
      "y": 4,
      "z": 3,
      "name": "Cloth_Block_Wool_Black"
    },
    {
      "x": -2,
      "y": 0,
      "z": 4,
      "name": "Cloth_Block_Wool_Black"
    },
    {
      "x": -2,
      "y": 1,
      "z": 4,
      "name": "Rock_Basalt_Brick"
    },
    {
      "x": -2,
      "y": 2,
      "z": 4,
      "name": "Rock_Basalt_Brick"
    },
    {
      "x": -2,
      "y": 3,
      "z": 4,
      "name": "Rock_Basalt_Brick"
    },
    {
      "x": -2,
      "y": 4,
      "z": 4,
      "name": "Cloth_Block_Wool_Black"
    },
    {
      "x": -2,
      "y": 0,
      "z": 5,
      "name": "Cloth_Block_Wool_Black"
    },
    {
      "x": -2,
      "y": 1,
      "z": 5,
      "name": "Rock_Basalt_Brick"
    },
    {
      "x": -2,
      "y": 2,
      "z": 5,
      "name": "Rock_Basalt_Brick"
    },
    {
      "x": -2,
      "y": 3,
      "z": 5,
      "name": "Rock_Basalt_Brick"
    },
    {
      "x": -2,
      "y": 4,
      "z": 5,
      "name": "Cloth_Block_Wool_Black"
    },
    {
      "x": -2,
      "y": 0,
      "z": 6,
      "name": "Cloth_Block_Wool_Black"
    },
    {
      "x": -2,
      "y": 1,
      "z": 6,
      "name": "Rock_Basalt_Brick"
    },
    {
      "x": -2,
      "y": 2,
      "z": 6,
      "name": "Rock_Basalt_Brick"
    },
    {
      "x": -2,
      "y": 3,
      "z": 6,
      "name": "Rock_Basalt_Brick"
    },
    {
      "x": -2,
      "y": 4,
      "z": 6,
      "name": "Cloth_Block_Wool_Black"
    },
    {
      "x": -2,
      "y": 0,
      "z": 7,
      "name": "Cloth_Block_Wool_Black"
    },
    {
      "x": -2,
      "y": 1,
      "z": 7,
      "name": "Cloth_Block_Wool_Black"
    },
    {
      "x": -2,
      "y": 2,
      "z": 7,
      "name": "Cloth_Block_Wool_Black"
    },
    {
      "x": -2,
      "y": 3,
      "z": 7,
      "name": "Cloth_Block_Wool_Black"
    },
    {
      "x": -2,
      "y": 4,
      "z": 7,
      "name": "Cloth_Block_Wool_Black"
    },
    {
      "x": -1,
      "y": 0,
      "z": -7,
      "name": "Rock_Volcanic"
    },
    {
      "x": -1,
      "y": 1,
      "z": -7,
      "name": "Rock_Volcanic"
    },
    {
      "x": -1,
      "y": 2,
      "z": -7,
      "name": "Rock_Volcanic"
    },
    {
      "x": -1,
      "y": 3,
      "z": -7,
      "name": "Rock_Volcanic"
    },
    {
      "x": -1,
      "y": 4,
      "z": -7,
      "name": "Rock_Volcanic"
    },
    {
      "x": -1,
      "y": 0,
      "z": -6,
      "name": "Rock_Volcanic"
    },
    {
      "x": -1,
      "y": 1,
      "z": -6,
      "name": "Rock_Volcanic"
    },
    {
      "x": -1,
      "y": 2,
      "z": -6,
      "name": "Rock_Volcanic"
    },
    {
      "x": -1,
      "y": 3,
      "z": -6,
      "name": "Rock_Volcanic"
    },
    {
      "x": -1,
      "y": 4,
      "z": -6,
      "name": "Rock_Volcanic"
    },
    {
      "x": -1,
      "y": 0,
      "z": -5,
      "name": "Rock_Volcanic"
    },
    {
      "x": -1,
      "y": 1,
      "z": -5,
      "name": "Rock_Volcanic"
    },
    {
      "x": -1,
      "y": 2,
      "z": -5,
      "name": "Rock_Volcanic"
    },
    {
      "x": -1,
      "y": 3,
      "z": -5,
      "name": "Rock_Volcanic"
    },
    {
      "x": -1,
      "y": 4,
      "z": -5,
      "name": "Rock_Volcanic"
    },
    {
      "x": -1,
      "y": 0,
      "z": -4,
      "name": "Rock_Volcanic"
    },
    {
      "x": -1,
      "y": 1,
      "z": -4,
      "name": "Rock_Volcanic"
    },
    {
      "x": -1,
      "y": 2,
      "z": -4,
      "name": "Rock_Volcanic"
    },
    {
      "x": -1,
      "y": 3,
      "z": -4,
      "name": "Rock_Volcanic"
    },
    {
      "x": -1,
      "y": 4,
      "z": -4,
      "name": "Rock_Volcanic"
    },
    {
      "x": -1,
      "y": 0,
      "z": -3,
      "name": "Rock_Volcanic"
    },
    {
      "x": -1,
      "y": 1,
      "z": -3,
      "name": "Rock_Volcanic"
    },
    {
      "x": -1,
      "y": 2,
      "z": -3,
      "name": "Rock_Volcanic"
    },
    {
      "x": -1,
      "y": 3,
      "z": -3,
      "name": "Rock_Volcanic"
    },
    {
      "x": -1,
      "y": 4,
      "z": -3,
      "name": "Rock_Volcanic"
    },
    {
      "x": -1,
      "y": 0,
      "z": -2,
      "name": "Cloth_Block_Wool_Black"
    },
    {
      "x": -1,
      "y": 1,
      "z": -2,
      "name": "Rock_Basalt_Brick"
    },
    {
      "x": -1,
      "y": 2,
      "z": -2,
      "name": "Rock_Basalt_Brick"
    },
    {
      "x": -1,
      "y": 3,
      "z": -2,
      "name": "Rock_Basalt_Brick"
    },
    {
      "x": -1,
      "y": 4,
      "z": -2,
      "name": "Cloth_Block_Wool_Black"
    },
    {
      "x": -1,
      "y": 0,
      "z": -1,
      "name": "Cloth_Block_Wool_Black"
    },
    {
      "x": -1,
      "y": 1,
      "z": -1,
      "name": "Empty"
    },
    {
      "x": -1,
      "y": 2,
      "z": -1,
      "name": "Empty"
    },
    {
      "x": -1,
      "y": 3,
      "z": -1,
      "name": "Wood_Torch_Wall"
    },
    {
      "x": -1,
      "y": 4,
      "z": -1,
      "name": "Cloth_Block_Wool_Black"
    },
    {
      "x": -1,
      "y": 0,
      "z": 0,
      "name": "Cloth_Block_Wool_Black"
    },
    {
      "x": -1,
      "y": 1,
      "z": 0,
      "name": "Empty"
    },
    {
      "x": -1,
      "y": 2,
      "z": 0,
      "name": "Empty"
    },
    {
      "x": -1,
      "y": 3,
      "z": 0,
      "name": "Empty"
    },
    {
      "x": -1,
      "y": 4,
      "z": 0,
      "name": "Cloth_Block_Wool_Black"
    },
    {
      "x": -1,
      "y": 0,
      "z": 1,
      "name": "Cloth_Block_Wool_Black"
    },
    {
      "x": -1,
      "y": 1,
      "z": 1,
      "name": "Empty"
    },
    {
      "x": -1,
      "y": 2,
      "z": 1,
      "name": "Empty"
    },
    {
      "x": -1,
      "y": 3,
      "z": 1,
      "name": "Empty"
    },
    {
      "x": -1,
      "y": 4,
      "z": 1,
      "name": "Cloth_Block_Wool_Black"
    },
    {
      "x": -1,
      "y": 0,
      "z": 2,
      "name": "Cloth_Block_Wool_Black"
    },
    {
      "x": -1,
      "y": 1,
      "z": 2,
      "name": "Empty"
    },
    {
      "x": -1,
      "y": 2,
      "z": 2,
      "name": "Empty"
    },
    {
      "x": -1,
      "y": 3,
      "z": 2,
      "name": "Wood_Torch_Wall",
      "rotation": 2
    },
    {
      "x": -1,
      "y": 4,
      "z": 2,
      "name": "Cloth_Block_Wool_Black"
    },
    {
      "x": -1,
      "y": 0,
      "z": 3,
      "name": "Cloth_Block_Wool_Black"
    },
    {
      "x": -1,
      "y": 1,
      "z": 3,
      "name": "*Furniture_Temple_Light_Door_State_Definitions_CloseDoorIn",
      "rotation": 2
    },
    {
      "x": -1,
      "y": 2,
      "z": 3,
      "name": "*Furniture_Temple_Light_Door_State_Definitions_CloseDoorIn",
      "filler": 1024,
      "rotation": 2
    },
    {
      "x": -1,
      "y": 3,
      "z": 3,
      "name": "Rock_Basalt_Brick"
    },
    {
      "x": -1,
      "y": 4,
      "z": 3,
      "name": "Cloth_Block_Wool_Black"
    },
    {
      "x": -1,
      "y": 0,
      "z": 4,
      "name": "Cloth_Block_Wool_Black"
    },
    {
      "x": -1,
      "y": 1,
      "z": 4,
      "name": "Empty"
    },
    {
      "x": -1,
      "y": 2,
      "z": 4,
      "name": "Empty"
    },
    {
      "x": -1,
      "y": 3,
      "z": 4,
      "name": "Empty"
    },
    {
      "x": -1,
      "y": 4,
      "z": 4,
      "name": "Cloth_Block_Wool_Black"
    },
    {
      "x": -1,
      "y": 0,
      "z": 5,
      "name": "Cloth_Block_Wool_Black"
    },
    {
      "x": -1,
      "y": 1,
      "z": 5,
      "name": "Empty"
    },
    {
      "x": -1,
      "y": 2,
      "z": 5,
      "name": "Empty"
    },
    {
      "x": -1,
      "y": 3,
      "z": 5,
      "name": "Wood_Torch_Wall",
      "rotation": 1
    },
    {
      "x": -1,
      "y": 4,
      "z": 5,
      "name": "Cloth_Block_Wool_Black"
    },
    {
      "x": -1,
      "y": 0,
      "z": 6,
      "name": "Cloth_Block_Wool_Black"
    },
    {
      "x": -1,
      "y": 1,
      "z": 6,
      "name": "Empty"
    },
    {
      "x": -1,
      "y": 2,
      "z": 6,
      "name": "Empty"
    },
    {
      "x": -1,
      "y": 3,
      "z": 6,
      "name": "Empty"
    },
    {
      "x": -1,
      "y": 4,
      "z": 6,
      "name": "Cloth_Block_Wool_Black"
    },
    {
      "x": -1,
      "y": 0,
      "z": 7,
      "name": "Cloth_Block_Wool_Black"
    },
    {
      "x": -1,
      "y": 1,
      "z": 7,
      "name": "Rock_Basalt_Brick"
    },
    {
      "x": -1,
      "y": 2,
      "z": 7,
      "name": "Rock_Basalt_Brick"
    },
    {
      "x": -1,
      "y": 3,
      "z": 7,
      "name": "Rock_Basalt_Brick"
    },
    {
      "x": -1,
      "y": 4,
      "z": 7,
      "name": "Cloth_Block_Wool_Black"
    },
    {
      "x": 0,
      "y": 0,
      "z": -7,
      "name": "Rock_Volcanic"
    },
    {
      "x": 0,
      "y": 1,
      "z": -7,
      "name": "Rock_Volcanic"
    },
    {
      "x": 0,
      "y": 2,
      "z": -7,
      "name": "Rock_Volcanic"
    },
    {
      "x": 0,
      "y": 3,
      "z": -7,
      "name": "Rock_Volcanic"
    },
    {
      "x": 0,
      "y": 4,
      "z": -7,
      "name": "Rock_Volcanic"
    },
    {
      "x": 0,
      "y": 0,
      "z": -6,
      "name": "Rock_Volcanic"
    },
    {
      "x": 0,
      "y": 1,
      "z": -6,
      "name": "Rock_Volcanic"
    },
    {
      "x": 0,
      "y": 2,
      "z": -6,
      "name": "Rock_Volcanic"
    },
    {
      "x": 0,
      "y": 3,
      "z": -6,
      "name": "Rock_Volcanic"
    },
    {
      "x": 0,
      "y": 4,
      "z": -6,
      "name": "Rock_Volcanic"
    },
    {
      "x": 0,
      "y": 0,
      "z": -5,
      "name": "Rock_Volcanic"
    },
    {
      "x": 0,
      "y": 1,
      "z": -5,
      "name": "Rock_Volcanic"
    },
    {
      "x": 0,
      "y": 2,
      "z": -5,
      "name": "Rock_Volcanic"
    },
    {
      "x": 0,
      "y": 3,
      "z": -5,
      "name": "Rock_Volcanic"
    },
    {
      "x": 0,
      "y": 4,
      "z": -5,
      "name": "Rock_Volcanic"
    },
    {
      "x": 0,
      "y": 0,
      "z": -4,
      "name": "Rock_Volcanic"
    },
    {
      "x": 0,
      "y": 1,
      "z": -4,
      "name": "Rock_Volcanic"
    },
    {
      "x": 0,
      "y": 2,
      "z": -4,
      "name": "Rock_Volcanic"
    },
    {
      "x": 0,
      "y": 3,
      "z": -4,
      "name": "Rock_Volcanic"
    },
    {
      "x": 0,
      "y": 4,
      "z": -4,
      "name": "Rock_Volcanic"
    },
    {
      "x": 0,
      "y": 0,
      "z": -3,
      "name": "Rock_Volcanic"
    },
    {
      "x": 0,
      "y": 1,
      "z": -3,
      "name": "Rock_Volcanic"
    },
    {
      "x": 0,
      "y": 2,
      "z": -3,
      "name": "Rock_Volcanic"
    },
    {
      "x": 0,
      "y": 3,
      "z": -3,
      "name": "Rock_Volcanic"
    },
    {
      "x": 0,
      "y": 4,
      "z": -3,
      "name": "Rock_Volcanic"
    },
    {
      "x": 0,
      "y": 0,
      "z": -2,
      "name": "Cloth_Block_Wool_Black"
    },
    {
      "x": 0,
      "y": 1,
      "z": -2,
      "name": "Rock_Basalt_Brick"
    },
    {
      "x": 0,
      "y": 2,
      "z": -2,
      "name": "Rock_Basalt_Brick"
    },
    {
      "x": 0,
      "y": 3,
      "z": -2,
      "name": "Rock_Basalt_Brick"
    },
    {
      "x": 0,
      "y": 4,
      "z": -2,
      "name": "Cloth_Block_Wool_Black"
    },
    {
      "x": 0,
      "y": 0,
      "z": -1,
      "name": "Cloth_Block_Wool_Black"
    },
    {
      "x": 0,
      "y": 1,
      "z": -1,
      "name": "Empty"
    },
    {
      "x": 0,
      "y": 2,
      "z": -1,
      "name": "Empty"
    },
    {
      "x": 0,
      "y": 3,
      "z": -1,
      "name": "Empty"
    },
    {
      "x": 0,
      "y": 4,
      "z": -1,
      "name": "Cloth_Block_Wool_Black"
    },
    {
      "x": 0,
      "y": 0,
      "z": 0,
      "name": "Cloth_Block_Wool_Black"
    },
    {
      "x": 0,
      "y": 1,
      "z": 0,
      "name": "Empty"
    },
    {
      "x": 0,
      "y": 2,
      "z": 0,
      "name": "Empty"
    },
    {
      "x": 0,
      "y": 3,
      "z": 0,
      "name": "Empty"
    },
    {
      "x": 0,
      "y": 4,
      "z": 0,
      "name": "Cloth_Block_Wool_Black"
    },
    {
      "x": 0,
      "y": 0,
      "z": 1,
      "name": "Cloth_Block_Wool_Black"
    },
    {
      "x": 0,
      "y": 1,
      "z": 1,
      "name": "Empty"
    },
    {
      "x": 0,
      "y": 2,
      "z": 1,
      "name": "Empty"
    },
    {
      "x": 0,
      "y": 3,
      "z": 1,
      "name": "Empty"
    },
    {
      "x": 0,
      "y": 4,
      "z": 1,
      "name": "Cloth_Block_Wool_Black"
    },
    {
      "x": 0,
      "y": 0,
      "z": 2,
      "name": "Cloth_Block_Wool_Black"
    },
    {
      "x": 0,
      "y": 1,
      "z": 2,
      "name": "Empty"
    },
    {
      "x": 0,
      "y": 2,
      "z": 2,
      "name": "Empty"
    },
    {
      "x": 0,
      "y": 3,
      "z": 2,
      "name": "Empty"
    },
    {
      "x": 0,
      "y": 4,
      "z": 2,
      "name": "Cloth_Block_Wool_Black"
    },
    {
      "x": 0,
      "y": 0,
      "z": 3,
      "name": "Cloth_Block_Wool_Black"
    },
    {
      "x": 0,
      "y": 1,
      "z": 3,
      "name": "Rock_Basalt_Brick"
    },
    {
      "x": 0,
      "y": 2,
      "z": 3,
      "name": "Rock_Basalt_Brick"
    },
    {
      "x": 0,
      "y": 3,
      "z": 3,
      "name": "Rock_Basalt_Brick"
    },
    {
      "x": 0,
      "y": 4,
      "z": 3,
      "name": "Cloth_Block_Wool_Black"
    },
    {
      "x": 0,
      "y": 0,
      "z": 4,
      "name": "Cloth_Block_Wool_Black"
    },
    {
      "x": 0,
      "y": 1,
      "z": 4,
      "name": "Empty"
    },
    {
      "x": 0,
      "y": 2,
      "z": 4,
      "name": "Empty"
    },
    {
      "x": 0,
      "y": 3,
      "z": 4,
      "name": "Empty"
    },
    {
      "x": 0,
      "y": 4,
      "z": 4,
      "name": "Cloth_Block_Wool_Black"
    },
    {
      "x": 0,
      "y": 0,
      "z": 5,
      "name": "Cloth_Block_Wool_Black"
    },
    {
      "x": 0,
      "y": 1,
      "z": 5,
      "name": "Empty"
    },
    {
      "x": 0,
      "y": 2,
      "z": 5,
      "name": "Empty"
    },
    {
      "x": 0,
      "y": 3,
      "z": 5,
      "name": "Empty"
    },
    {
      "x": 0,
      "y": 4,
      "z": 5,
      "name": "Cloth_Block_Wool_Black"
    },
    {
      "x": 0,
      "y": 0,
      "z": 6,
      "name": "Cloth_Block_Wool_Black"
    },
    {
      "x": 0,
      "y": 1,
      "z": 6,
      "name": "Prefab_Spawner_Block",
      "components": {
        "Components": {
          "PlacedByInteraction": {
            "WhoPlacedUuid": {
              "$binary": "DMiGy3J/TN6oy+22PsxJgw==",
              "$type": "04"
            }
          },
          "prefabspawner": {
            "PrefabPath": "Refresh_Studios\\Chest",
            "FitHeightmap": false,
            "InheritSeed": true,
            "InheritHeightCondition": true
          }
        }
      }
    },
    {
      "x": 0,
      "y": 2,
      "z": 6,
      "name": "Empty"
    },
    {
      "x": 0,
      "y": 3,
      "z": 6,
      "name": "Empty"
    },
    {
      "x": 0,
      "y": 4,
      "z": 6,
      "name": "Cloth_Block_Wool_Black"
    },
    {
      "x": 0,
      "y": 0,
      "z": 7,
      "name": "Cloth_Block_Wool_Black"
    },
    {
      "x": 0,
      "y": 1,
      "z": 7,
      "name": "Rock_Basalt_Brick"
    },
    {
      "x": 0,
      "y": 2,
      "z": 7,
      "name": "Rock_Basalt_Brick"
    },
    {
      "x": 0,
      "y": 3,
      "z": 7,
      "name": "Rock_Basalt_Brick"
    },
    {
      "x": 0,
      "y": 4,
      "z": 7,
      "name": "Cloth_Block_Wool_Black"
    },
    {
      "x": 1,
      "y": 0,
      "z": -7,
      "name": "Rock_Volcanic"
    },
    {
      "x": 1,
      "y": 1,
      "z": -7,
      "name": "Rock_Volcanic"
    },
    {
      "x": 1,
      "y": 2,
      "z": -7,
      "name": "Rock_Volcanic"
    },
    {
      "x": 1,
      "y": 3,
      "z": -7,
      "name": "Rock_Volcanic"
    },
    {
      "x": 1,
      "y": 4,
      "z": -7,
      "name": "Rock_Volcanic"
    },
    {
      "x": 1,
      "y": 0,
      "z": -6,
      "name": "Rock_Volcanic"
    },
    {
      "x": 1,
      "y": 1,
      "z": -6,
      "name": "Rock_Volcanic"
    },
    {
      "x": 1,
      "y": 2,
      "z": -6,
      "name": "Rock_Volcanic"
    },
    {
      "x": 1,
      "y": 3,
      "z": -6,
      "name": "Rock_Volcanic"
    },
    {
      "x": 1,
      "y": 4,
      "z": -6,
      "name": "Rock_Volcanic"
    },
    {
      "x": 1,
      "y": 0,
      "z": -5,
      "name": "Rock_Volcanic"
    },
    {
      "x": 1,
      "y": 1,
      "z": -5,
      "name": "Rock_Volcanic"
    },
    {
      "x": 1,
      "y": 2,
      "z": -5,
      "name": "Rock_Volcanic"
    },
    {
      "x": 1,
      "y": 3,
      "z": -5,
      "name": "Rock_Volcanic"
    },
    {
      "x": 1,
      "y": 4,
      "z": -5,
      "name": "Rock_Volcanic"
    },
    {
      "x": 1,
      "y": 0,
      "z": -4,
      "name": "Rock_Volcanic"
    },
    {
      "x": 1,
      "y": 1,
      "z": -4,
      "name": "Rock_Volcanic"
    },
    {
      "x": 1,
      "y": 2,
      "z": -4,
      "name": "Rock_Volcanic"
    },
    {
      "x": 1,
      "y": 3,
      "z": -4,
      "name": "Rock_Volcanic"
    },
    {
      "x": 1,
      "y": 4,
      "z": -4,
      "name": "Rock_Volcanic"
    },
    {
      "x": 1,
      "y": 0,
      "z": -3,
      "name": "Rock_Volcanic"
    },
    {
      "x": 1,
      "y": 1,
      "z": -3,
      "name": "Rock_Volcanic"
    },
    {
      "x": 1,
      "y": 2,
      "z": -3,
      "name": "Rock_Volcanic"
    },
    {
      "x": 1,
      "y": 3,
      "z": -3,
      "name": "Rock_Volcanic"
    },
    {
      "x": 1,
      "y": 4,
      "z": -3,
      "name": "Rock_Volcanic"
    },
    {
      "x": 1,
      "y": 0,
      "z": -2,
      "name": "Cloth_Block_Wool_Black"
    },
    {
      "x": 1,
      "y": 1,
      "z": -2,
      "name": "Rock_Basalt_Brick"
    },
    {
      "x": 1,
      "y": 2,
      "z": -2,
      "name": "Rock_Basalt_Brick"
    },
    {
      "x": 1,
      "y": 3,
      "z": -2,
      "name": "Rock_Basalt_Brick"
    },
    {
      "x": 1,
      "y": 4,
      "z": -2,
      "name": "Cloth_Block_Wool_Black"
    },
    {
      "x": 1,
      "y": 0,
      "z": -1,
      "name": "Cloth_Block_Wool_Black"
    },
    {
      "x": 1,
      "y": 1,
      "z": -1,
      "name": "Empty"
    },
    {
      "x": 1,
      "y": 2,
      "z": -1,
      "name": "Empty"
    },
    {
      "x": 1,
      "y": 3,
      "z": -1,
      "name": "Empty"
    },
    {
      "x": 1,
      "y": 4,
      "z": -1,
      "name": "Cloth_Block_Wool_Black"
    },
    {
      "x": 1,
      "y": 0,
      "z": 0,
      "name": "Cloth_Block_Wool_Black"
    },
    {
      "x": 1,
      "y": 1,
      "z": 0,
      "name": "Empty"
    },
    {
      "x": 1,
      "y": 2,
      "z": 0,
      "name": "Empty"
    },
    {
      "x": 1,
      "y": 3,
      "z": 0,
      "name": "Empty"
    },
    {
      "x": 1,
      "y": 4,
      "z": 0,
      "name": "Cloth_Block_Wool_Black"
    },
    {
      "x": 1,
      "y": 0,
      "z": 1,
      "name": "Cloth_Block_Wool_Black"
    },
    {
      "x": 1,
      "y": 1,
      "z": 1,
      "name": "Empty"
    },
    {
      "x": 1,
      "y": 2,
      "z": 1,
      "name": "Empty"
    },
    {
      "x": 1,
      "y": 3,
      "z": 1,
      "name": "Empty"
    },
    {
      "x": 1,
      "y": 4,
      "z": 1,
      "name": "Cloth_Block_Wool_Black"
    },
    {
      "x": 1,
      "y": 0,
      "z": 2,
      "name": "Cloth_Block_Wool_Black"
    },
    {
      "x": 1,
      "y": 1,
      "z": 2,
      "name": "Empty"
    },
    {
      "x": 1,
      "y": 2,
      "z": 2,
      "name": "Empty"
    },
    {
      "x": 1,
      "y": 3,
      "z": 2,
      "name": "Empty"
    },
    {
      "x": 1,
      "y": 4,
      "z": 2,
      "name": "Cloth_Block_Wool_Black"
    },
    {
      "x": 1,
      "y": 0,
      "z": 3,
      "name": "Cloth_Block_Wool_Black"
    },
    {
      "x": 1,
      "y": 1,
      "z": 3,
      "name": "Rock_Basalt_Brick"
    },
    {
      "x": 1,
      "y": 2,
      "z": 3,
      "name": "Rock_Basalt_Brick"
    },
    {
      "x": 1,
      "y": 3,
      "z": 3,
      "name": "Rock_Basalt_Brick"
    },
    {
      "x": 1,
      "y": 4,
      "z": 3,
      "name": "Cloth_Block_Wool_Black"
    },
    {
      "x": 1,
      "y": 0,
      "z": 4,
      "name": "Cloth_Block_Wool_Black"
    },
    {
      "x": 1,
      "y": 1,
      "z": 4,
      "name": "Empty"
    },
    {
      "x": 1,
      "y": 2,
      "z": 4,
      "name": "Empty"
    },
    {
      "x": 1,
      "y": 3,
      "z": 4,
      "name": "Empty"
    },
    {
      "x": 1,
      "y": 4,
      "z": 4,
      "name": "Cloth_Block_Wool_Black"
    },
    {
      "x": 1,
      "y": 0,
      "z": 5,
      "name": "Cloth_Block_Wool_Black"
    },
    {
      "x": 1,
      "y": 1,
      "z": 5,
      "name": "Empty"
    },
    {
      "x": 1,
      "y": 2,
      "z": 5,
      "name": "Empty"
    },
    {
      "x": 1,
      "y": 3,
      "z": 5,
      "name": "Empty"
    },
    {
      "x": 1,
      "y": 4,
      "z": 5,
      "name": "Cloth_Block_Wool_Black"
    },
    {
      "x": 1,
      "y": 0,
      "z": 6,
      "name": "Cloth_Block_Wool_Black"
    },
    {
      "x": 1,
      "y": 1,
      "z": 6,
      "name": "Empty"
    },
    {
      "x": 1,
      "y": 2,
      "z": 6,
      "name": "Empty"
    },
    {
      "x": 1,
      "y": 3,
      "z": 6,
      "name": "Empty"
    },
    {
      "x": 1,
      "y": 4,
      "z": 6,
      "name": "Cloth_Block_Wool_Black"
    },
    {
      "x": 1,
      "y": 0,
      "z": 7,
      "name": "Cloth_Block_Wool_Black"
    },
    {
      "x": 1,
      "y": 1,
      "z": 7,
      "name": "Rock_Basalt_Brick"
    },
    {
      "x": 1,
      "y": 2,
      "z": 7,
      "name": "Rock_Basalt_Brick"
    },
    {
      "x": 1,
      "y": 3,
      "z": 7,
      "name": "Rock_Basalt_Brick"
    },
    {
      "x": 1,
      "y": 4,
      "z": 7,
      "name": "Cloth_Block_Wool_Black"
    },
    {
      "x": 2,
      "y": 0,
      "z": -7,
      "name": "Rock_Volcanic"
    },
    {
      "x": 2,
      "y": 1,
      "z": -7,
      "name": "Rock_Volcanic"
    },
    {
      "x": 2,
      "y": 2,
      "z": -7,
      "name": "Rock_Volcanic"
    },
    {
      "x": 2,
      "y": 3,
      "z": -7,
      "name": "Rock_Volcanic"
    },
    {
      "x": 2,
      "y": 4,
      "z": -7,
      "name": "Rock_Volcanic"
    },
    {
      "x": 2,
      "y": 0,
      "z": -6,
      "name": "Rock_Volcanic"
    },
    {
      "x": 2,
      "y": 1,
      "z": -6,
      "name": "Rock_Volcanic"
    },
    {
      "x": 2,
      "y": 2,
      "z": -6,
      "name": "Rock_Volcanic"
    },
    {
      "x": 2,
      "y": 3,
      "z": -6,
      "name": "Rock_Volcanic"
    },
    {
      "x": 2,
      "y": 4,
      "z": -6,
      "name": "Rock_Volcanic"
    },
    {
      "x": 2,
      "y": 0,
      "z": -5,
      "name": "Rock_Volcanic"
    },
    {
      "x": 2,
      "y": 1,
      "z": -5,
      "name": "Rock_Volcanic"
    },
    {
      "x": 2,
      "y": 2,
      "z": -5,
      "name": "Rock_Volcanic"
    },
    {
      "x": 2,
      "y": 3,
      "z": -5,
      "name": "Rock_Volcanic"
    },
    {
      "x": 2,
      "y": 4,
      "z": -5,
      "name": "Rock_Volcanic"
    },
    {
      "x": 2,
      "y": 0,
      "z": -4,
      "name": "Rock_Volcanic"
    },
    {
      "x": 2,
      "y": 1,
      "z": -4,
      "name": "Rock_Volcanic"
    },
    {
      "x": 2,
      "y": 2,
      "z": -4,
      "name": "Rock_Volcanic"
    },
    {
      "x": 2,
      "y": 3,
      "z": -4,
      "name": "Rock_Volcanic"
    },
    {
      "x": 2,
      "y": 4,
      "z": -4,
      "name": "Rock_Volcanic"
    },
    {
      "x": 2,
      "y": 0,
      "z": -3,
      "name": "Rock_Volcanic"
    },
    {
      "x": 2,
      "y": 1,
      "z": -3,
      "name": "Rock_Volcanic"
    },
    {
      "x": 2,
      "y": 2,
      "z": -3,
      "name": "Rock_Volcanic"
    },
    {
      "x": 2,
      "y": 3,
      "z": -3,
      "name": "Rock_Volcanic"
    },
    {
      "x": 2,
      "y": 4,
      "z": -3,
      "name": "Rock_Volcanic"
    },
    {
      "x": 2,
      "y": 0,
      "z": -2,
      "name": "Cloth_Block_Wool_Black"
    },
    {
      "x": 2,
      "y": 1,
      "z": -2,
      "name": "Rock_Basalt_Brick"
    },
    {
      "x": 2,
      "y": 2,
      "z": -2,
      "name": "Rock_Basalt_Brick"
    },
    {
      "x": 2,
      "y": 3,
      "z": -2,
      "name": "Rock_Basalt_Brick"
    },
    {
      "x": 2,
      "y": 4,
      "z": -2,
      "name": "Cloth_Block_Wool_Black"
    },
    {
      "x": 2,
      "y": 0,
      "z": -1,
      "name": "Cloth_Block_Wool_Black"
    },
    {
      "x": 2,
      "y": 1,
      "z": -1,
      "name": "Empty"
    },
    {
      "x": 2,
      "y": 2,
      "z": -1,
      "name": "Empty"
    },
    {
      "x": 2,
      "y": 3,
      "z": -1,
      "name": "Wood_Torch_Wall"
    },
    {
      "x": 2,
      "y": 4,
      "z": -1,
      "name": "Cloth_Block_Wool_Black"
    },
    {
      "x": 2,
      "y": 0,
      "z": 0,
      "name": "Cloth_Block_Wool_Black"
    },
    {
      "x": 2,
      "y": 1,
      "z": 0,
      "name": "Empty"
    },
    {
      "x": 2,
      "y": 2,
      "z": 0,
      "name": "Empty"
    },
    {
      "x": 2,
      "y": 3,
      "z": 0,
      "name": "Empty"
    },
    {
      "x": 2,
      "y": 4,
      "z": 0,
      "name": "Cloth_Block_Wool_Black"
    },
    {
      "x": 2,
      "y": 0,
      "z": 1,
      "name": "Cloth_Block_Wool_Black"
    },
    {
      "x": 2,
      "y": 1,
      "z": 1,
      "name": "Empty"
    },
    {
      "x": 2,
      "y": 2,
      "z": 1,
      "name": "Empty"
    },
    {
      "x": 2,
      "y": 3,
      "z": 1,
      "name": "Empty"
    },
    {
      "x": 2,
      "y": 4,
      "z": 1,
      "name": "Cloth_Block_Wool_Black"
    },
    {
      "x": 2,
      "y": 0,
      "z": 2,
      "name": "Cloth_Block_Wool_Black"
    },
    {
      "x": 2,
      "y": 1,
      "z": 2,
      "name": "Empty"
    },
    {
      "x": 2,
      "y": 2,
      "z": 2,
      "name": "Empty"
    },
    {
      "x": 2,
      "y": 3,
      "z": 2,
      "name": "Wood_Torch_Wall",
      "rotation": 2
    },
    {
      "x": 2,
      "y": 4,
      "z": 2,
      "name": "Cloth_Block_Wool_Black"
    },
    {
      "x": 2,
      "y": 0,
      "z": 3,
      "name": "Cloth_Block_Wool_Black"
    },
    {
      "x": 2,
      "y": 1,
      "z": 3,
      "name": "Rock_Basalt_Brick"
    },
    {
      "x": 2,
      "y": 2,
      "z": 3,
      "name": "Rock_Basalt_Brick"
    },
    {
      "x": 2,
      "y": 3,
      "z": 3,
      "name": "Rock_Basalt_Brick"
    },
    {
      "x": 2,
      "y": 4,
      "z": 3,
      "name": "Cloth_Block_Wool_Black"
    },
    {
      "x": 2,
      "y": 0,
      "z": 4,
      "name": "Cloth_Block_Wool_Black"
    },
    {
      "x": 2,
      "y": 1,
      "z": 4,
      "name": "Empty"
    },
    {
      "x": 2,
      "y": 2,
      "z": 4,
      "name": "Empty"
    },
    {
      "x": 2,
      "y": 3,
      "z": 4,
      "name": "Empty"
    },
    {
      "x": 2,
      "y": 4,
      "z": 4,
      "name": "Cloth_Block_Wool_Black"
    },
    {
      "x": 2,
      "y": 0,
      "z": 5,
      "name": "Cloth_Block_Wool_Black"
    },
    {
      "x": 2,
      "y": 1,
      "z": 5,
      "name": "Empty"
    },
    {
      "x": 2,
      "y": 2,
      "z": 5,
      "name": "Empty"
    },
    {
      "x": 2,
      "y": 3,
      "z": 5,
      "name": "Empty"
    },
    {
      "x": 2,
      "y": 4,
      "z": 5,
      "name": "Cloth_Block_Wool_Black"
    },
    {
      "x": 2,
      "y": 0,
      "z": 6,
      "name": "Cloth_Block_Wool_Black"
    },
    {
      "x": 2,
      "y": 1,
      "z": 6,
      "name": "Empty"
    },
    {
      "x": 2,
      "y": 2,
      "z": 6,
      "name": "Empty"
    },
    {
      "x": 2,
      "y": 3,
      "z": 6,
      "name": "Empty"
    },
    {
      "x": 2,
      "y": 4,
      "z": 6,
      "name": "Cloth_Block_Wool_Black"
    },
    {
      "x": 2,
      "y": 0,
      "z": 7,
      "name": "Cloth_Block_Wool_Black"
    },
    {
      "x": 2,
      "y": 1,
      "z": 7,
      "name": "Rock_Basalt_Brick"
    },
    {
      "x": 2,
      "y": 2,
      "z": 7,
      "name": "Rock_Basalt_Brick"
    },
    {
      "x": 2,
      "y": 3,
      "z": 7,
      "name": "Rock_Basalt_Brick"
    },
    {
      "x": 2,
      "y": 4,
      "z": 7,
      "name": "Cloth_Block_Wool_Black"
    },
    {
      "x": 3,
      "y": 0,
      "z": -7,
      "name": "Cloth_Block_Wool_Black"
    },
    {
      "x": 3,
      "y": 1,
      "z": -7,
      "name": "Cloth_Block_Wool_Black"
    },
    {
      "x": 3,
      "y": 2,
      "z": -7,
      "name": "Cloth_Block_Wool_Black"
    },
    {
      "x": 3,
      "y": 3,
      "z": -7,
      "name": "Cloth_Block_Wool_Black"
    },
    {
      "x": 3,
      "y": 4,
      "z": -7,
      "name": "Cloth_Block_Wool_Black"
    },
    {
      "x": 3,
      "y": 0,
      "z": -6,
      "name": "Cloth_Block_Wool_Black"
    },
    {
      "x": 3,
      "y": 1,
      "z": -6,
      "name": "Rock_Basalt_Brick"
    },
    {
      "x": 3,
      "y": 2,
      "z": -6,
      "name": "Rock_Basalt_Brick"
    },
    {
      "x": 3,
      "y": 3,
      "z": -6,
      "name": "Rock_Basalt_Brick"
    },
    {
      "x": 3,
      "y": 4,
      "z": -6,
      "name": "Cloth_Block_Wool_Black"
    },
    {
      "x": 3,
      "y": 0,
      "z": -5,
      "name": "Cloth_Block_Wool_Black"
    },
    {
      "x": 3,
      "y": 1,
      "z": -5,
      "name": "Rock_Basalt_Brick"
    },
    {
      "x": 3,
      "y": 2,
      "z": -5,
      "name": "Rock_Basalt_Brick"
    },
    {
      "x": 3,
      "y": 3,
      "z": -5,
      "name": "Rock_Basalt_Brick"
    },
    {
      "x": 3,
      "y": 4,
      "z": -5,
      "name": "Cloth_Block_Wool_Black"
    },
    {
      "x": 3,
      "y": 0,
      "z": -4,
      "name": "Cloth_Block_Wool_Black"
    },
    {
      "x": 3,
      "y": 1,
      "z": -4,
      "name": "Rock_Basalt_Brick"
    },
    {
      "x": 3,
      "y": 2,
      "z": -4,
      "name": "Rock_Basalt_Brick"
    },
    {
      "x": 3,
      "y": 3,
      "z": -4,
      "name": "Rock_Basalt_Brick"
    },
    {
      "x": 3,
      "y": 4,
      "z": -4,
      "name": "Cloth_Block_Wool_Black"
    },
    {
      "x": 3,
      "y": 0,
      "z": -3,
      "name": "Cloth_Block_Wool_Black"
    },
    {
      "x": 3,
      "y": 1,
      "z": -3,
      "name": "Rock_Basalt_Brick"
    },
    {
      "x": 3,
      "y": 2,
      "z": -3,
      "name": "Rock_Basalt_Brick"
    },
    {
      "x": 3,
      "y": 3,
      "z": -3,
      "name": "Rock_Basalt_Brick"
    },
    {
      "x": 3,
      "y": 4,
      "z": -3,
      "name": "Cloth_Block_Wool_Black"
    },
    {
      "x": 3,
      "y": 0,
      "z": -2,
      "name": "Cloth_Block_Wool_Black"
    },
    {
      "x": 3,
      "y": 1,
      "z": -2,
      "name": "Cloth_Block_Wool_Black"
    },
    {
      "x": 3,
      "y": 2,
      "z": -2,
      "name": "Cloth_Block_Wool_Black"
    },
    {
      "x": 3,
      "y": 3,
      "z": -2,
      "name": "Cloth_Block_Wool_Black"
    },
    {
      "x": 3,
      "y": 4,
      "z": -2,
      "name": "Cloth_Block_Wool_Black"
    },
    {
      "x": 3,
      "y": 0,
      "z": -1,
      "name": "Cloth_Block_Wool_Black"
    },
    {
      "x": 3,
      "y": 1,
      "z": -1,
      "name": "Rock_Basalt_Brick"
    },
    {
      "x": 3,
      "y": 2,
      "z": -1,
      "name": "Rock_Basalt_Brick"
    },
    {
      "x": 3,
      "y": 3,
      "z": -1,
      "name": "Rock_Basalt_Brick"
    },
    {
      "x": 3,
      "y": 4,
      "z": -1,
      "name": "Cloth_Block_Wool_Black"
    },
    {
      "x": 3,
      "y": 0,
      "z": 0,
      "name": "Cloth_Block_Wool_Black"
    },
    {
      "x": 3,
      "y": 1,
      "z": 0,
      "name": "Rock_Basalt_Brick"
    },
    {
      "x": 3,
      "y": 2,
      "z": 0,
      "name": "Rock_Basalt_Brick"
    },
    {
      "x": 3,
      "y": 3,
      "z": 0,
      "name": "Rock_Basalt_Brick"
    },
    {
      "x": 3,
      "y": 4,
      "z": 0,
      "name": "Cloth_Block_Wool_Black"
    },
    {
      "x": 3,
      "y": 0,
      "z": 1,
      "name": "Cloth_Block_Wool_Black"
    },
    {
      "x": 3,
      "y": 1,
      "z": 1,
      "name": "Rock_Basalt_Brick"
    },
    {
      "x": 3,
      "y": 2,
      "z": 1,
      "name": "Rock_Basalt_Brick"
    },
    {
      "x": 3,
      "y": 3,
      "z": 1,
      "name": "Rock_Basalt_Brick"
    },
    {
      "x": 3,
      "y": 4,
      "z": 1,
      "name": "Cloth_Block_Wool_Black"
    },
    {
      "x": 3,
      "y": 0,
      "z": 2,
      "name": "Cloth_Block_Wool_Black"
    },
    {
      "x": 3,
      "y": 1,
      "z": 2,
      "name": "Rock_Basalt_Brick"
    },
    {
      "x": 3,
      "y": 2,
      "z": 2,
      "name": "Rock_Basalt_Brick"
    },
    {
      "x": 3,
      "y": 3,
      "z": 2,
      "name": "Rock_Basalt_Brick"
    },
    {
      "x": 3,
      "y": 4,
      "z": 2,
      "name": "Cloth_Block_Wool_Black"
    },
    {
      "x": 3,
      "y": 0,
      "z": 3,
      "name": "Cloth_Block_Wool_Black"
    },
    {
      "x": 3,
      "y": 1,
      "z": 3,
      "name": "Rock_Basalt_Brick"
    },
    {
      "x": 3,
      "y": 2,
      "z": 3,
      "name": "Rock_Basalt_Brick"
    },
    {
      "x": 3,
      "y": 3,
      "z": 3,
      "name": "Rock_Basalt_Brick"
    },
    {
      "x": 3,
      "y": 4,
      "z": 3,
      "name": "Cloth_Block_Wool_Black"
    },
    {
      "x": 3,
      "y": 0,
      "z": 4,
      "name": "Cloth_Block_Wool_Black"
    },
    {
      "x": 3,
      "y": 1,
      "z": 4,
      "name": "*Furniture_Ancient_Door_State_Definitions_CloseDoorOut",
      "rotation": 1
    },
    {
      "x": 3,
      "y": 2,
      "z": 4,
      "name": "*Furniture_Ancient_Door_State_Definitions_CloseDoorOut",
      "filler": 1024,
      "rotation": 1
    },
    {
      "x": 3,
      "y": 3,
      "z": 4,
      "name": "Rock_Basalt_Brick"
    },
    {
      "x": 3,
      "y": 4,
      "z": 4,
      "name": "Cloth_Block_Wool_Black"
    },
    {
      "x": 3,
      "y": 0,
      "z": 5,
      "name": "Cloth_Block_Wool_Black"
    },
    {
      "x": 3,
      "y": 1,
      "z": 5,
      "name": "Rock_Basalt_Brick"
    },
    {
      "x": 3,
      "y": 2,
      "z": 5,
      "name": "Rock_Basalt_Brick"
    },
    {
      "x": 3,
      "y": 3,
      "z": 5,
      "name": "Rock_Basalt_Brick"
    },
    {
      "x": 3,
      "y": 4,
      "z": 5,
      "name": "Cloth_Block_Wool_Black"
    },
    {
      "x": 3,
      "y": 0,
      "z": 6,
      "name": "Cloth_Block_Wool_Black"
    },
    {
      "x": 3,
      "y": 1,
      "z": 6,
      "name": "Rock_Basalt_Brick"
    },
    {
      "x": 3,
      "y": 2,
      "z": 6,
      "name": "Rock_Basalt_Brick"
    },
    {
      "x": 3,
      "y": 3,
      "z": 6,
      "name": "Rock_Basalt_Brick"
    },
    {
      "x": 3,
      "y": 4,
      "z": 6,
      "name": "Cloth_Block_Wool_Black"
    },
    {
      "x": 3,
      "y": 0,
      "z": 7,
      "name": "Cloth_Block_Wool_Black"
    },
    {
      "x": 3,
      "y": 1,
      "z": 7,
      "name": "Cloth_Block_Wool_Black"
    },
    {
      "x": 3,
      "y": 2,
      "z": 7,
      "name": "Cloth_Block_Wool_Black"
    },
    {
      "x": 3,
      "y": 3,
      "z": 7,
      "name": "Cloth_Block_Wool_Black"
    },
    {
      "x": 3,
      "y": 4,
      "z": 7,
      "name": "Cloth_Block_Wool_Black"
    },
    {
      "x": 4,
      "y": 0,
      "z": -7,
      "name": "Cloth_Block_Wool_Black"
    },
    {
      "x": 4,
      "y": 1,
      "z": -7,
      "name": "Rock_Basalt_Brick"
    },
    {
      "x": 4,
      "y": 2,
      "z": -7,
      "name": "Rock_Basalt_Brick"
    },
    {
      "x": 4,
      "y": 3,
      "z": -7,
      "name": "Rock_Basalt_Brick"
    },
    {
      "x": 4,
      "y": 4,
      "z": -7,
      "name": "Cloth_Block_Wool_Black"
    },
    {
      "x": 4,
      "y": 0,
      "z": -6,
      "name": "Cloth_Block_Wool_Black"
    },
    {
      "x": 4,
      "y": 1,
      "z": -6,
      "name": "Empty"
    },
    {
      "x": 4,
      "y": 2,
      "z": -6,
      "name": "Empty"
    },
    {
      "x": 4,
      "y": 3,
      "z": -6,
      "name": "Wood_Torch_Wall",
      "rotation": 1
    },
    {
      "x": 4,
      "y": 4,
      "z": -6,
      "name": "Cloth_Block_Wool_Black"
    },
    {
      "x": 4,
      "y": 0,
      "z": -5,
      "name": "Cloth_Block_Wool_Black"
    },
    {
      "x": 4,
      "y": 1,
      "z": -5,
      "name": "Empty"
    },
    {
      "x": 4,
      "y": 2,
      "z": -5,
      "name": "Empty"
    },
    {
      "x": 4,
      "y": 3,
      "z": -5,
      "name": "Empty"
    },
    {
      "x": 4,
      "y": 4,
      "z": -5,
      "name": "Cloth_Block_Wool_Black"
    },
    {
      "x": 4,
      "y": 0,
      "z": -4,
      "name": "Cloth_Block_Wool_Black"
    },
    {
      "x": 4,
      "y": 1,
      "z": -4,
      "name": "Empty"
    },
    {
      "x": 4,
      "y": 2,
      "z": -4,
      "name": "Empty"
    },
    {
      "x": 4,
      "y": 3,
      "z": -4,
      "name": "Empty"
    },
    {
      "x": 4,
      "y": 4,
      "z": -4,
      "name": "Cloth_Block_Wool_Black"
    },
    {
      "x": 4,
      "y": 0,
      "z": -3,
      "name": "Cloth_Block_Wool_Black"
    },
    {
      "x": 4,
      "y": 1,
      "z": -3,
      "name": "Empty"
    },
    {
      "x": 4,
      "y": 2,
      "z": -3,
      "name": "Empty"
    },
    {
      "x": 4,
      "y": 3,
      "z": -3,
      "name": "Empty"
    },
    {
      "x": 4,
      "y": 4,
      "z": -3,
      "name": "Cloth_Block_Wool_Black"
    },
    {
      "x": 4,
      "y": 0,
      "z": -2,
      "name": "Cloth_Block_Wool_Black"
    },
    {
      "x": 4,
      "y": 1,
      "z": -2,
      "name": "Empty"
    },
    {
      "x": 4,
      "y": 2,
      "z": -2,
      "name": "Empty"
    },
    {
      "x": 4,
      "y": 3,
      "z": -2,
      "name": "Wood_Torch_Wall",
      "rotation": 1
    },
    {
      "x": 4,
      "y": 4,
      "z": -2,
      "name": "Cloth_Block_Wool_Black"
    },
    {
      "x": 4,
      "y": 0,
      "z": -1,
      "name": "Cloth_Block_Wool_Black"
    },
    {
      "x": 4,
      "y": 1,
      "z": -1,
      "name": "Empty"
    },
    {
      "x": 4,
      "y": 2,
      "z": -1,
      "name": "Empty"
    },
    {
      "x": 4,
      "y": 3,
      "z": -1,
      "name": "Empty"
    },
    {
      "x": 4,
      "y": 4,
      "z": -1,
      "name": "Cloth_Block_Wool_Black"
    },
    {
      "x": 4,
      "y": 0,
      "z": 0,
      "name": "Cloth_Block_Wool_Black"
    },
    {
      "x": 4,
      "y": 1,
      "z": 0,
      "name": "Empty"
    },
    {
      "x": 4,
      "y": 2,
      "z": 0,
      "name": "Empty"
    },
    {
      "x": 4,
      "y": 3,
      "z": 0,
      "name": "Empty"
    },
    {
      "x": 4,
      "y": 4,
      "z": 0,
      "name": "Cloth_Block_Wool_Black"
    },
    {
      "x": 4,
      "y": 0,
      "z": 1,
      "name": "Cloth_Block_Wool_Black"
    },
    {
      "x": 4,
      "y": 1,
      "z": 1,
      "name": "Empty"
    },
    {
      "x": 4,
      "y": 2,
      "z": 1,
      "name": "Empty"
    },
    {
      "x": 4,
      "y": 3,
      "z": 1,
      "name": "Empty"
    },
    {
      "x": 4,
      "y": 4,
      "z": 1,
      "name": "Cloth_Block_Wool_Black"
    },
    {
      "x": 4,
      "y": 0,
      "z": 2,
      "name": "Cloth_Block_Wool_Black"
    },
    {
      "x": 4,
      "y": 1,
      "z": 2,
      "name": "Empty"
    },
    {
      "x": 4,
      "y": 2,
      "z": 2,
      "name": "Empty"
    },
    {
      "x": 4,
      "y": 3,
      "z": 2,
      "name": "Empty"
    },
    {
      "x": 4,
      "y": 4,
      "z": 2,
      "name": "Cloth_Block_Wool_Black"
    },
    {
      "x": 4,
      "y": 0,
      "z": 3,
      "name": "Cloth_Block_Wool_Black"
    },
    {
      "x": 4,
      "y": 1,
      "z": 3,
      "name": "Empty"
    },
    {
      "x": 4,
      "y": 2,
      "z": 3,
      "name": "Empty"
    },
    {
      "x": 4,
      "y": 3,
      "z": 3,
      "name": "Wood_Torch_Wall",
      "rotation": 1
    },
    {
      "x": 4,
      "y": 4,
      "z": 3,
      "name": "Cloth_Block_Wool_Black"
    },
    {
      "x": 4,
      "y": 0,
      "z": 4,
      "name": "Cloth_Block_Wool_Black"
    },
    {
      "x": 4,
      "y": 1,
      "z": 4,
      "name": "Empty"
    },
    {
      "x": 4,
      "y": 2,
      "z": 4,
      "name": "Empty"
    },
    {
      "x": 4,
      "y": 3,
      "z": 4,
      "name": "Empty"
    },
    {
      "x": 4,
      "y": 4,
      "z": 4,
      "name": "Cloth_Block_Wool_Black"
    },
    {
      "x": 4,
      "y": 0,
      "z": 5,
      "name": "Cloth_Block_Wool_Black"
    },
    {
      "x": 4,
      "y": 1,
      "z": 5,
      "name": "Empty"
    },
    {
      "x": 4,
      "y": 2,
      "z": 5,
      "name": "Empty"
    },
    {
      "x": 4,
      "y": 3,
      "z": 5,
      "name": "Empty"
    },
    {
      "x": 4,
      "y": 4,
      "z": 5,
      "name": "Cloth_Block_Wool_Black"
    },
    {
      "x": 4,
      "y": 0,
      "z": 6,
      "name": "Cloth_Block_Wool_Black"
    },
    {
      "x": 4,
      "y": 1,
      "z": 6,
      "name": "Empty"
    },
    {
      "x": 4,
      "y": 2,
      "z": 6,
      "name": "Empty"
    },
    {
      "x": 4,
      "y": 3,
      "z": 6,
      "name": "Empty"
    },
    {
      "x": 4,
      "y": 4,
      "z": 6,
      "name": "Cloth_Block_Wool_Black"
    },
    {
      "x": 4,
      "y": 0,
      "z": 7,
      "name": "Cloth_Block_Wool_Black"
    },
    {
      "x": 4,
      "y": 1,
      "z": 7,
      "name": "Rock_Basalt_Brick"
    },
    {
      "x": 4,
      "y": 2,
      "z": 7,
      "name": "Rock_Basalt_Brick"
    },
    {
      "x": 4,
      "y": 3,
      "z": 7,
      "name": "Rock_Basalt_Brick"
    },
    {
      "x": 4,
      "y": 4,
      "z": 7,
      "name": "Cloth_Block_Wool_Black"
    },
    {
      "x": 5,
      "y": 0,
      "z": -7,
      "name": "Cloth_Block_Wool_Black"
    },
    {
      "x": 5,
      "y": 1,
      "z": -7,
      "name": "Rock_Basalt_Brick"
    },
    {
      "x": 5,
      "y": 2,
      "z": -7,
      "name": "Rock_Basalt_Brick"
    },
    {
      "x": 5,
      "y": 3,
      "z": -7,
      "name": "Rock_Basalt_Brick"
    },
    {
      "x": 5,
      "y": 4,
      "z": -7,
      "name": "Cloth_Block_Wool_Black"
    },
    {
      "x": 5,
      "y": 0,
      "z": -6,
      "name": "Cloth_Block_Wool_Black"
    },
    {
      "x": 5,
      "y": 1,
      "z": -6,
      "name": "Empty"
    },
    {
      "x": 5,
      "y": 2,
      "z": -6,
      "name": "Empty"
    },
    {
      "x": 5,
      "y": 3,
      "z": -6,
      "name": "Empty"
    },
    {
      "x": 5,
      "y": 4,
      "z": -6,
      "name": "Cloth_Block_Wool_Black"
    },
    {
      "x": 5,
      "y": 0,
      "z": -5,
      "name": "Cloth_Block_Wool_Black"
    },
    {
      "x": 5,
      "y": 1,
      "z": -5,
      "name": "Empty"
    },
    {
      "x": 5,
      "y": 2,
      "z": -5,
      "name": "Empty"
    },
    {
      "x": 5,
      "y": 3,
      "z": -5,
      "name": "Empty"
    },
    {
      "x": 5,
      "y": 4,
      "z": -5,
      "name": "Cloth_Block_Wool_Black"
    },
    {
      "x": 5,
      "y": 0,
      "z": -4,
      "name": "Cloth_Block_Wool_Black"
    },
    {
      "x": 5,
      "y": 1,
      "z": -4,
      "name": "Empty"
    },
    {
      "x": 5,
      "y": 2,
      "z": -4,
      "name": "Empty"
    },
    {
      "x": 5,
      "y": 3,
      "z": -4,
      "name": "Empty"
    },
    {
      "x": 5,
      "y": 4,
      "z": -4,
      "name": "Cloth_Block_Wool_Black"
    },
    {
      "x": 5,
      "y": 0,
      "z": -3,
      "name": "Cloth_Block_Wool_Black"
    },
    {
      "x": 5,
      "y": 1,
      "z": -3,
      "name": "Empty"
    },
    {
      "x": 5,
      "y": 2,
      "z": -3,
      "name": "Empty"
    },
    {
      "x": 5,
      "y": 3,
      "z": -3,
      "name": "Empty"
    },
    {
      "x": 5,
      "y": 4,
      "z": -3,
      "name": "Cloth_Block_Wool_Black"
    },
    {
      "x": 5,
      "y": 0,
      "z": -2,
      "name": "Cloth_Block_Wool_Black"
    },
    {
      "x": 5,
      "y": 1,
      "z": -2,
      "name": "Empty"
    },
    {
      "x": 5,
      "y": 2,
      "z": -2,
      "name": "Empty"
    },
    {
      "x": 5,
      "y": 3,
      "z": -2,
      "name": "Empty"
    },
    {
      "x": 5,
      "y": 4,
      "z": -2,
      "name": "Cloth_Block_Wool_Black"
    },
    {
      "x": 5,
      "y": 0,
      "z": -1,
      "name": "Cloth_Block_Wool_Black"
    },
    {
      "x": 5,
      "y": 1,
      "z": -1,
      "name": "Empty"
    },
    {
      "x": 5,
      "y": 2,
      "z": -1,
      "name": "Empty"
    },
    {
      "x": 5,
      "y": 3,
      "z": -1,
      "name": "Empty"
    },
    {
      "x": 5,
      "y": 4,
      "z": -1,
      "name": "Cloth_Block_Wool_Black"
    },
    {
      "x": 5,
      "y": 0,
      "z": 0,
      "name": "Cloth_Block_Wool_Black"
    },
    {
      "x": 5,
      "y": 1,
      "z": 0,
      "name": "Empty"
    },
    {
      "x": 5,
      "y": 2,
      "z": 0,
      "name": "Empty"
    },
    {
      "x": 5,
      "y": 3,
      "z": 0,
      "name": "Empty"
    },
    {
      "x": 5,
      "y": 4,
      "z": 0,
      "name": "Cloth_Block_Wool_Black"
    },
    {
      "x": 5,
      "y": 0,
      "z": 1,
      "name": "Cloth_Block_Wool_Black"
    },
    {
      "x": 5,
      "y": 1,
      "z": 1,
      "name": "Empty"
    },
    {
      "x": 5,
      "y": 2,
      "z": 1,
      "name": "Empty"
    },
    {
      "x": 5,
      "y": 3,
      "z": 1,
      "name": "Empty"
    },
    {
      "x": 5,
      "y": 4,
      "z": 1,
      "name": "Cloth_Block_Wool_Black"
    },
    {
      "x": 5,
      "y": 0,
      "z": 2,
      "name": "Cloth_Block_Wool_Black"
    },
    {
      "x": 5,
      "y": 1,
      "z": 2,
      "name": "Empty"
    },
    {
      "x": 5,
      "y": 2,
      "z": 2,
      "name": "Empty"
    },
    {
      "x": 5,
      "y": 3,
      "z": 2,
      "name": "Empty"
    },
    {
      "x": 5,
      "y": 4,
      "z": 2,
      "name": "Cloth_Block_Wool_Black"
    },
    {
      "x": 5,
      "y": 0,
      "z": 3,
      "name": "Cloth_Block_Wool_Black"
    },
    {
      "x": 5,
      "y": 1,
      "z": 3,
      "name": "Empty"
    },
    {
      "x": 5,
      "y": 2,
      "z": 3,
      "name": "Empty"
    },
    {
      "x": 5,
      "y": 3,
      "z": 3,
      "name": "Empty"
    },
    {
      "x": 5,
      "y": 4,
      "z": 3,
      "name": "Cloth_Block_Wool_Black"
    },
    {
      "x": 5,
      "y": 0,
      "z": 4,
      "name": "Cloth_Block_Wool_Black"
    },
    {
      "x": 5,
      "y": 1,
      "z": 4,
      "name": "Empty"
    },
    {
      "x": 5,
      "y": 2,
      "z": 4,
      "name": "Empty"
    },
    {
      "x": 5,
      "y": 3,
      "z": 4,
      "name": "Empty"
    },
    {
      "x": 5,
      "y": 4,
      "z": 4,
      "name": "Cloth_Block_Wool_Black"
    },
    {
      "x": 5,
      "y": 0,
      "z": 5,
      "name": "Cloth_Block_Wool_Black"
    },
    {
      "x": 5,
      "y": 1,
      "z": 5,
      "name": "Empty"
    },
    {
      "x": 5,
      "y": 2,
      "z": 5,
      "name": "Empty"
    },
    {
      "x": 5,
      "y": 3,
      "z": 5,
      "name": "Empty"
    },
    {
      "x": 5,
      "y": 4,
      "z": 5,
      "name": "Cloth_Block_Wool_Black"
    },
    {
      "x": 5,
      "y": 0,
      "z": 6,
      "name": "Cloth_Block_Wool_Black"
    },
    {
      "x": 5,
      "y": 1,
      "z": 6,
      "name": "Empty"
    },
    {
      "x": 5,
      "y": 2,
      "z": 6,
      "name": "Empty"
    },
    {
      "x": 5,
      "y": 3,
      "z": 6,
      "name": "Empty"
    },
    {
      "x": 5,
      "y": 4,
      "z": 6,
      "name": "Cloth_Block_Wool_Black"
    },
    {
      "x": 5,
      "y": 0,
      "z": 7,
      "name": "Cloth_Block_Wool_Black"
    },
    {
      "x": 5,
      "y": 1,
      "z": 7,
      "name": "Rock_Basalt_Brick"
    },
    {
      "x": 5,
      "y": 2,
      "z": 7,
      "name": "Rock_Basalt_Brick"
    },
    {
      "x": 5,
      "y": 3,
      "z": 7,
      "name": "Rock_Basalt_Brick"
    },
    {
      "x": 5,
      "y": 4,
      "z": 7,
      "name": "Cloth_Block_Wool_Black"
    },
    {
      "x": 6,
      "y": 0,
      "z": -7,
      "name": "Cloth_Block_Wool_Black"
    },
    {
      "x": 6,
      "y": 1,
      "z": -7,
      "name": "Rock_Basalt_Brick"
    },
    {
      "x": 6,
      "y": 2,
      "z": -7,
      "name": "Rock_Basalt_Brick"
    },
    {
      "x": 6,
      "y": 3,
      "z": -7,
      "name": "Rock_Basalt_Brick"
    },
    {
      "x": 6,
      "y": 4,
      "z": -7,
      "name": "Cloth_Block_Wool_Black"
    },
    {
      "x": 6,
      "y": 0,
      "z": -6,
      "name": "Cloth_Block_Wool_Black"
    },
    {
      "x": 6,
      "y": 1,
      "z": -6,
      "name": "Empty"
    },
    {
      "x": 6,
      "y": 2,
      "z": -6,
      "name": "Empty"
    },
    {
      "x": 6,
      "y": 3,
      "z": -6,
      "name": "Empty"
    },
    {
      "x": 6,
      "y": 4,
      "z": -6,
      "name": "Cloth_Block_Wool_Black"
    },
    {
      "x": 6,
      "y": 0,
      "z": -5,
      "name": "Cloth_Block_Wool_Black"
    },
    {
      "x": 6,
      "y": 1,
      "z": -5,
      "name": "Empty"
    },
    {
      "x": 6,
      "y": 2,
      "z": -5,
      "name": "Empty"
    },
    {
      "x": 6,
      "y": 3,
      "z": -5,
      "name": "Empty"
    },
    {
      "x": 6,
      "y": 4,
      "z": -5,
      "name": "Cloth_Block_Wool_Black"
    },
    {
      "x": 6,
      "y": 0,
      "z": -4,
      "name": "Cloth_Block_Wool_Black"
    },
    {
      "x": 6,
      "y": 1,
      "z": -4,
      "name": "Empty"
    },
    {
      "x": 6,
      "y": 2,
      "z": -4,
      "name": "Empty"
    },
    {
      "x": 6,
      "y": 3,
      "z": -4,
      "name": "Empty"
    },
    {
      "x": 6,
      "y": 4,
      "z": -4,
      "name": "Cloth_Block_Wool_Black"
    },
    {
      "x": 6,
      "y": 0,
      "z": -3,
      "name": "Cloth_Block_Wool_Black"
    },
    {
      "x": 6,
      "y": 1,
      "z": -3,
      "name": "Empty"
    },
    {
      "x": 6,
      "y": 2,
      "z": -3,
      "name": "Empty"
    },
    {
      "x": 6,
      "y": 3,
      "z": -3,
      "name": "Empty"
    },
    {
      "x": 6,
      "y": 4,
      "z": -3,
      "name": "Cloth_Block_Wool_Black"
    },
    {
      "x": 6,
      "y": 0,
      "z": -2,
      "name": "Cloth_Block_Wool_Black"
    },
    {
      "x": 6,
      "y": 1,
      "z": -2,
      "name": "Empty"
    },
    {
      "x": 6,
      "y": 2,
      "z": -2,
      "name": "Empty"
    },
    {
      "x": 6,
      "y": 3,
      "z": -2,
      "name": "Empty"
    },
    {
      "x": 6,
      "y": 4,
      "z": -2,
      "name": "Cloth_Block_Wool_Black"
    },
    {
      "x": 6,
      "y": 0,
      "z": -1,
      "name": "Cloth_Block_Wool_Black"
    },
    {
      "x": 6,
      "y": 1,
      "z": -1,
      "name": "Empty"
    },
    {
      "x": 6,
      "y": 2,
      "z": -1,
      "name": "Empty"
    },
    {
      "x": 6,
      "y": 3,
      "z": -1,
      "name": "Empty"
    },
    {
      "x": 6,
      "y": 4,
      "z": -1,
      "name": "Cloth_Block_Wool_Black"
    },
    {
      "x": 6,
      "y": 0,
      "z": 0,
      "name": "Cloth_Block_Wool_Black"
    },
    {
      "x": 6,
      "y": 1,
      "z": 0,
      "name": "Empty"
    },
    {
      "x": 6,
      "y": 2,
      "z": 0,
      "name": "Empty"
    },
    {
      "x": 6,
      "y": 3,
      "z": 0,
      "name": "Empty"
    },
    {
      "x": 6,
      "y": 4,
      "z": 0,
      "name": "Cloth_Block_Wool_Black"
    },
    {
      "x": 6,
      "y": 0,
      "z": 1,
      "name": "Cloth_Block_Wool_Black"
    },
    {
      "x": 6,
      "y": 1,
      "z": 1,
      "name": "Empty"
    },
    {
      "x": 6,
      "y": 2,
      "z": 1,
      "name": "Empty"
    },
    {
      "x": 6,
      "y": 3,
      "z": 1,
      "name": "Empty"
    },
    {
      "x": 6,
      "y": 4,
      "z": 1,
      "name": "Cloth_Block_Wool_Black"
    },
    {
      "x": 6,
      "y": 0,
      "z": 2,
      "name": "Cloth_Block_Wool_Black"
    },
    {
      "x": 6,
      "y": 1,
      "z": 2,
      "name": "Empty"
    },
    {
      "x": 6,
      "y": 2,
      "z": 2,
      "name": "Empty"
    },
    {
      "x": 6,
      "y": 3,
      "z": 2,
      "name": "Empty"
    },
    {
      "x": 6,
      "y": 4,
      "z": 2,
      "name": "Cloth_Block_Wool_Black"
    },
    {
      "x": 6,
      "y": 0,
      "z": 3,
      "name": "Cloth_Block_Wool_Black"
    },
    {
      "x": 6,
      "y": 1,
      "z": 3,
      "name": "Empty"
    },
    {
      "x": 6,
      "y": 2,
      "z": 3,
      "name": "Empty"
    },
    {
      "x": 6,
      "y": 3,
      "z": 3,
      "name": "Empty"
    },
    {
      "x": 6,
      "y": 4,
      "z": 3,
      "name": "Cloth_Block_Wool_Black"
    },
    {
      "x": 6,
      "y": 0,
      "z": 4,
      "name": "Cloth_Block_Wool_Black"
    },
    {
      "x": 6,
      "y": 1,
      "z": 4,
      "name": "Empty"
    },
    {
      "x": 6,
      "y": 2,
      "z": 4,
      "name": "Empty"
    },
    {
      "x": 6,
      "y": 3,
      "z": 4,
      "name": "Empty"
    },
    {
      "x": 6,
      "y": 4,
      "z": 4,
      "name": "Cloth_Block_Wool_Black"
    },
    {
      "x": 6,
      "y": 0,
      "z": 5,
      "name": "Cloth_Block_Wool_Black"
    },
    {
      "x": 6,
      "y": 1,
      "z": 5,
      "name": "Empty"
    },
    {
      "x": 6,
      "y": 2,
      "z": 5,
      "name": "Empty"
    },
    {
      "x": 6,
      "y": 3,
      "z": 5,
      "name": "Empty"
    },
    {
      "x": 6,
      "y": 4,
      "z": 5,
      "name": "Cloth_Block_Wool_Black"
    },
    {
      "x": 6,
      "y": 0,
      "z": 6,
      "name": "Cloth_Block_Wool_Black"
    },
    {
      "x": 6,
      "y": 1,
      "z": 6,
      "name": "Empty"
    },
    {
      "x": 6,
      "y": 2,
      "z": 6,
      "name": "Empty"
    },
    {
      "x": 6,
      "y": 3,
      "z": 6,
      "name": "Empty"
    },
    {
      "x": 6,
      "y": 4,
      "z": 6,
      "name": "Cloth_Block_Wool_Black"
    },
    {
      "x": 6,
      "y": 0,
      "z": 7,
      "name": "Cloth_Block_Wool_Black"
    },
    {
      "x": 6,
      "y": 1,
      "z": 7,
      "name": "Rock_Basalt_Brick"
    },
    {
      "x": 6,
      "y": 2,
      "z": 7,
      "name": "Rock_Basalt_Brick"
    },
    {
      "x": 6,
      "y": 3,
      "z": 7,
      "name": "Rock_Basalt_Brick"
    },
    {
      "x": 6,
      "y": 4,
      "z": 7,
      "name": "Cloth_Block_Wool_Black"
    },
    {
      "x": 7,
      "y": 0,
      "z": -7,
      "name": "Cloth_Block_Wool_Black"
    },
    {
      "x": 7,
      "y": 1,
      "z": -7,
      "name": "Rock_Basalt_Brick"
    },
    {
      "x": 7,
      "y": 2,
      "z": -7,
      "name": "Rock_Basalt_Brick"
    },
    {
      "x": 7,
      "y": 3,
      "z": -7,
      "name": "Rock_Basalt_Brick"
    },
    {
      "x": 7,
      "y": 4,
      "z": -7,
      "name": "Cloth_Block_Wool_Black"
    },
    {
      "x": 7,
      "y": 0,
      "z": -6,
      "name": "Cloth_Block_Wool_Black"
    },
    {
      "x": 7,
      "y": 1,
      "z": -6,
      "name": "Empty"
    },
    {
      "x": 7,
      "y": 2,
      "z": -6,
      "name": "Empty"
    },
    {
      "x": 7,
      "y": 3,
      "z": -6,
      "name": "Empty"
    },
    {
      "x": 7,
      "y": 4,
      "z": -6,
      "name": "Cloth_Block_Wool_Black"
    },
    {
      "x": 7,
      "y": 0,
      "z": -5,
      "name": "Cloth_Block_Wool_Black"
    },
    {
      "x": 7,
      "y": 1,
      "z": -5,
      "name": "Empty"
    },
    {
      "x": 7,
      "y": 2,
      "z": -5,
      "name": "Empty"
    },
    {
      "x": 7,
      "y": 3,
      "z": -5,
      "name": "Empty"
    },
    {
      "x": 7,
      "y": 4,
      "z": -5,
      "name": "Cloth_Block_Wool_Black"
    },
    {
      "x": 7,
      "y": 0,
      "z": -4,
      "name": "Cloth_Block_Wool_Black"
    },
    {
      "x": 7,
      "y": 1,
      "z": -4,
      "name": "Empty"
    },
    {
      "x": 7,
      "y": 2,
      "z": -4,
      "name": "Empty"
    },
    {
      "x": 7,
      "y": 3,
      "z": -4,
      "name": "Empty"
    },
    {
      "x": 7,
      "y": 4,
      "z": -4,
      "name": "Cloth_Block_Wool_Black"
    },
    {
      "x": 7,
      "y": 0,
      "z": -3,
      "name": "Cloth_Block_Wool_Black"
    },
    {
      "x": 7,
      "y": 1,
      "z": -3,
      "name": "Empty"
    },
    {
      "x": 7,
      "y": 2,
      "z": -3,
      "name": "Empty"
    },
    {
      "x": 7,
      "y": 3,
      "z": -3,
      "name": "Empty"
    },
    {
      "x": 7,
      "y": 4,
      "z": -3,
      "name": "Cloth_Block_Wool_Black"
    },
    {
      "x": 7,
      "y": 0,
      "z": -2,
      "name": "Cloth_Block_Wool_Black"
    },
    {
      "x": 7,
      "y": 1,
      "z": -2,
      "name": "Empty"
    },
    {
      "x": 7,
      "y": 2,
      "z": -2,
      "name": "Empty"
    },
    {
      "x": 7,
      "y": 3,
      "z": -2,
      "name": "Empty"
    },
    {
      "x": 7,
      "y": 4,
      "z": -2,
      "name": "Cloth_Block_Wool_Black"
    },
    {
      "x": 7,
      "y": 0,
      "z": -1,
      "name": "Cloth_Block_Wool_Black"
    },
    {
      "x": 7,
      "y": 1,
      "z": -1,
      "name": "Empty"
    },
    {
      "x": 7,
      "y": 2,
      "z": -1,
      "name": "Empty"
    },
    {
      "x": 7,
      "y": 3,
      "z": -1,
      "name": "Empty"
    },
    {
      "x": 7,
      "y": 4,
      "z": -1,
      "name": "Cloth_Block_Wool_Black"
    },
    {
      "x": 7,
      "y": 0,
      "z": 0,
      "name": "Cloth_Block_Wool_Black"
    },
    {
      "x": 7,
      "y": 1,
      "z": 0,
      "name": "Empty"
    },
    {
      "x": 7,
      "y": 2,
      "z": 0,
      "name": "Empty"
    },
    {
      "x": 7,
      "y": 3,
      "z": 0,
      "name": "Empty"
    },
    {
      "x": 7,
      "y": 4,
      "z": 0,
      "name": "Cloth_Block_Wool_Black"
    },
    {
      "x": 7,
      "y": 0,
      "z": 1,
      "name": "Cloth_Block_Wool_Black"
    },
    {
      "x": 7,
      "y": 1,
      "z": 1,
      "name": "Empty"
    },
    {
      "x": 7,
      "y": 2,
      "z": 1,
      "name": "Empty"
    },
    {
      "x": 7,
      "y": 3,
      "z": 1,
      "name": "Empty"
    },
    {
      "x": 7,
      "y": 4,
      "z": 1,
      "name": "Cloth_Block_Wool_Black"
    },
    {
      "x": 7,
      "y": 0,
      "z": 2,
      "name": "Cloth_Block_Wool_Black"
    },
    {
      "x": 7,
      "y": 1,
      "z": 2,
      "name": "Empty"
    },
    {
      "x": 7,
      "y": 2,
      "z": 2,
      "name": "Empty"
    },
    {
      "x": 7,
      "y": 3,
      "z": 2,
      "name": "Empty"
    },
    {
      "x": 7,
      "y": 4,
      "z": 2,
      "name": "Cloth_Block_Wool_Black"
    },
    {
      "x": 7,
      "y": 0,
      "z": 3,
      "name": "Cloth_Block_Wool_Black"
    },
    {
      "x": 7,
      "y": 1,
      "z": 3,
      "name": "Empty"
    },
    {
      "x": 7,
      "y": 2,
      "z": 3,
      "name": "Empty"
    },
    {
      "x": 7,
      "y": 3,
      "z": 3,
      "name": "Empty"
    },
    {
      "x": 7,
      "y": 4,
      "z": 3,
      "name": "Cloth_Block_Wool_Black"
    },
    {
      "x": 7,
      "y": 0,
      "z": 4,
      "name": "Cloth_Block_Wool_Black"
    },
    {
      "x": 7,
      "y": 1,
      "z": 4,
      "name": "Empty"
    },
    {
      "x": 7,
      "y": 2,
      "z": 4,
      "name": "Empty"
    },
    {
      "x": 7,
      "y": 3,
      "z": 4,
      "name": "Empty"
    },
    {
      "x": 7,
      "y": 4,
      "z": 4,
      "name": "Cloth_Block_Wool_Black"
    },
    {
      "x": 7,
      "y": 0,
      "z": 5,
      "name": "Cloth_Block_Wool_Black"
    },
    {
      "x": 7,
      "y": 1,
      "z": 5,
      "name": "Empty"
    },
    {
      "x": 7,
      "y": 2,
      "z": 5,
      "name": "Empty"
    },
    {
      "x": 7,
      "y": 3,
      "z": 5,
      "name": "Empty"
    },
    {
      "x": 7,
      "y": 4,
      "z": 5,
      "name": "Cloth_Block_Wool_Black"
    },
    {
      "x": 7,
      "y": 0,
      "z": 6,
      "name": "Cloth_Block_Wool_Black"
    },
    {
      "x": 7,
      "y": 1,
      "z": 6,
      "name": "Empty"
    },
    {
      "x": 7,
      "y": 2,
      "z": 6,
      "name": "Empty"
    },
    {
      "x": 7,
      "y": 3,
      "z": 6,
      "name": "Empty"
    },
    {
      "x": 7,
      "y": 4,
      "z": 6,
      "name": "Cloth_Block_Wool_Black"
    },
    {
      "x": 7,
      "y": 0,
      "z": 7,
      "name": "Cloth_Block_Wool_Black"
    },
    {
      "x": 7,
      "y": 1,
      "z": 7,
      "name": "Rock_Basalt_Brick"
    },
    {
      "x": 7,
      "y": 2,
      "z": 7,
      "name": "Rock_Basalt_Brick"
    },
    {
      "x": 7,
      "y": 3,
      "z": 7,
      "name": "Rock_Basalt_Brick"
    },
    {
      "x": 7,
      "y": 4,
      "z": 7,
      "name": "Cloth_Block_Wool_Black"
    },
    {
      "x": 8,
      "y": 0,
      "z": -7,
      "name": "Cloth_Block_Wool_Black"
    },
    {
      "x": 8,
      "y": 1,
      "z": -7,
      "name": "Rock_Basalt_Brick"
    },
    {
      "x": 8,
      "y": 2,
      "z": -7,
      "name": "Rock_Basalt_Brick"
    },
    {
      "x": 8,
      "y": 3,
      "z": -7,
      "name": "Rock_Basalt_Brick"
    },
    {
      "x": 8,
      "y": 4,
      "z": -7,
      "name": "Cloth_Block_Wool_Black"
    },
    {
      "x": 8,
      "y": 0,
      "z": -6,
      "name": "Cloth_Block_Wool_Black"
    },
    {
      "x": 8,
      "y": 1,
      "z": -6,
      "name": "Empty"
    },
    {
      "x": 8,
      "y": 2,
      "z": -6,
      "name": "Empty"
    },
    {
      "x": 8,
      "y": 3,
      "z": -6,
      "name": "Empty"
    },
    {
      "x": 8,
      "y": 4,
      "z": -6,
      "name": "Cloth_Block_Wool_Black"
    },
    {
      "x": 8,
      "y": 0,
      "z": -5,
      "name": "Cloth_Block_Wool_Black"
    },
    {
      "x": 8,
      "y": 1,
      "z": -5,
      "name": "Empty"
    },
    {
      "x": 8,
      "y": 2,
      "z": -5,
      "name": "Empty"
    },
    {
      "x": 8,
      "y": 3,
      "z": -5,
      "name": "Empty"
    },
    {
      "x": 8,
      "y": 4,
      "z": -5,
      "name": "Cloth_Block_Wool_Black"
    },
    {
      "x": 8,
      "y": 0,
      "z": -4,
      "name": "Cloth_Block_Wool_Black"
    },
    {
      "x": 8,
      "y": 1,
      "z": -4,
      "name": "Empty"
    },
    {
      "x": 8,
      "y": 2,
      "z": -4,
      "name": "Empty"
    },
    {
      "x": 8,
      "y": 3,
      "z": -4,
      "name": "Empty"
    },
    {
      "x": 8,
      "y": 4,
      "z": -4,
      "name": "Cloth_Block_Wool_Black"
    },
    {
      "x": 8,
      "y": 0,
      "z": -3,
      "name": "Cloth_Block_Wool_Black"
    },
    {
      "x": 8,
      "y": 1,
      "z": -3,
      "name": "Empty"
    },
    {
      "x": 8,
      "y": 2,
      "z": -3,
      "name": "Empty"
    },
    {
      "x": 8,
      "y": 3,
      "z": -3,
      "name": "Empty"
    },
    {
      "x": 8,
      "y": 4,
      "z": -3,
      "name": "Cloth_Block_Wool_Black"
    },
    {
      "x": 8,
      "y": 0,
      "z": -2,
      "name": "Cloth_Block_Wool_Black"
    },
    {
      "x": 8,
      "y": 1,
      "z": -2,
      "name": "Empty"
    },
    {
      "x": 8,
      "y": 2,
      "z": -2,
      "name": "Empty"
    },
    {
      "x": 8,
      "y": 3,
      "z": -2,
      "name": "Empty"
    },
    {
      "x": 8,
      "y": 4,
      "z": -2,
      "name": "Cloth_Block_Wool_Black"
    },
    {
      "x": 8,
      "y": 0,
      "z": -1,
      "name": "Cloth_Block_Wool_Black"
    },
    {
      "x": 8,
      "y": 1,
      "z": -1,
      "name": "Empty"
    },
    {
      "x": 8,
      "y": 2,
      "z": -1,
      "name": "Empty"
    },
    {
      "x": 8,
      "y": 3,
      "z": -1,
      "name": "Empty"
    },
    {
      "x": 8,
      "y": 4,
      "z": -1,
      "name": "Cloth_Block_Wool_Black"
    },
    {
      "x": 8,
      "y": 0,
      "z": 0,
      "name": "Cloth_Block_Wool_Black"
    },
    {
      "x": 8,
      "y": 1,
      "z": 0,
      "name": "Empty"
    },
    {
      "x": 8,
      "y": 2,
      "z": 0,
      "name": "Empty"
    },
    {
      "x": 8,
      "y": 3,
      "z": 0,
      "name": "Empty"
    },
    {
      "x": 8,
      "y": 4,
      "z": 0,
      "name": "Cloth_Block_Wool_Black"
    },
    {
      "x": 8,
      "y": 0,
      "z": 1,
      "name": "Cloth_Block_Wool_Black"
    },
    {
      "x": 8,
      "y": 1,
      "z": 1,
      "name": "Empty"
    },
    {
      "x": 8,
      "y": 2,
      "z": 1,
      "name": "Empty"
    },
    {
      "x": 8,
      "y": 3,
      "z": 1,
      "name": "Empty"
    },
    {
      "x": 8,
      "y": 4,
      "z": 1,
      "name": "Cloth_Block_Wool_Black"
    },
    {
      "x": 8,
      "y": 0,
      "z": 2,
      "name": "Cloth_Block_Wool_Black"
    },
    {
      "x": 8,
      "y": 1,
      "z": 2,
      "name": "Empty"
    },
    {
      "x": 8,
      "y": 2,
      "z": 2,
      "name": "Empty"
    },
    {
      "x": 8,
      "y": 3,
      "z": 2,
      "name": "Empty"
    },
    {
      "x": 8,
      "y": 4,
      "z": 2,
      "name": "Cloth_Block_Wool_Black"
    },
    {
      "x": 8,
      "y": 0,
      "z": 3,
      "name": "Cloth_Block_Wool_Black"
    },
    {
      "x": 8,
      "y": 1,
      "z": 3,
      "name": "Empty"
    },
    {
      "x": 8,
      "y": 2,
      "z": 3,
      "name": "Empty"
    },
    {
      "x": 8,
      "y": 3,
      "z": 3,
      "name": "Empty"
    },
    {
      "x": 8,
      "y": 4,
      "z": 3,
      "name": "Cloth_Block_Wool_Black"
    },
    {
      "x": 8,
      "y": 0,
      "z": 4,
      "name": "Cloth_Block_Wool_Black"
    },
    {
      "x": 8,
      "y": 1,
      "z": 4,
      "name": "Empty"
    },
    {
      "x": 8,
      "y": 2,
      "z": 4,
      "name": "Empty"
    },
    {
      "x": 8,
      "y": 3,
      "z": 4,
      "name": "Empty"
    },
    {
      "x": 8,
      "y": 4,
      "z": 4,
      "name": "Cloth_Block_Wool_Black"
    },
    {
      "x": 8,
      "y": 0,
      "z": 5,
      "name": "Cloth_Block_Wool_Black"
    },
    {
      "x": 8,
      "y": 1,
      "z": 5,
      "name": "Empty"
    },
    {
      "x": 8,
      "y": 2,
      "z": 5,
      "name": "Empty"
    },
    {
      "x": 8,
      "y": 3,
      "z": 5,
      "name": "Empty"
    },
    {
      "x": 8,
      "y": 4,
      "z": 5,
      "name": "Cloth_Block_Wool_Black"
    },
    {
      "x": 8,
      "y": 0,
      "z": 6,
      "name": "Cloth_Block_Wool_Black"
    },
    {
      "x": 8,
      "y": 1,
      "z": 6,
      "name": "Empty"
    },
    {
      "x": 8,
      "y": 2,
      "z": 6,
      "name": "Empty"
    },
    {
      "x": 8,
      "y": 3,
      "z": 6,
      "name": "Wood_Torch_Wall",
      "rotation": 2
    },
    {
      "x": 8,
      "y": 4,
      "z": 6,
      "name": "Cloth_Block_Wool_Black"
    },
    {
      "x": 8,
      "y": 0,
      "z": 7,
      "name": "Cloth_Block_Wool_Black"
    },
    {
      "x": 8,
      "y": 1,
      "z": 7,
      "name": "Rock_Basalt_Brick"
    },
    {
      "x": 8,
      "y": 2,
      "z": 7,
      "name": "Rock_Basalt_Brick"
    },
    {
      "x": 8,
      "y": 3,
      "z": 7,
      "name": "Rock_Basalt_Brick"
    },
    {
      "x": 8,
      "y": 4,
      "z": 7,
      "name": "Cloth_Block_Wool_Black"
    },
    {
      "x": 9,
      "y": 0,
      "z": -7,
      "name": "Cloth_Block_Wool_Black"
    },
    {
      "x": 9,
      "y": 1,
      "z": -7,
      "name": "Rock_Basalt_Brick"
    },
    {
      "x": 9,
      "y": 2,
      "z": -7,
      "name": "Rock_Basalt_Brick"
    },
    {
      "x": 9,
      "y": 3,
      "z": -7,
      "name": "Rock_Basalt_Brick"
    },
    {
      "x": 9,
      "y": 4,
      "z": -7,
      "name": "Cloth_Block_Wool_Black"
    },
    {
      "x": 9,
      "y": 0,
      "z": -6,
      "name": "Cloth_Block_Wool_Black"
    },
    {
      "x": 9,
      "y": 1,
      "z": -6,
      "name": "Empty"
    },
    {
      "x": 9,
      "y": 2,
      "z": -6,
      "name": "Empty"
    },
    {
      "x": 9,
      "y": 3,
      "z": -6,
      "name": "Empty"
    },
    {
      "x": 9,
      "y": 4,
      "z": -6,
      "name": "Cloth_Block_Wool_Black"
    },
    {
      "x": 9,
      "y": 0,
      "z": -5,
      "name": "Cloth_Block_Wool_Black"
    },
    {
      "x": 9,
      "y": 1,
      "z": -5,
      "name": "Empty"
    },
    {
      "x": 9,
      "y": 2,
      "z": -5,
      "name": "Empty"
    },
    {
      "x": 9,
      "y": 3,
      "z": -5,
      "name": "Empty"
    },
    {
      "x": 9,
      "y": 4,
      "z": -5,
      "name": "Cloth_Block_Wool_Black"
    },
    {
      "x": 9,
      "y": 0,
      "z": -4,
      "name": "Cloth_Block_Wool_Black"
    },
    {
      "x": 9,
      "y": 1,
      "z": -4,
      "name": "Empty"
    },
    {
      "x": 9,
      "y": 2,
      "z": -4,
      "name": "Empty"
    },
    {
      "x": 9,
      "y": 3,
      "z": -4,
      "name": "Empty"
    },
    {
      "x": 9,
      "y": 4,
      "z": -4,
      "name": "Cloth_Block_Wool_Black"
    },
    {
      "x": 9,
      "y": 0,
      "z": -3,
      "name": "Cloth_Block_Wool_Black"
    },
    {
      "x": 9,
      "y": 1,
      "z": -3,
      "name": "Empty"
    },
    {
      "x": 9,
      "y": 2,
      "z": -3,
      "name": "Empty"
    },
    {
      "x": 9,
      "y": 3,
      "z": -3,
      "name": "Empty"
    },
    {
      "x": 9,
      "y": 4,
      "z": -3,
      "name": "Cloth_Block_Wool_Black"
    },
    {
      "x": 9,
      "y": 0,
      "z": -2,
      "name": "Cloth_Block_Wool_Black"
    },
    {
      "x": 9,
      "y": 1,
      "z": -2,
      "name": "Empty"
    },
    {
      "x": 9,
      "y": 2,
      "z": -2,
      "name": "Empty"
    },
    {
      "x": 9,
      "y": 3,
      "z": -2,
      "name": "Empty"
    },
    {
      "x": 9,
      "y": 4,
      "z": -2,
      "name": "Cloth_Block_Wool_Black"
    },
    {
      "x": 9,
      "y": 0,
      "z": -1,
      "name": "Cloth_Block_Wool_Black"
    },
    {
      "x": 9,
      "y": 1,
      "z": -1,
      "name": "Empty"
    },
    {
      "x": 9,
      "y": 2,
      "z": -1,
      "name": "Empty"
    },
    {
      "x": 9,
      "y": 3,
      "z": -1,
      "name": "Empty"
    },
    {
      "x": 9,
      "y": 4,
      "z": -1,
      "name": "Cloth_Block_Wool_Black"
    },
    {
      "x": 9,
      "y": 0,
      "z": 0,
      "name": "Cloth_Block_Wool_Black"
    },
    {
      "x": 9,
      "y": 1,
      "z": 0,
      "name": "Empty"
    },
    {
      "x": 9,
      "y": 2,
      "z": 0,
      "name": "Empty"
    },
    {
      "x": 9,
      "y": 3,
      "z": 0,
      "name": "Empty"
    },
    {
      "x": 9,
      "y": 4,
      "z": 0,
      "name": "Cloth_Block_Wool_Black"
    },
    {
      "x": 9,
      "y": 0,
      "z": 1,
      "name": "Cloth_Block_Wool_Black"
    },
    {
      "x": 9,
      "y": 1,
      "z": 1,
      "name": "Empty"
    },
    {
      "x": 9,
      "y": 2,
      "z": 1,
      "name": "Empty"
    },
    {
      "x": 9,
      "y": 3,
      "z": 1,
      "name": "Empty"
    },
    {
      "x": 9,
      "y": 4,
      "z": 1,
      "name": "Cloth_Block_Wool_Black"
    },
    {
      "x": 9,
      "y": 0,
      "z": 2,
      "name": "Cloth_Block_Wool_Black"
    },
    {
      "x": 9,
      "y": 1,
      "z": 2,
      "name": "Empty"
    },
    {
      "x": 9,
      "y": 2,
      "z": 2,
      "name": "Empty"
    },
    {
      "x": 9,
      "y": 3,
      "z": 2,
      "name": "Empty"
    },
    {
      "x": 9,
      "y": 4,
      "z": 2,
      "name": "Cloth_Block_Wool_Black"
    },
    {
      "x": 9,
      "y": 0,
      "z": 3,
      "name": "Cloth_Block_Wool_Black"
    },
    {
      "x": 9,
      "y": 1,
      "z": 3,
      "name": "Empty"
    },
    {
      "x": 9,
      "y": 2,
      "z": 3,
      "name": "Empty"
    },
    {
      "x": 9,
      "y": 3,
      "z": 3,
      "name": "Empty"
    },
    {
      "x": 9,
      "y": 4,
      "z": 3,
      "name": "Cloth_Block_Wool_Black"
    },
    {
      "x": 9,
      "y": 0,
      "z": 4,
      "name": "Cloth_Block_Wool_Black"
    },
    {
      "x": 9,
      "y": 1,
      "z": 4,
      "name": "Empty"
    },
    {
      "x": 9,
      "y": 2,
      "z": 4,
      "name": "Empty"
    },
    {
      "x": 9,
      "y": 3,
      "z": 4,
      "name": "Empty"
    },
    {
      "x": 9,
      "y": 4,
      "z": 4,
      "name": "Cloth_Block_Wool_Black"
    },
    {
      "x": 9,
      "y": 0,
      "z": 5,
      "name": "Cloth_Block_Wool_Black"
    },
    {
      "x": 9,
      "y": 1,
      "z": 5,
      "name": "Empty"
    },
    {
      "x": 9,
      "y": 2,
      "z": 5,
      "name": "Empty"
    },
    {
      "x": 9,
      "y": 3,
      "z": 5,
      "name": "Empty"
    },
    {
      "x": 9,
      "y": 4,
      "z": 5,
      "name": "Cloth_Block_Wool_Black"
    },
    {
      "x": 9,
      "y": 0,
      "z": 6,
      "name": "Cloth_Block_Wool_Black"
    },
    {
      "x": 9,
      "y": 1,
      "z": 6,
      "name": "Empty"
    },
    {
      "x": 9,
      "y": 2,
      "z": 6,
      "name": "Empty"
    },
    {
      "x": 9,
      "y": 3,
      "z": 6,
      "name": "Empty"
    },
    {
      "x": 9,
      "y": 4,
      "z": 6,
      "name": "Cloth_Block_Wool_Black"
    },
    {
      "x": 9,
      "y": 0,
      "z": 7,
      "name": "Cloth_Block_Wool_Black"
    },
    {
      "x": 9,
      "y": 1,
      "z": 7,
      "name": "Rock_Basalt_Brick"
    },
    {
      "x": 9,
      "y": 2,
      "z": 7,
      "name": "Rock_Basalt_Brick"
    },
    {
      "x": 9,
      "y": 3,
      "z": 7,
      "name": "Rock_Basalt_Brick"
    },
    {
      "x": 9,
      "y": 4,
      "z": 7,
      "name": "Cloth_Block_Wool_Black"
    },
    {
      "x": 10,
      "y": 0,
      "z": -7,
      "name": "Cloth_Block_Wool_Black"
    },
    {
      "x": 10,
      "y": 1,
      "z": -7,
      "name": "Rock_Basalt_Brick"
    },
    {
      "x": 10,
      "y": 2,
      "z": -7,
      "name": "Rock_Basalt_Brick"
    },
    {
      "x": 10,
      "y": 3,
      "z": -7,
      "name": "Rock_Basalt_Brick"
    },
    {
      "x": 10,
      "y": 4,
      "z": -7,
      "name": "Cloth_Block_Wool_Black"
    },
    {
      "x": 10,
      "y": 0,
      "z": -6,
      "name": "Cloth_Block_Wool_Black"
    },
    {
      "x": 10,
      "y": 1,
      "z": -6,
      "name": "Empty"
    },
    {
      "x": 10,
      "y": 2,
      "z": -6,
      "name": "Empty"
    },
    {
      "x": 10,
      "y": 3,
      "z": -6,
      "name": "Wood_Torch_Wall"
    },
    {
      "x": 10,
      "y": 4,
      "z": -6,
      "name": "Cloth_Block_Wool_Black"
    },
    {
      "x": 10,
      "y": 0,
      "z": -5,
      "name": "Cloth_Block_Wool_Black"
    },
    {
      "x": 10,
      "y": 1,
      "z": -5,
      "name": "Empty"
    },
    {
      "x": 10,
      "y": 2,
      "z": -5,
      "name": "Empty"
    },
    {
      "x": 10,
      "y": 3,
      "z": -5,
      "name": "Empty"
    },
    {
      "x": 10,
      "y": 4,
      "z": -5,
      "name": "Cloth_Block_Wool_Black"
    },
    {
      "x": 10,
      "y": 0,
      "z": -4,
      "name": "Cloth_Block_Wool_Black"
    },
    {
      "x": 10,
      "y": 1,
      "z": -4,
      "name": "Empty"
    },
    {
      "x": 10,
      "y": 2,
      "z": -4,
      "name": "Empty"
    },
    {
      "x": 10,
      "y": 3,
      "z": -4,
      "name": "Empty"
    },
    {
      "x": 10,
      "y": 4,
      "z": -4,
      "name": "Cloth_Block_Wool_Black"
    },
    {
      "x": 10,
      "y": 0,
      "z": -3,
      "name": "Cloth_Block_Wool_Black"
    },
    {
      "x": 10,
      "y": 1,
      "z": -3,
      "name": "Empty"
    },
    {
      "x": 10,
      "y": 2,
      "z": -3,
      "name": "Empty"
    },
    {
      "x": 10,
      "y": 3,
      "z": -3,
      "name": "Empty"
    },
    {
      "x": 10,
      "y": 4,
      "z": -3,
      "name": "Cloth_Block_Wool_Black"
    },
    {
      "x": 10,
      "y": 0,
      "z": -2,
      "name": "Cloth_Block_Wool_Black"
    },
    {
      "x": 10,
      "y": 1,
      "z": -2,
      "name": "Empty"
    },
    {
      "x": 10,
      "y": 2,
      "z": -2,
      "name": "Empty"
    },
    {
      "x": 10,
      "y": 3,
      "z": -2,
      "name": "Empty"
    },
    {
      "x": 10,
      "y": 4,
      "z": -2,
      "name": "Cloth_Block_Wool_Black"
    },
    {
      "x": 10,
      "y": 0,
      "z": -1,
      "name": "Cloth_Block_Wool_Black"
    },
    {
      "x": 10,
      "y": 1,
      "z": -1,
      "name": "Empty"
    },
    {
      "x": 10,
      "y": 2,
      "z": -1,
      "name": "Empty"
    },
    {
      "x": 10,
      "y": 3,
      "z": -1,
      "name": "Empty"
    },
    {
      "x": 10,
      "y": 4,
      "z": -1,
      "name": "Cloth_Block_Wool_Black"
    },
    {
      "x": 10,
      "y": 0,
      "z": 0,
      "name": "Cloth_Block_Wool_Black"
    },
    {
      "x": 10,
      "y": 1,
      "z": 0,
      "name": "Empty"
    },
    {
      "x": 10,
      "y": 2,
      "z": 0,
      "name": "Empty"
    },
    {
      "x": 10,
      "y": 3,
      "z": 0,
      "name": "Empty"
    },
    {
      "x": 10,
      "y": 4,
      "z": 0,
      "name": "Cloth_Block_Wool_Black"
    },
    {
      "x": 10,
      "y": 0,
      "z": 1,
      "name": "Cloth_Block_Wool_Black"
    },
    {
      "x": 10,
      "y": 1,
      "z": 1,
      "name": "Empty"
    },
    {
      "x": 10,
      "y": 2,
      "z": 1,
      "name": "Empty"
    },
    {
      "x": 10,
      "y": 3,
      "z": 1,
      "name": "Empty"
    },
    {
      "x": 10,
      "y": 4,
      "z": 1,
      "name": "Cloth_Block_Wool_Black"
    },
    {
      "x": 10,
      "y": 0,
      "z": 2,
      "name": "Cloth_Block_Wool_Black"
    },
    {
      "x": 10,
      "y": 1,
      "z": 2,
      "name": "Empty"
    },
    {
      "x": 10,
      "y": 2,
      "z": 2,
      "name": "Empty"
    },
    {
      "x": 10,
      "y": 3,
      "z": 2,
      "name": "Empty"
    },
    {
      "x": 10,
      "y": 4,
      "z": 2,
      "name": "Cloth_Block_Wool_Black"
    },
    {
      "x": 10,
      "y": 0,
      "z": 3,
      "name": "Cloth_Block_Wool_Black"
    },
    {
      "x": 10,
      "y": 1,
      "z": 3,
      "name": "Empty"
    },
    {
      "x": 10,
      "y": 2,
      "z": 3,
      "name": "Empty"
    },
    {
      "x": 10,
      "y": 3,
      "z": 3,
      "name": "Empty"
    },
    {
      "x": 10,
      "y": 4,
      "z": 3,
      "name": "Cloth_Block_Wool_Black"
    },
    {
      "x": 10,
      "y": 0,
      "z": 4,
      "name": "Cloth_Block_Wool_Black"
    },
    {
      "x": 10,
      "y": 1,
      "z": 4,
      "name": "Empty"
    },
    {
      "x": 10,
      "y": 2,
      "z": 4,
      "name": "Empty"
    },
    {
      "x": 10,
      "y": 3,
      "z": 4,
      "name": "Empty"
    },
    {
      "x": 10,
      "y": 4,
      "z": 4,
      "name": "Cloth_Block_Wool_Black"
    },
    {
      "x": 10,
      "y": 0,
      "z": 5,
      "name": "Cloth_Block_Wool_Black"
    },
    {
      "x": 10,
      "y": 1,
      "z": 5,
      "name": "Empty"
    },
    {
      "x": 10,
      "y": 2,
      "z": 5,
      "name": "Empty"
    },
    {
      "x": 10,
      "y": 3,
      "z": 5,
      "name": "Empty"
    },
    {
      "x": 10,
      "y": 4,
      "z": 5,
      "name": "Cloth_Block_Wool_Black"
    },
    {
      "x": 10,
      "y": 0,
      "z": 6,
      "name": "Cloth_Block_Wool_Black"
    },
    {
      "x": 10,
      "y": 1,
      "z": 6,
      "name": "Empty"
    },
    {
      "x": 10,
      "y": 2,
      "z": 6,
      "name": "Empty"
    },
    {
      "x": 10,
      "y": 3,
      "z": 6,
      "name": "Empty"
    },
    {
      "x": 10,
      "y": 4,
      "z": 6,
      "name": "Cloth_Block_Wool_Black"
    },
    {
      "x": 10,
      "y": 0,
      "z": 7,
      "name": "Cloth_Block_Wool_Black"
    },
    {
      "x": 10,
      "y": 1,
      "z": 7,
      "name": "Rock_Basalt_Brick"
    },
    {
      "x": 10,
      "y": 2,
      "z": 7,
      "name": "Rock_Basalt_Brick"
    },
    {
      "x": 10,
      "y": 3,
      "z": 7,
      "name": "Rock_Basalt_Brick"
    },
    {
      "x": 10,
      "y": 4,
      "z": 7,
      "name": "Cloth_Block_Wool_Black"
    },
    {
      "x": 11,
      "y": 0,
      "z": -7,
      "name": "Cloth_Block_Wool_Black"
    },
    {
      "x": 11,
      "y": 1,
      "z": -7,
      "name": "Rock_Basalt_Brick"
    },
    {
      "x": 11,
      "y": 2,
      "z": -7,
      "name": "Rock_Basalt_Brick"
    },
    {
      "x": 11,
      "y": 3,
      "z": -7,
      "name": "Rock_Basalt_Brick"
    },
    {
      "x": 11,
      "y": 4,
      "z": -7,
      "name": "Cloth_Block_Wool_Black"
    },
    {
      "x": 11,
      "y": 0,
      "z": -6,
      "name": "Cloth_Block_Wool_Black"
    },
    {
      "x": 11,
      "y": 1,
      "z": -6,
      "name": "Empty"
    },
    {
      "x": 11,
      "y": 2,
      "z": -6,
      "name": "Empty"
    },
    {
      "x": 11,
      "y": 3,
      "z": -6,
      "name": "Empty"
    },
    {
      "x": 11,
      "y": 4,
      "z": -6,
      "name": "Cloth_Block_Wool_Black"
    },
    {
      "x": 11,
      "y": 0,
      "z": -5,
      "name": "Cloth_Block_Wool_Black"
    },
    {
      "x": 11,
      "y": 1,
      "z": -5,
      "name": "Empty"
    },
    {
      "x": 11,
      "y": 2,
      "z": -5,
      "name": "Empty"
    },
    {
      "x": 11,
      "y": 3,
      "z": -5,
      "name": "Empty"
    },
    {
      "x": 11,
      "y": 4,
      "z": -5,
      "name": "Cloth_Block_Wool_Black"
    },
    {
      "x": 11,
      "y": 0,
      "z": -4,
      "name": "Cloth_Block_Wool_Black"
    },
    {
      "x": 11,
      "y": 1,
      "z": -4,
      "name": "Empty"
    },
    {
      "x": 11,
      "y": 2,
      "z": -4,
      "name": "Empty"
    },
    {
      "x": 11,
      "y": 3,
      "z": -4,
      "name": "Empty"
    },
    {
      "x": 11,
      "y": 4,
      "z": -4,
      "name": "Cloth_Block_Wool_Black"
    },
    {
      "x": 11,
      "y": 0,
      "z": -3,
      "name": "Cloth_Block_Wool_Black"
    },
    {
      "x": 11,
      "y": 1,
      "z": -3,
      "name": "Empty"
    },
    {
      "x": 11,
      "y": 2,
      "z": -3,
      "name": "Empty"
    },
    {
      "x": 11,
      "y": 3,
      "z": -3,
      "name": "Empty"
    },
    {
      "x": 11,
      "y": 4,
      "z": -3,
      "name": "Cloth_Block_Wool_Black"
    },
    {
      "x": 11,
      "y": 0,
      "z": -2,
      "name": "Cloth_Block_Wool_Black"
    },
    {
      "x": 11,
      "y": 1,
      "z": -2,
      "name": "Empty"
    },
    {
      "x": 11,
      "y": 2,
      "z": -2,
      "name": "Empty"
    },
    {
      "x": 11,
      "y": 3,
      "z": -2,
      "name": "Empty"
    },
    {
      "x": 11,
      "y": 4,
      "z": -2,
      "name": "Cloth_Block_Wool_Black"
    },
    {
      "x": 11,
      "y": 0,
      "z": -1,
      "name": "Cloth_Block_Wool_Black"
    },
    {
      "x": 11,
      "y": 1,
      "z": -1,
      "name": "Empty"
    },
    {
      "x": 11,
      "y": 2,
      "z": -1,
      "name": "Empty"
    },
    {
      "x": 11,
      "y": 3,
      "z": -1,
      "name": "Empty"
    },
    {
      "x": 11,
      "y": 4,
      "z": -1,
      "name": "Cloth_Block_Wool_Black"
    },
    {
      "x": 11,
      "y": 0,
      "z": 0,
      "name": "Cloth_Block_Wool_Black"
    },
    {
      "x": 11,
      "y": 1,
      "z": 0,
      "name": "Empty"
    },
    {
      "x": 11,
      "y": 2,
      "z": 0,
      "name": "Empty"
    },
    {
      "x": 11,
      "y": 3,
      "z": 0,
      "name": "Empty"
    },
    {
      "x": 11,
      "y": 4,
      "z": 0,
      "name": "Cloth_Block_Wool_Black"
    },
    {
      "x": 11,
      "y": 0,
      "z": 1,
      "name": "Cloth_Block_Wool_Black"
    },
    {
      "x": 11,
      "y": 1,
      "z": 1,
      "name": "Empty"
    },
    {
      "x": 11,
      "y": 2,
      "z": 1,
      "name": "Empty"
    },
    {
      "x": 11,
      "y": 3,
      "z": 1,
      "name": "Empty"
    },
    {
      "x": 11,
      "y": 4,
      "z": 1,
      "name": "Cloth_Block_Wool_Black"
    },
    {
      "x": 11,
      "y": 0,
      "z": 2,
      "name": "Cloth_Block_Wool_Black"
    },
    {
      "x": 11,
      "y": 1,
      "z": 2,
      "name": "Empty"
    },
    {
      "x": 11,
      "y": 2,
      "z": 2,
      "name": "Empty"
    },
    {
      "x": 11,
      "y": 3,
      "z": 2,
      "name": "Empty"
    },
    {
      "x": 11,
      "y": 4,
      "z": 2,
      "name": "Cloth_Block_Wool_Black"
    },
    {
      "x": 11,
      "y": 0,
      "z": 3,
      "name": "Cloth_Block_Wool_Black"
    },
    {
      "x": 11,
      "y": 1,
      "z": 3,
      "name": "Empty"
    },
    {
      "x": 11,
      "y": 2,
      "z": 3,
      "name": "Empty"
    },
    {
      "x": 11,
      "y": 3,
      "z": 3,
      "name": "Empty"
    },
    {
      "x": 11,
      "y": 4,
      "z": 3,
      "name": "Cloth_Block_Wool_Black"
    },
    {
      "x": 11,
      "y": 0,
      "z": 4,
      "name": "Cloth_Block_Wool_Black"
    },
    {
      "x": 11,
      "y": 1,
      "z": 4,
      "name": "Empty"
    },
    {
      "x": 11,
      "y": 2,
      "z": 4,
      "name": "Empty"
    },
    {
      "x": 11,
      "y": 3,
      "z": 4,
      "name": "Empty"
    },
    {
      "x": 11,
      "y": 4,
      "z": 4,
      "name": "Cloth_Block_Wool_Black"
    },
    {
      "x": 11,
      "y": 0,
      "z": 5,
      "name": "Cloth_Block_Wool_Black"
    },
    {
      "x": 11,
      "y": 1,
      "z": 5,
      "name": "Empty"
    },
    {
      "x": 11,
      "y": 2,
      "z": 5,
      "name": "Empty"
    },
    {
      "x": 11,
      "y": 3,
      "z": 5,
      "name": "Empty"
    },
    {
      "x": 11,
      "y": 4,
      "z": 5,
      "name": "Cloth_Block_Wool_Black"
    },
    {
      "x": 11,
      "y": 0,
      "z": 6,
      "name": "Cloth_Block_Wool_Black"
    },
    {
      "x": 11,
      "y": 1,
      "z": 6,
      "name": "Empty"
    },
    {
      "x": 11,
      "y": 2,
      "z": 6,
      "name": "Empty"
    },
    {
      "x": 11,
      "y": 3,
      "z": 6,
      "name": "Wood_Torch_Wall",
      "rotation": 2
    },
    {
      "x": 11,
      "y": 4,
      "z": 6,
      "name": "Cloth_Block_Wool_Black"
    },
    {
      "x": 11,
      "y": 0,
      "z": 7,
      "name": "Cloth_Block_Wool_Black"
    },
    {
      "x": 11,
      "y": 1,
      "z": 7,
      "name": "Rock_Basalt_Brick"
    },
    {
      "x": 11,
      "y": 2,
      "z": 7,
      "name": "Rock_Basalt_Brick"
    },
    {
      "x": 11,
      "y": 3,
      "z": 7,
      "name": "Rock_Basalt_Brick"
    },
    {
      "x": 11,
      "y": 4,
      "z": 7,
      "name": "Cloth_Block_Wool_Black"
    },
    {
      "x": 12,
      "y": 0,
      "z": -7,
      "name": "Cloth_Block_Wool_Black"
    },
    {
      "x": 12,
      "y": 1,
      "z": -7,
      "name": "Rock_Basalt_Brick"
    },
    {
      "x": 12,
      "y": 2,
      "z": -7,
      "name": "Rock_Basalt_Brick"
    },
    {
      "x": 12,
      "y": 3,
      "z": -7,
      "name": "Rock_Basalt_Brick"
    },
    {
      "x": 12,
      "y": 4,
      "z": -7,
      "name": "Cloth_Block_Wool_Black"
    },
    {
      "x": 12,
      "y": 0,
      "z": -6,
      "name": "Cloth_Block_Wool_Black"
    },
    {
      "x": 12,
      "y": 1,
      "z": -6,
      "name": "Empty"
    },
    {
      "x": 12,
      "y": 2,
      "z": -6,
      "name": "Empty"
    },
    {
      "x": 12,
      "y": 3,
      "z": -6,
      "name": "Empty"
    },
    {
      "x": 12,
      "y": 4,
      "z": -6,
      "name": "Cloth_Block_Wool_Black"
    },
    {
      "x": 12,
      "y": 0,
      "z": -5,
      "name": "Cloth_Block_Wool_Black"
    },
    {
      "x": 12,
      "y": 1,
      "z": -5,
      "name": "Empty"
    },
    {
      "x": 12,
      "y": 2,
      "z": -5,
      "name": "Empty"
    },
    {
      "x": 12,
      "y": 3,
      "z": -5,
      "name": "Empty"
    },
    {
      "x": 12,
      "y": 4,
      "z": -5,
      "name": "Cloth_Block_Wool_Black"
    },
    {
      "x": 12,
      "y": 0,
      "z": -4,
      "name": "Cloth_Block_Wool_Black"
    },
    {
      "x": 12,
      "y": 1,
      "z": -4,
      "name": "Empty"
    },
    {
      "x": 12,
      "y": 2,
      "z": -4,
      "name": "Empty"
    },
    {
      "x": 12,
      "y": 3,
      "z": -4,
      "name": "Empty"
    },
    {
      "x": 12,
      "y": 4,
      "z": -4,
      "name": "Cloth_Block_Wool_Black"
    },
    {
      "x": 12,
      "y": 0,
      "z": -3,
      "name": "Cloth_Block_Wool_Black"
    },
    {
      "x": 12,
      "y": 1,
      "z": -3,
      "name": "Empty"
    },
    {
      "x": 12,
      "y": 2,
      "z": -3,
      "name": "Empty"
    },
    {
      "x": 12,
      "y": 3,
      "z": -3,
      "name": "Empty"
    },
    {
      "x": 12,
      "y": 4,
      "z": -3,
      "name": "Cloth_Block_Wool_Black"
    },
    {
      "x": 12,
      "y": 0,
      "z": -2,
      "name": "Cloth_Block_Wool_Black"
    },
    {
      "x": 12,
      "y": 1,
      "z": -2,
      "name": "Empty"
    },
    {
      "x": 12,
      "y": 2,
      "z": -2,
      "name": "Empty"
    },
    {
      "x": 12,
      "y": 3,
      "z": -2,
      "name": "Empty"
    },
    {
      "x": 12,
      "y": 4,
      "z": -2,
      "name": "Cloth_Block_Wool_Black"
    },
    {
      "x": 12,
      "y": 0,
      "z": -1,
      "name": "Cloth_Block_Wool_Black"
    },
    {
      "x": 12,
      "y": 1,
      "z": -1,
      "name": "Empty"
    },
    {
      "x": 12,
      "y": 2,
      "z": -1,
      "name": "Empty"
    },
    {
      "x": 12,
      "y": 3,
      "z": -1,
      "name": "Empty"
    },
    {
      "x": 12,
      "y": 4,
      "z": -1,
      "name": "Cloth_Block_Wool_Black"
    },
    {
      "x": 12,
      "y": 0,
      "z": 0,
      "name": "Cloth_Block_Wool_Black"
    },
    {
      "x": 12,
      "y": 1,
      "z": 0,
      "name": "Empty"
    },
    {
      "x": 12,
      "y": 2,
      "z": 0,
      "name": "Empty"
    },
    {
      "x": 12,
      "y": 3,
      "z": 0,
      "name": "Empty"
    },
    {
      "x": 12,
      "y": 4,
      "z": 0,
      "name": "Cloth_Block_Wool_Black"
    },
    {
      "x": 12,
      "y": 0,
      "z": 1,
      "name": "Cloth_Block_Wool_Black"
    },
    {
      "x": 12,
      "y": 1,
      "z": 1,
      "name": "Empty"
    },
    {
      "x": 12,
      "y": 2,
      "z": 1,
      "name": "Empty"
    },
    {
      "x": 12,
      "y": 3,
      "z": 1,
      "name": "Empty"
    },
    {
      "x": 12,
      "y": 4,
      "z": 1,
      "name": "Cloth_Block_Wool_Black"
    },
    {
      "x": 12,
      "y": 0,
      "z": 2,
      "name": "Cloth_Block_Wool_Black"
    },
    {
      "x": 12,
      "y": 1,
      "z": 2,
      "name": "Empty"
    },
    {
      "x": 12,
      "y": 2,
      "z": 2,
      "name": "Empty"
    },
    {
      "x": 12,
      "y": 3,
      "z": 2,
      "name": "Empty"
    },
    {
      "x": 12,
      "y": 4,
      "z": 2,
      "name": "Cloth_Block_Wool_Black"
    },
    {
      "x": 12,
      "y": 0,
      "z": 3,
      "name": "Cloth_Block_Wool_Black"
    },
    {
      "x": 12,
      "y": 1,
      "z": 3,
      "name": "Empty"
    },
    {
      "x": 12,
      "y": 2,
      "z": 3,
      "name": "Empty"
    },
    {
      "x": 12,
      "y": 3,
      "z": 3,
      "name": "Empty"
    },
    {
      "x": 12,
      "y": 4,
      "z": 3,
      "name": "Cloth_Block_Wool_Black"
    },
    {
      "x": 12,
      "y": 0,
      "z": 4,
      "name": "Cloth_Block_Wool_Black"
    },
    {
      "x": 12,
      "y": 1,
      "z": 4,
      "name": "Empty"
    },
    {
      "x": 12,
      "y": 2,
      "z": 4,
      "name": "Empty"
    },
    {
      "x": 12,
      "y": 3,
      "z": 4,
      "name": "Empty"
    },
    {
      "x": 12,
      "y": 4,
      "z": 4,
      "name": "Cloth_Block_Wool_Black"
    },
    {
      "x": 12,
      "y": 0,
      "z": 5,
      "name": "Cloth_Block_Wool_Black"
    },
    {
      "x": 12,
      "y": 1,
      "z": 5,
      "name": "Empty"
    },
    {
      "x": 12,
      "y": 2,
      "z": 5,
      "name": "Empty"
    },
    {
      "x": 12,
      "y": 3,
      "z": 5,
      "name": "Empty"
    },
    {
      "x": 12,
      "y": 4,
      "z": 5,
      "name": "Cloth_Block_Wool_Black"
    },
    {
      "x": 12,
      "y": 0,
      "z": 6,
      "name": "Cloth_Block_Wool_Black"
    },
    {
      "x": 12,
      "y": 1,
      "z": 6,
      "name": "Empty"
    },
    {
      "x": 12,
      "y": 2,
      "z": 6,
      "name": "Empty"
    },
    {
      "x": 12,
      "y": 3,
      "z": 6,
      "name": "Empty"
    },
    {
      "x": 12,
      "y": 4,
      "z": 6,
      "name": "Cloth_Block_Wool_Black"
    },
    {
      "x": 12,
      "y": 0,
      "z": 7,
      "name": "Cloth_Block_Wool_Black"
    },
    {
      "x": 12,
      "y": 1,
      "z": 7,
      "name": "Rock_Basalt_Brick"
    },
    {
      "x": 12,
      "y": 2,
      "z": 7,
      "name": "Rock_Basalt_Brick"
    },
    {
      "x": 12,
      "y": 3,
      "z": 7,
      "name": "Rock_Basalt_Brick"
    },
    {
      "x": 12,
      "y": 4,
      "z": 7,
      "name": "Cloth_Block_Wool_Black"
    },
    {
      "x": 13,
      "y": 0,
      "z": -7,
      "name": "Cloth_Block_Wool_Black"
    },
    {
      "x": 13,
      "y": 1,
      "z": -7,
      "name": "Rock_Basalt_Brick"
    },
    {
      "x": 13,
      "y": 2,
      "z": -7,
      "name": "Rock_Basalt_Brick"
    },
    {
      "x": 13,
      "y": 3,
      "z": -7,
      "name": "Rock_Basalt_Brick"
    },
    {
      "x": 13,
      "y": 4,
      "z": -7,
      "name": "Cloth_Block_Wool_Black"
    },
    {
      "x": 13,
      "y": 0,
      "z": -6,
      "name": "Cloth_Block_Wool_Black"
    },
    {
      "x": 13,
      "y": 1,
      "z": -6,
      "name": "Empty"
    },
    {
      "x": 13,
      "y": 2,
      "z": -6,
      "name": "Empty"
    },
    {
      "x": 13,
      "y": 3,
      "z": -6,
      "name": "Empty"
    },
    {
      "x": 13,
      "y": 4,
      "z": -6,
      "name": "Cloth_Block_Wool_Black"
    },
    {
      "x": 13,
      "y": 0,
      "z": -5,
      "name": "Cloth_Block_Wool_Black"
    },
    {
      "x": 13,
      "y": 1,
      "z": -5,
      "name": "Empty"
    },
    {
      "x": 13,
      "y": 2,
      "z": -5,
      "name": "Empty"
    },
    {
      "x": 13,
      "y": 3,
      "z": -5,
      "name": "Empty"
    },
    {
      "x": 13,
      "y": 4,
      "z": -5,
      "name": "Cloth_Block_Wool_Black"
    },
    {
      "x": 13,
      "y": 0,
      "z": -4,
      "name": "Cloth_Block_Wool_Black"
    },
    {
      "x": 13,
      "y": 1,
      "z": -4,
      "name": "Empty"
